Workbook
Name Actuality: 'P&L Month by CC summary'!#REF!
Name Actuality: 'P&L Month YTD by CC summary'!#REF!
Name Actuality_1: 'P&L Month by CC detailed'!$D$22
Name Actuality_1: 'P&L Month by CC summary'!$D$21
Name Actuality_1: 'P&L Month YTD by CC detailed'!$D$22
Name Actuality_1: 'P&L Month YTD by CC summary'!$D$21
Name Actuality_2: 'P&L Month by CC detailed'!$E$22
Name Actuality_2: 'P&L Month by CC summary'!#REF!
Name Actuality_2: 'P&L Month YTD by CC detailed'!$E$22
Name Actuality_2: 'P&L Month YTD by CC summary'!#REF!
Name Actuality_3: 'P&L Month by CC detailed'!$H$22
Name Actuality_3: 'P&L Month by CC summary'!#REF!
Name Actuality_3: 'P&L Month YTD by CC detailed'!$H$22
Name Actuality_3: 'P&L Month YTD by CC summary'!#REF!
Name company: 'P&L Month by CC detailed'!$C$17
Name company: 'P&L Month by CC summary'!$C$17
Name company: 'P&L Month YTD by CC detailed'!$C$17
Name company: 'P&L Month YTD by CC summary'!$C$17
Name Month: 'P&L Month by CC detailed'!$C$19
Name Month: 'P&L Month by CC summary'!#REF!
Name Month: 'P&L Month YTD by CC detailed'!$C$19
Name Month: 'P&L Month YTD by CC summary'!#REF!
Name Month_1: 'P&L Month by CC summary'!$D$21
Name Month_1: 'P&L Month YTD by CC summary'!$D$21
Name ori: 'P&L Month by CC detailed'!$C$18
Name ori: 'P&L Month by CC summary'!$C$18
Name ori: 'P&L Month YTD by CC detailed'!$C$18
Name ori: 'P&L Month YTD by CC summary'!$C$18
Name origine: 'P&L Month by CC summary'!$C$18
Name TM1REBUILDOPTION: 1
Name TM1RPTDATARNGARPT1: 'P&L Month by CC detailed'!$25:$78
Name TM1RPTDATARNGARPT1: 'P&L Month by CC summary'!$23:$41
Name TM1RPTDATARNGARPT1: 'P&L Month YTD by CC detailed'!$25:$78
Name TM1RPTDATARNGARPT1: 'P&L Month YTD by CC summary'!$23:$41
Name TM1RPTFMTIDCOL: 'P&L Month by CC detailed'!$A$1:$A$8
Name TM1RPTFMTIDCOL: 'P&L Month by CC summary'!$A$1:$A$8
Name TM1RPTFMTIDCOL: 'P&L Month YTD by CC detailed'!$A$1:$A$8
Name TM1RPTFMTIDCOL: 'P&L Month YTD by CC summary'!$A$1:$A$8
Name TM1RPTFMTRNG: 'P&L Month by CC detailed'!$B$1:$L$8
Name TM1RPTFMTRNG: 'P&L Month by CC summary'!$B$1:$D$8
Name TM1RPTFMTRNG: 'P&L Month YTD by CC detailed'!$B$1:$L$8
Name TM1RPTFMTRNG: 'P&L Month YTD by CC summary'!$B$1:$D$8

Sheet P&L Month by CC summary
B18: Origin_Company | C18: =_xll.SUBNM("CXMD:DIM_Origin_Company","","Total Origin Company") -> Total Origin Company | H18: P&L Month _ summary
B19: Actuality | C19: =_xll.SUBNM("CXMD:Actuality","","AC2022","Description EN") -> AC2022
B20: Allocation | C20: =_xll.SUBNM("CXMD:DIM_Allocation","","Total Allocation") -> Total Allocation
C21: in K Local Currency | D21: January | E21: February | F21: March | G21: April | H21: May | I21: June | J21: July | K21: August | L21: September | M21: October | N21: November | O21: December | P21: TOTAL YEAR
B22: Bucher Account
B23: G - 309000 - NET SALES | C23: Profit and Loss | D23: =_xll.DBR("CXMD:FTM_DATA_BALANCE_SHEET","Total_Customer_Supplier",D$21,$C$19,ori,"TOTAL PRODUCT","B-300010",$C$20,"Amount_BS")*-1/1000 -> 359843.49 | E23: =_xll.DBR("CXMD:FTM_DATA_BALANCE_SHEET","Total_Customer_Supplier",E$21,$C$19,ori,"TOTAL PRODUCT","B-300010",$C$20,"Amount_BS")*-1/1000 -> 340351.87 | F23: =_xll.DBR("CXMD:FTM_DATA_BALANCE_SHEET","Total_Customer_Supplier",F$21,$C$19,ori,"TOTAL PRODUCT","B-300010",$C$20,"Amount_BS")*-1/1000 -> 353866.18 | G23: =_xll.DBR("CXMD:FTM_DATA_BALANCE_SHEET","Total_Customer_Supplier",G$21,$C$19,ori,"TOTAL PRODUCT","B-300010",$C$20,"Amount_BS")*-1/1000 -> 323237.93 | H23: =_xll.DBR("CXMD:FTM_DATA_BALANCE_SHEET","Total_Customer_Supplier",H$21,$C$19,ori,"TOTAL PRODUCT","B-300010",$C$20,"Amount_BS")*-1/1000 -> 359434.3 | I23: =_xll.DBR("CXMD:FTM_DATA_BALANCE_SHEET","Total_Customer_Supplier",I$21,$C$19,ori,"TOTAL PRODUCT","B-300010",$C$20,"Amount_BS")*-1/1000 -> 379893.72 | J23: =_xll.DBR("CXMD:FTM_DATA_BALANCE_SHEET","Total_Customer_Supplier",J$21,$C$19,ori,"TOTAL PRODUCT","B-300010",$C$20,"Amount_BS")*-1/1000 -> 380094.44 | K23: =_xll.DBR("CXMD:FTM_DATA_BALANCE_SHEET","Total_Customer_Supplier",K$21,$C$19,ori,"TOTAL PRODUCT","B-300010",$C$20,"Amount_BS")*-1/1000 -> 362873.71 | ... O23: =_xll.DBR("CXMD:FTM_DATA_BALANCE_SHEET","Total_Customer_Supplier",O$21,$C$19,ori,"TOTAL PRODUCT","B-300010",$C$20,"Amount_BS")*-1/1000 -> 252037.44 | P23: =SUM(D23:O23) -> 4072661.1
B24: G - 319000 - NET VARIATION OF STOCK | C24: Profit and Loss | D24: =_xll.DBR("CXMD:FTM_DATA_BALANCE_SHEET","Total_Customer_Supplier",D$21,$C$19,ori,"TOTAL PRODUCT","B-310010",$C$20,"Amount_BS")*-1/1000 -> -30807.778 | E24: =_xll.DBR("CXMD:FTM_DATA_BALANCE_SHEET","Total_Customer_Supplier",E$21,$C$19,ori,"TOTAL PRODUCT","B-310010",$C$20,"Amount_BS")*-1/1000 -> -7700.917 | F24: =_xll.DBR("CXMD:FTM_DATA_BALANCE_SHEET","Total_Customer_Supplier",F$21,$C$19,ori,"TOTAL PRODUCT","B-310010",$C$20,"Amount_BS")*-1/1000 -> 17816.846 | G24: =_xll.DBR("CXMD:FTM_DATA_BALANCE_SHEET","Total_Customer_Supplier",G$21,$C$19,ori,"TOTAL PRODUCT","B-310010",$C$20,"Amount_BS")*-1/1000 -> -5525.5791 | H24: =_xll.DBR("CXMD:FTM_DATA_BALANCE_SHEET","Total_Customer_Supplier",H$21,$C$19,ori,"TOTAL PRODUCT","B-310010",$C$20,"Amount_BS")*-1/1000 -> 23479.517 | I24: =_xll.DBR("CXMD:FTM_DATA_BALANCE_SHEET","Total_Customer_Supplier",I$21,$C$19,ori,"TOTAL PRODUCT","B-310010",$C$20,"Amount_BS")*-1/1000 -> -8578.8464 | J24: =_xll.DBR("CXMD:FTM_DATA_BALANCE_SHEET","Total_Customer_Supplier",J$21,$C$19,ori,"TOTAL PRODUCT","B-310010",$C$20,"Amount_BS")*-1/1000 -> -18897.088 | K24: =_xll.DBR("CXMD:FTM_DATA_BALANCE_SHEET","Total_Customer_Supplier",K$21,$C$19,ori,"TOTAL PRODUCT","B-310010",$C$20,"Amount_BS")*-1/1000 -> -224.62734 | ... O24: =_xll.DBR("CXMD:FTM_DATA_BALANCE_SHEET","Total_Customer_Supplier",O$21,$C$19,ori,"TOTAL PRODUCT","B-310010",$C$20,"Amount_BS")*-1/1000 -> 3887.5685 | P24: =SUM(D24:O24) -> 10475.845
B25: G-329000 Corporate output | D25: =D23+D24 -> 329035.72 | E25: =E23+E24 -> 332650.95 | F25: =F23+F24 -> 371683.02 | G25: =G23+G24 -> 317712.35 | H25: =H23+H24 -> 382913.81 | I25: =I23+I24 -> 371314.88 | J25: =J23+J24 -> 361197.35 | K25: =K23+K24 -> 362649.08 | ... P25: =P23+P24 -> 4083136.9
B26: G - 339000 - OPERATING INCOME | C26: Profit and Loss | D26: =_xll.DBR("CXMD:FTM_DATA_BALANCE_SHEET","Total_Customer_Supplier",D$21,$C$19,ori,"TOTAL PRODUCT","B-330010",$C$20,"Amount_BS")*-1/1000 -> 4042.3655 | E26: =_xll.DBR("CXMD:FTM_DATA_BALANCE_SHEET","Total_Customer_Supplier",E$21,$C$19,ori,"TOTAL PRODUCT","B-330010",$C$20,"Amount_BS")*-1/1000 -> 4540.9253 | F26: =_xll.DBR("CXMD:FTM_DATA_BALANCE_SHEET","Total_Customer_Supplier",F$21,$C$19,ori,"TOTAL PRODUCT","B-330010",$C$20,"Amount_BS")*-1/1000 -> 4848.1721 | G26: =_xll.DBR("CXMD:FTM_DATA_BALANCE_SHEET","Total_Customer_Supplier",G$21,$C$19,ori,"TOTAL PRODUCT","B-330010",$C$20,"Amount_BS")*-1/1000 -> 4398.9568 | H26: =_xll.DBR("CXMD:FTM_DATA_BALANCE_SHEET","Total_Customer_Supplier",H$21,$C$19,ori,"TOTAL PRODUCT","B-330010",$C$20,"Amount_BS")*-1/1000 -> 4382.8768 | I26: =_xll.DBR("CXMD:FTM_DATA_BALANCE_SHEET","Total_Customer_Supplier",I$21,$C$19,ori,"TOTAL PRODUCT","B-330010",$C$20,"Amount_BS")*-1/1000 -> 4726.6561 | J26: =_xll.DBR("CXMD:FTM_DATA_BALANCE_SHEET","Total_Customer_Supplier",J$21,$C$19,ori,"TOTAL PRODUCT","B-330010",$C$20,"Amount_BS")*-1/1000 -> 4529.6568 | K26: =_xll.DBR("CXMD:FTM_DATA_BALANCE_SHEET","Total_Customer_Supplier",K$21,$C$19,ori,"TOTAL PRODUCT","B-330010",$C$20,"Amount_BS")*-1/1000 -> 4356.6035 | ... O26: =_xll.DBR("CXMD:FTM_DATA_BALANCE_SHEET","Total_Customer_Supplier",O$21,$C$19,ori,"TOTAL PRODUCT","B-330010",$C$20,"Amount_BS")*-1/1000 -> 2890.2751 | P26: =SUM(D26:O26) -> 52175.87
B27: REVENUE | D27: =D25+D26 -> 333078.08 | E27: =E25+E26 -> 337191.88 | F27: =F25+F26 -> 376531.2 | G27: =G25+G26 -> 322111.3 | H27: =H25+H26 -> 387296.69 | I27: =I25+I26 -> 376041.53 | J27: =J25+J26 -> 365727.01 | K27: =K25+K26 -> 367005.68 | ... P27: =P25+P26 -> 4135312.8
B28: G - 452000 - VARIATION OF PROVISIONS | C28: Profit and Loss | D28: =(_xll.DBR("CXMD:FTM_DATA_BALANCE_SHEET","Total_Customer_Supplier",D$21,$C$19,ori,"TOTAL PRODUCT","B-452010",$C$20,"Amount_BS")/1000)+(_xll.DBR("CXMD:FTM_DATA_BALANCE_SHEET","Total_Customer_Supplier",D$21,$C$19,ori,"TOTAL PRODUCT","B-452210",$C$20,"Amount_BS")/1000) -> 442.07326 | E28: =(_xll.DBR("CXMD:FTM_DATA_BALANCE_SHEET","Total_Customer_Supplier",E$21,$C$19,ori,"TOTAL PRODUCT","B-452010",$C$20,"Amount_BS")/1000)+(_xll.DBR("CXMD:FTM_DATA_BALANCE_SHEET","Total_Customer_Supplier",E$21,$C$19,ori,"TOTAL PRODUCT","B-452210",$C$20,"Amount_BS")/1000) -> -194.91658 | F28: =(_xll.DBR("CXMD:FTM_DATA_BALANCE_SHEET","Total_Customer_Supplier",F$21,$C$19,ori,"TOTAL PRODUCT","B-452010",$C$20,"Amount_BS")/1000)+(_xll.DBR("CXMD:FTM_DATA_BALANCE_SHEET","Total_Customer_Supplier",F$21,$C$19,ori,"TOTAL PRODUCT","B-452210",$C$20,"Amount_BS")/1000) -> 1613.4027 | G28: =(_xll.DBR("CXMD:FTM_DATA_BALANCE_SHEET","Total_Customer_Supplier",G$21,$C$19,ori,"TOTAL PRODUCT","B-452010",$C$20,"Amount_BS")/1000)+(_xll.DBR("CXMD:FTM_DATA_BALANCE_SHEET","Total_Customer_Supplier",G$21,$C$19,ori,"TOTAL PRODUCT","B-452210",$C$20,"Amount_BS")/1000) -> 1257.8317 | H28: =(_xll.DBR("CXMD:FTM_DATA_BALANCE_SHEET","Total_Customer_Supplier",H$21,$C$19,ori,"TOTAL PRODUCT","B-452010",$C$20,"Amount_BS")/1000)+(_xll.DBR("CXMD:FTM_DATA_BALANCE_SHEET","Total_Customer_Supplier",H$21,$C$19,ori,"TOTAL PRODUCT","B-452210",$C$20,"Amount_BS")/1000) -> -66.29061 | I28: =(_xll.DBR("CXMD:FTM_DATA_BALANCE_SHEET","Total_Customer_Supplier",I$21,$C$19,ori,"TOTAL PRODUCT","B-452010",$C$20,"Amount_BS")/1000)+(_xll.DBR("CXMD:FTM_DATA_BALANCE_SHEET","Total_Customer_Supplier",I$21,$C$19,ori,"TOTAL PRODUCT","B-452210",$C$20,"Amount_BS")/1000) -> 544.75837 | J28: =(_xll.DBR("CXMD:FTM_DATA_BALANCE_SHEET","Total_Customer_Supplier",J$21,$C$19,ori,"TOTAL PRODUCT","B-452010",$C$20,"Amount_BS")/1000)+(_xll.DBR("CXMD:FTM_DATA_BALANCE_SHEET","Total_Customer_Supplier",J$21,$C$19,ori,"TOTAL PRODUCT","B-452210",$C$20,"Amount_BS")/1000) -> 1477.1387 | K28: =(_xll.DBR("CXMD:FTM_DATA_BALANCE_SHEET","Total_Customer_Supplier",K$21,$C$19,ori,"TOTAL PRODUCT","B-452010",$C$20,"Amount_BS")/1000)+(_xll.DBR("CXMD:FTM_DATA_BALANCE_SHEET","Total_Customer_Supplier",K$21,$C$19,ori,"TOTAL PRODUCT","B-452210",$C$20,"Amount_BS")/1000) -> 908.98217 | ... O28: =(_xll.DBR("CXMD:FTM_DATA_BALANCE_SHEET","Total_Customer_Supplier",O$21,$C$19,ori,"TOTAL PRODUCT","B-452010",$C$20,"Amount_BS")/1000)+(_xll.DBR("CXMD:FTM_DATA_BALANCE_SHEET","Total_Customer_Supplier",O$21,$C$19,ori,"TOTAL PRODUCT","B-452210",$C$20,"Amount_BS")/1000) -> 9764.6165 | P28: =SUM(D28:O28) -> 29689.028
B29: Total Material expenses + net var. stock | D29: =(_xll.DBR("CXMD:FTM_DATA_BALANCE_SHEET","Total_Customer_Supplier",D$21,$C$19,ori,"TOTAL PRODUCT","B-401010",$C$20,"Amount_BS")/1000)+(_xll.DBR("CXMD:FTM_DATA_BALANCE_SHEET","Total_Customer_Supplier",D$21,$C$19,ori,"TOTAL PRODUCT","B-401020",$C$20,"Amount_BS")/1000)+(_xll.DBR("CXMD:FTM_DATA_BALANCE_SHEET","Total_Customer_Supplier",D$21,$C$19,ori,"TOTAL PRODUCT","B-402110",$C$20,"Amount_BS")/1000)+(_xll.DBR("CXMD:FTM_DATA_BALANCE_SHEET","Total_Customer_Supplier",D$21,$C$19,ori,"TOTAL PRODUCT","B-402111",$C$20,"Amount_BS")/1000)+(_xll.DBR("CXMD:FTM_DATA_BALANCE_SHEET","Total_Customer_Supplier",D$21,$C$19,ori,"TOTAL PRODUCT","B-407010",$C$20,"Amount_BS")/1000) -> 190042.62 | E29: =(_xll.DBR("CXMD:FTM_DATA_BALANCE_SHEET","Total_Customer_Supplier",E$21,$C$19,ori,"TOTAL PRODUCT","B-401010",$C$20,"Amount_BS")/1000)+(_xll.DBR("CXMD:FTM_DATA_BALANCE_SHEET","Total_Customer_Supplier",E$21,$C$19,ori,"TOTAL PRODUCT","B-401020",$C$20,"Amount_BS")/1000)+(_xll.DBR("CXMD:FTM_DATA_BALANCE_SHEET","Total_Customer_Supplier",E$21,$C$19,ori,"TOTAL PRODUCT","B-402110",$C$20,"Amount_BS")/1000)+(_xll.DBR("CXMD:FTM_DATA_BALANCE_SHEET","Total_Customer_Supplier",E$21,$C$19,ori,"TOTAL PRODUCT","B-402111",$C$20,"Amount_BS")/1000)+(_xll.DBR("CXMD:FTM_DATA_BALANCE_SHEET","Total_Customer_Supplier",E$21,$C$19,ori,"TOTAL PRODUCT","B-407010",$C$20,"Amount_BS")/1000) -> 192852.16 | F29: =(_xll.DBR("CXMD:FTM_DATA_BALANCE_SHEET","Total_Customer_Supplier",F$21,$C$19,ori,"TOTAL PRODUCT","B-401010",$C$20,"Amount_BS")/1000)+(_xll.DBR("CXMD:FTM_DATA_BALANCE_SHEET","Total_Customer_Supplier",F$21,$C$19,ori,"TOTAL PRODUCT","B-401020",$C$20,"Amount_BS")/1000)+(_xll.DBR("CXMD:FTM_DATA_BALANCE_SHEET","Total_Customer_Supplier",F$21,$C$19,ori,"TOTAL PRODUCT","B-402110",$C$20,"Amount_BS")/1000)+(_xll.DBR("CXMD:FTM_DATA_BALANCE_SHEET","Total_Customer_Supplier",F$21,$C$19,ori,"TOTAL PRODUCT","B-402111",$C$20,"Amount_BS")/1000)+(_xll.DBR("CXMD:FTM_DATA_BALANCE_SHEET","Total_Customer_Supplier",F$21,$C$19,ori,"TOTAL PRODUCT","B-407010",$C$20,"Amount_BS")/1000) -> 252392.84 | G29: =(_xll.DBR("CXMD:FTM_DATA_BALANCE_SHEET","Total_Customer_Supplier",G$21,$C$19,ori,"TOTAL PRODUCT","B-401010",$C$20,"Amount_BS")/1000)+(_xll.DBR("CXMD:FTM_DATA_BALANCE_SHEET","Total_Customer_Supplier",G$21,$C$19,ori,"TOTAL PRODUCT","B-401020",$C$20,"Amount_BS")/1000)+(_xll.DBR("CXMD:FTM_DATA_BALANCE_SHEET","Total_Customer_Supplier",G$21,$C$19,ori,"TOTAL PRODUCT","B-402110",$C$20,"Amount_BS")/1000)+(_xll.DBR("CXMD:FTM_DATA_BALANCE_SHEET","Total_Customer_Supplier",G$21,$C$19,ori,"TOTAL PRODUCT","B-402111",$C$20,"Amount_BS")/1000)+(_xll.DBR("CXMD:FTM_DATA_BALANCE_SHEET","Total_Customer_Supplier",G$21,$C$19,ori,"TOTAL PRODUCT","B-407010",$C$20,"Amount_BS")/1000) -> 210140.84 | H29: =(_xll.DBR("CXMD:FTM_DATA_BALANCE_SHEET","Total_Customer_Supplier",H$21,$C$19,ori,"TOTAL PRODUCT","B-401010",$C$20,"Amount_BS")/1000)+(_xll.DBR("CXMD:FTM_DATA_BALANCE_SHEET","Total_Customer_Supplier",H$21,$C$19,ori,"TOTAL PRODUCT","B-401020",$C$20,"Amount_BS")/1000)+(_xll.DBR("CXMD:FTM_DATA_BALANCE_SHEET","Total_Customer_Supplier",H$21,$C$19,ori,"TOTAL PRODUCT","B-402110",$C$20,"Amount_BS")/1000)+(_xll.DBR("CXMD:FTM_DATA_BALANCE_SHEET","Total_Customer_Supplier",H$21,$C$19,ori,"TOTAL PRODUCT","B-402111",$C$20,"Amount_BS")/1000)+(_xll.DBR("CXMD:FTM_DATA_BALANCE_SHEET","Total_Customer_Supplier",H$21,$C$19,ori,"TOTAL PRODUCT","B-407010",$C$20,"Amount_BS")/1000) -> 243390.75 | I29: =(_xll.DBR("CXMD:FTM_DATA_BALANCE_SHEET","Total_Customer_Supplier",I$21,$C$19,ori,"TOTAL PRODUCT","B-401010",$C$20,"Amount_BS")/1000)+(_xll.DBR("CXMD:FTM_DATA_BALANCE_SHEET","Total_Customer_Supplier",I$21,$C$19,ori,"TOTAL PRODUCT","B-401020",$C$20,"Amount_BS")/1000)+(_xll.DBR("CXMD:FTM_DATA_BALANCE_SHEET","Total_Customer_Supplier",I$21,$C$19,ori,"TOTAL PRODUCT","B-402110",$C$20,"Amount_BS")/1000)+(_xll.DBR("CXMD:FTM_DATA_BALANCE_SHEET","Total_Customer_Supplier",I$21,$C$19,ori,"TOTAL PRODUCT","B-402111",$C$20,"Amount_BS")/1000)+(_xll.DBR("CXMD:FTM_DATA_BALANCE_SHEET","Total_Customer_Supplier",I$21,$C$19,ori,"TOTAL PRODUCT","B-407010",$C$20,"Amount_BS")/1000) -> 235213 | J29: =(_xll.DBR("CXMD:FTM_DATA_BALANCE_SHEET","Total_Customer_Supplier",J$21,$C$19,ori,"TOTAL PRODUCT","B-401010",$C$20,"Amount_BS")/1000)+(_xll.DBR("CXMD:FTM_DATA_BALANCE_SHEET","Total_Customer_Supplier",J$21,$C$19,ori,"TOTAL PRODUCT","B-401020",$C$20,"Amount_BS")/1000)+(_xll.DBR("CXMD:FTM_DATA_BALANCE_SHEET","Total_Customer_Supplier",J$21,$C$19,ori,"TOTAL PRODUCT","B-402110",$C$20,"Amount_BS")/1000)+(_xll.DBR("CXMD:FTM_DATA_BALANCE_SHEET","Total_Customer_Supplier",J$21,$C$19,ori,"TOTAL PRODUCT","B-402111",$C$20,"Amount_BS")/1000)+(_xll.DBR("CXMD:FTM_DATA_BALANCE_SHEET","Total_Customer_Supplier",J$21,$C$19,ori,"TOTAL PRODUCT","B-407010",$C$20,"Amount_BS")/1000) -> 221949.36 | K29: =(_xll.DBR("CXMD:FTM_DATA_BALANCE_SHEET","Total_Customer_Supplier",K$21,$C$19,ori,"TOTAL PRODUCT","B-401010",$C$20,"Amount_BS")/1000)+(_xll.DBR("CXMD:FTM_DATA_BALANCE_SHEET","Total_Customer_Supplier",K$21,$C$19,ori,"TOTAL PRODUCT","B-401020",$C$20,"Amount_BS")/1000)+(_xll.DBR("CXMD:FTM_DATA_BALANCE_SHEET","Total_Customer_Supplier",K$21,$C$19,ori,"TOTAL PRODUCT","B-402110",$C$20,"Amount_BS")/1000)+(_xll.DBR("CXMD:FTM_DATA_BALANCE_SHEET","Total_Customer_Supplier",K$21,$C$19,ori,"TOTAL PRODUCT","B-402111",$C$20,"Amount_BS")/1000)+(_xll.DBR("CXMD:FTM_DATA_BALANCE_SHEET","Total_Customer_Supplier",K$21,$C$19,ori,"TOTAL PRODUCT","B-407010",$C$20,"Amount_BS")/1000) -> 199063.85 | ... O29: =(_xll.DBR("CXMD:FTM_DATA_BALANCE_SHEET","Total_Customer_Supplier",O$21,$C$19,ori,"TOTAL PRODUCT","B-401010",$C$20,"Amount_BS")/1000)+(_xll.DBR("CXMD:FTM_DATA_BALANCE_SHEET","Total_Customer_Supplier",O$21,$C$19,ori,"TOTAL PRODUCT","B-401020",$C$20,"Amount_BS")/1000)+(_xll.DBR("CXMD:FTM_DATA_BALANCE_SHEET","Total_Customer_Supplier",O$21,$C$19,ori,"TOTAL PRODUCT","B-402110",$C$20,"Amount_BS")/1000)+(_xll.DBR("CXMD:FTM_DATA_BALANCE_SHEET","Total_Customer_Supplier",O$21,$C$19,ori,"TOTAL PRODUCT","B-402111",$C$20,"Amount_BS")/1000)+(_xll.DBR("CXMD:FTM_DATA_BALANCE_SHEET","Total_Customer_Supplier",O$21,$C$19,ori,"TOTAL PRODUCT","B-407010",$C$20,"Amount_BS")/1000) -> 161641.24 | P29: =SUM(D29:O29) -> 2543662.2
C30: % of corporate output | D30: =IF(D25<>0,D29/D25,0) -> 0.57757445 | E30: =IF(E25<>0,E29/E25,0) -> 0.57974328 | F30: =IF(F25<>0,F29/F25,0) -> 0.679054 | G30: =IF(G25<>0,G29/G25,0) -> 0.66141854 | H30: =IF(H25<>0,H29/H25,0) -> 0.63562803 | I30: =IF(I25<>0,I29/I25,0) -> 0.63345967 | J30: =IF(J25<>0,J29/J25,0) -> 0.61448226 | K30: =IF(K25<>0,K29/K25,0) -> 0.54891592 | ... P30: =IF(P25<>0,P29/P25,0) -> 0.62296765
B31: G-429999-GROSS MARGIN | D31: =D27-D29 -> 143035.46 | E31: =E27-E29 -> 144339.72 | F31: =F27-F29 -> 124138.35 | G31: =G27-G29 -> 111970.47 | H31: =H27-H29 -> 143905.94 | I31: =I27-I29 -> 140828.54 | J31: =J27-J29 -> 143777.64 | K31: =K27-K29 -> 167941.83 | ... P31: =P27-P29 -> 1591650.6
C32: % of corporate output | D32: =IF(D25<>0,D31/D25,0) -> 0.43471105 | E32: =IF(E25<>0,E31/E25,0) -> 0.43390744 | F32: =IF(F25<>0,F31/F25,0) -> 0.33398984 | G32: =IF(G25<>0,G31/G25,0) -> 0.35242718 | H32: =IF(H25<>0,H31/H25,0) -> 0.37581809 | I32: =IF(I25<>0,I31/I25,0) -> 0.37926984 | J32: =IF(J25<>0,J31/J25,0) -> 0.39805841 | K32: =IF(K25<>0,K31/K25,0) -> 0.46309736 | ... P32: =IF(P25<>0,P31/P25,0) -> 0.38981073
B33: G - 439000 - PERSONNEL COSTS | C33: Profit and Loss | D33: =(_xll.DBR("CXMD:FTM_DATA_BALANCE_SHEET","Total_Customer_Supplier",D$21,$C$19,ori,"TOTAL PRODUCT","B-430010",$C$20,"Amount_BS")/1000)+(_xll.DBR("CXMD:FTM_DATA_BALANCE_SHEET","Total_Customer_Supplier",D$21,$C$19,ori,"TOTAL PRODUCT","B-430040",$C$20,"Amount_BS")/1000)+(_xll.DBR("CXMD:FTM_DATA_BALANCE_SHEET","Total_Customer_Supplier",D$21,$C$19,ori,"TOTAL PRODUCT","B-431040",$C$20,"Amount_BS")/1000)+(_xll.DBR("CXMD:FTM_DATA_BALANCE_SHEET","Total_Customer_Supplier",D$21,$C$19,ori,"TOTAL PRODUCT","B-437010",$C$20,"Amount_BS")/1000)+(_xll.DBR("CXMD:FTM_DATA_BALANCE_SHEET","Total_Customer_Supplier",D$21,$C$19,ori,"TOTAL PRODUCT","B-438010",$C$20,"Amount_BS")/1000) -> 37400.484 | E33: =(_xll.DBR("CXMD:FTM_DATA_BALANCE_SHEET","Total_Customer_Supplier",E$21,$C$19,ori,"TOTAL PRODUCT","B-430010",$C$20,"Amount_BS")/1000)+(_xll.DBR("CXMD:FTM_DATA_BALANCE_SHEET","Total_Customer_Supplier",E$21,$C$19,ori,"TOTAL PRODUCT","B-430040",$C$20,"Amount_BS")/1000)+(_xll.DBR("CXMD:FTM_DATA_BALANCE_SHEET","Total_Customer_Supplier",E$21,$C$19,ori,"TOTAL PRODUCT","B-431040",$C$20,"Amount_BS")/1000)+(_xll.DBR("CXMD:FTM_DATA_BALANCE_SHEET","Total_Customer_Supplier",E$21,$C$19,ori,"TOTAL PRODUCT","B-437010",$C$20,"Amount_BS")/1000)+(_xll.DBR("CXMD:FTM_DATA_BALANCE_SHEET","Total_Customer_Supplier",E$21,$C$19,ori,"TOTAL PRODUCT","B-438010",$C$20,"Amount_BS")/1000) -> 40241.933 | F33: =(_xll.DBR("CXMD:FTM_DATA_BALANCE_SHEET","Total_Customer_Supplier",F$21,$C$19,ori,"TOTAL PRODUCT","B-430010",$C$20,"Amount_BS")/1000)+(_xll.DBR("CXMD:FTM_DATA_BALANCE_SHEET","Total_Customer_Supplier",F$21,$C$19,ori,"TOTAL PRODUCT","B-430040",$C$20,"Amount_BS")/1000)+(_xll.DBR("CXMD:FTM_DATA_BALANCE_SHEET","Total_Customer_Supplier",F$21,$C$19,ori,"TOTAL PRODUCT","B-431040",$C$20,"Amount_BS")/1000)+(_xll.DBR("CXMD:FTM_DATA_BALANCE_SHEET","Total_Customer_Supplier",F$21,$C$19,ori,"TOTAL PRODUCT","B-437010",$C$20,"Amount_BS")/1000)+(_xll.DBR("CXMD:FTM_DATA_BALANCE_SHEET","Total_Customer_Supplier",F$21,$C$19,ori,"TOTAL PRODUCT","B-438010",$C$20,"Amount_BS")/1000) -> 41481.869 | G33: =(_xll.DBR("CXMD:FTM_DATA_BALANCE_SHEET","Total_Customer_Supplier",G$21,$C$19,ori,"TOTAL PRODUCT","B-430010",$C$20,"Amount_BS")/1000)+(_xll.DBR("CXMD:FTM_DATA_BALANCE_SHEET","Total_Customer_Supplier",G$21,$C$19,ori,"TOTAL PRODUCT","B-430040",$C$20,"Amount_BS")/1000)+(_xll.DBR("CXMD:FTM_DATA_BALANCE_SHEET","Total_Customer_Supplier",G$21,$C$19,ori,"TOTAL PRODUCT","B-431040",$C$20,"Amount_BS")/1000)+(_xll.DBR("CXMD:FTM_DATA_BALANCE_SHEET","Total_Customer_Supplier",G$21,$C$19,ori,"TOTAL PRODUCT","B-437010",$C$20,"Amount_BS")/1000)+(_xll.DBR("CXMD:FTM_DATA_BALANCE_SHEET","Total_Customer_Supplier",G$21,$C$19,ori,"TOTAL PRODUCT","B-438010",$C$20,"Amount_BS")/1000) -> 38295.867 | H33: =(_xll.DBR("CXMD:FTM_DATA_BALANCE_SHEET","Total_Customer_Supplier",H$21,$C$19,ori,"TOTAL PRODUCT","B-430010",$C$20,"Amount_BS")/1000)+(_xll.DBR("CXMD:FTM_DATA_BALANCE_SHEET","Total_Customer_Supplier",H$21,$C$19,ori,"TOTAL PRODUCT","B-430040",$C$20,"Amount_BS")/1000)+(_xll.DBR("CXMD:FTM_DATA_BALANCE_SHEET","Total_Customer_Supplier",H$21,$C$19,ori,"TOTAL PRODUCT","B-431040",$C$20,"Amount_BS")/1000)+(_xll.DBR("CXMD:FTM_DATA_BALANCE_SHEET","Total_Customer_Supplier",H$21,$C$19,ori,"TOTAL PRODUCT","B-437010",$C$20,"Amount_BS")/1000)+(_xll.DBR("CXMD:FTM_DATA_BALANCE_SHEET","Total_Customer_Supplier",H$21,$C$19,ori,"TOTAL PRODUCT","B-438010",$C$20,"Amount_BS")/1000) -> 40150.205 | I33: =(_xll.DBR("CXMD:FTM_DATA_BALANCE_SHEET","Total_Customer_Supplier",I$21,$C$19,ori,"TOTAL PRODUCT","B-430010",$C$20,"Amount_BS")/1000)+(_xll.DBR("CXMD:FTM_DATA_BALANCE_SHEET","Total_Customer_Supplier",I$21,$C$19,ori,"TOTAL PRODUCT","B-430040",$C$20,"Amount_BS")/1000)+(_xll.DBR("CXMD:FTM_DATA_BALANCE_SHEET","Total_Customer_Supplier",I$21,$C$19,ori,"TOTAL PRODUCT","B-431040",$C$20,"Amount_BS")/1000)+(_xll.DBR("CXMD:FTM_DATA_BALANCE_SHEET","Total_Customer_Supplier",I$21,$C$19,ori,"TOTAL PRODUCT","B-437010",$C$20,"Amount_BS")/1000)+(_xll.DBR("CXMD:FTM_DATA_BALANCE_SHEET","Total_Customer_Supplier",I$21,$C$19,ori,"TOTAL PRODUCT","B-438010",$C$20,"Amount_BS")/1000) -> 43584.553 | J33: =(_xll.DBR("CXMD:FTM_DATA_BALANCE_SHEET","Total_Customer_Supplier",J$21,$C$19,ori,"TOTAL PRODUCT","B-430010",$C$20,"Amount_BS")/1000)+(_xll.DBR("CXMD:FTM_DATA_BALANCE_SHEET","Total_Customer_Supplier",J$21,$C$19,ori,"TOTAL PRODUCT","B-430040",$C$20,"Amount_BS")/1000)+(_xll.DBR("CXMD:FTM_DATA_BALANCE_SHEET","Total_Customer_Supplier",J$21,$C$19,ori,"TOTAL PRODUCT","B-431040",$C$20,"Amount_BS")/1000)+(_xll.DBR("CXMD:FTM_DATA_BALANCE_SHEET","Total_Customer_Supplier",J$21,$C$19,ori,"TOTAL PRODUCT","B-437010",$C$20,"Amount_BS")/1000)+(_xll.DBR("CXMD:FTM_DATA_BALANCE_SHEET","Total_Customer_Supplier",J$21,$C$19,ori,"TOTAL PRODUCT","B-438010",$C$20,"Amount_BS")/1000) -> 37568.565 | K33: =(_xll.DBR("CXMD:FTM_DATA_BALANCE_SHEET","Total_Customer_Supplier",K$21,$C$19,ori,"TOTAL PRODUCT","B-430010",$C$20,"Amount_BS")/1000)+(_xll.DBR("CXMD:FTM_DATA_BALANCE_SHEET","Total_Customer_Supplier",K$21,$C$19,ori,"TOTAL PRODUCT","B-430040",$C$20,"Amount_BS")/1000)+(_xll.DBR("CXMD:FTM_DATA_BALANCE_SHEET","Total_Customer_Supplier",K$21,$C$19,ori,"TOTAL PRODUCT","B-431040",$C$20,"Amount_BS")/1000)+(_xll.DBR("CXMD:FTM_DATA_BALANCE_SHEET","Total_Customer_Supplier",K$21,$C$19,ori,"TOTAL PRODUCT","B-437010",$C$20,"Amount_BS")/1000)+(_xll.DBR("CXMD:FTM_DATA_BALANCE_SHEET","Total_Customer_Supplier",K$21,$C$19,ori,"TOTAL PRODUCT","B-438010",$C$20,"Amount_BS")/1000) -> 31559.169 | ... O33: =(_xll.DBR("CXMD:FTM_DATA_BALANCE_SHEET","Total_Customer_Supplier",O$21,$C$19,ori,"TOTAL PRODUCT","B-430010",$C$20,"Amount_BS")/1000)+(_xll.DBR("CXMD:FTM_DATA_BALANCE_SHEET","Total_Customer_Supplier",O$21,$C$19,ori,"TOTAL PRODUCT","B-430040",$C$20,"Amount_BS")/1000)+(_xll.DBR("CXMD:FTM_DATA_BALANCE_SHEET","Total_Customer_Supplier",O$21,$C$19,ori,"TOTAL PRODUCT","B-431040",$C$20,"Amount_BS")/1000)+(_xll.DBR("CXMD:FTM_DATA_BALANCE_SHEET","Total_Customer_Supplier",O$21,$C$19,ori,"TOTAL PRODUCT","B-437010",$C$20,"Amount_BS")/1000)+(_xll.DBR("CXMD:FTM_DATA_BALANCE_SHEET","Total_Customer_Supplier",O$21,$C$19,ori,"TOTAL PRODUCT","B-438010",$C$20,"Amount_BS")/1000) -> 33483.778 | P33: =SUM(D33:O33) -> 460087.47
C34: % of corporate output | D34: =IF(D25<>0,D33/D25,0) -> 0.11366694 | E34: =IF(E25<>0,E33/E25,0) -> 0.12097345 | F34: =IF(F25<>0,F33/F25,0) -> 0.1116055 | G34: =IF(G25<>0,G33/G25,0) -> 0.12053629 | H34: =IF(H25<>0,H33/H25,0) -> 0.10485442 | I34: =IF(I25<>0,I33/I25,0) -> 0.11737896 | J34: =IF(J25<>0,J33/J25,0) -> 0.10401119 | K34: =IF(K25<>0,K33/K25,0) -> 0.087023987 | ... P34: =IF(P25<>0,P33/P25,0) -> 0.1126799
B35: G - 459000 - OTHER EXPENSES | C35: Profit and Loss | D35: =(_xll.DBR("CXMD:FTM_DATA_BALANCE_SHEET","Total_Customer_Supplier",D$21,$C$19,ori,"TOTAL PRODUCT","B-451010",$C$20,"Amount_BS")/1000)+(_xll.DBR("CXMD:FTM_DATA_BALANCE_SHEET","Total_Customer_Supplier",D$21,$C$19,ori,"TOTAL PRODUCT","B-451020",$C$20,"Amount_BS")/1000)+(_xll.DBR("CXMD:FTM_DATA_BALANCE_SHEET","Total_Customer_Supplier",D$21,$C$19,ori,"TOTAL PRODUCT","B-451030",$C$20,"Amount_BS")/1000)+(_xll.DBR("CXMD:FTM_DATA_BALANCE_SHEET","Total_Customer_Supplier",D$21,$C$19,ori,"TOTAL PRODUCT","B-451110",$C$20,"Amount_BS")/1000)+(_xll.DBR("CXMD:FTM_DATA_BALANCE_SHEET","Total_Customer_Supplier",D$21,$C$19,ori,"TOTAL PRODUCT","B-451210",$C$20,"Amount_BS")/1000)+(_xll.DBR("CXMD:FTM_DATA_BALANCE_SHEET","Total_Customer_Supplier",D$21,$C$19,ori,"TOTAL PRODUCT","B-451220",$C$20,"Amount_BS")/1000)+(_xll.DBR("CXMD:FTM_DATA_BALANCE_SHEET","Total_Customer_Supplier",D$21,$C$19,ori,"TOTAL PRODUCT","B-451310",$C$20,"Amount_BS")/1000)+(_xll.DBR("CXMD:FTM_DATA_BALANCE_SHEET","Total_Customer_Supplier",D$21,$C$19,ori,"TOTAL PRODUCT","B-451450",$C$20,"Amount_BS")/1000)+(_xll.DBR("CXMD:FTM_DATA_BALANCE_SHEET","Total_Customer_Supplier",D$21,$C$19,ori,"TOTAL PRODUCT","B-451510",$C$20,"Amount_BS")/1000)+(_xll.DBR("CXMD:FTM_DATA_BALANCE_SHEET","Total_Customer_Supplier",D$21,$C$19,ori,"TOTAL PRODUCT","B-451610",$C$20,"Amount_BS")/1000)+(_xll.DBR("CXMD:FTM_DATA_BALANCE_SHEET","Total_Customer_Supplier",D$21,$C$19,ori,"TOTAL PRODUCT","B-451620",$C$20,"Amount_BS")/1000) -> 29278.132 | E35: =(_xll.DBR("CXMD:FTM_DATA_BALANCE_SHEET","Total_Customer_Supplier",E$21,$C$19,ori,"TOTAL PRODUCT","B-451010",$C$20,"Amount_BS")/1000)+(_xll.DBR("CXMD:FTM_DATA_BALANCE_SHEET","Total_Customer_Supplier",E$21,$C$19,ori,"TOTAL PRODUCT","B-451020",$C$20,"Amount_BS")/1000)+(_xll.DBR("CXMD:FTM_DATA_BALANCE_SHEET","Total_Customer_Supplier",E$21,$C$19,ori,"TOTAL PRODUCT","B-451030",$C$20,"Amount_BS")/1000)+(_xll.DBR("CXMD:FTM_DATA_BALANCE_SHEET","Total_Customer_Supplier",E$21,$C$19,ori,"TOTAL PRODUCT","B-451110",$C$20,"Amount_BS")/1000)+(_xll.DBR("CXMD:FTM_DATA_BALANCE_SHEET","Total_Customer_Supplier",E$21,$C$19,ori,"TOTAL PRODUCT","B-451210",$C$20,"Amount_BS")/1000)+(_xll.DBR("CXMD:FTM_DATA_BALANCE_SHEET","Total_Customer_Supplier",E$21,$C$19,ori,"TOTAL PRODUCT","B-451220",$C$20,"Amount_BS")/1000)+(_xll.DBR("CXMD:FTM_DATA_BALANCE_SHEET","Total_Customer_Supplier",E$21,$C$19,ori,"TOTAL PRODUCT","B-451310",$C$20,"Amount_BS")/1000)+(_xll.DBR("CXMD:FTM_DATA_BALANCE_SHEET","Total_Customer_Supplier",E$21,$C$19,ori,"TOTAL PRODUCT","B-451450",$C$20,"Amount_BS")/1000)+(_xll.DBR("CXMD:FTM_DATA_BALANCE_SHEET","Total_Customer_Supplier",E$21,$C$19,ori,"TOTAL PRODUCT","B-451510",$C$20,"Amount_BS")/1000)+(_xll.DBR("CXMD:FTM_DATA_BALANCE_SHEET","Total_Customer_Supplier",E$21,$C$19,ori,"TOTAL PRODUCT","B-451610",$C$20,"Amount_BS")/1000)+(_xll.DBR("CXMD:FTM_DATA_BALANCE_SHEET","Total_Customer_Supplier",E$21,$C$19,ori,"TOTAL PRODUCT","B-451620",$C$20,"Amount_BS")/1000) -> 26426.217 | F35: =(_xll.DBR("CXMD:FTM_DATA_BALANCE_SHEET","Total_Customer_Supplier",F$21,$C$19,ori,"TOTAL PRODUCT","B-451010",$C$20,"Amount_BS")/1000)+(_xll.DBR("CXMD:FTM_DATA_BALANCE_SHEET","Total_Customer_Supplier",F$21,$C$19,ori,"TOTAL PRODUCT","B-451020",$C$20,"Amount_BS")/1000)+(_xll.DBR("CXMD:FTM_DATA_BALANCE_SHEET","Total_Customer_Supplier",F$21,$C$19,ori,"TOTAL PRODUCT","B-451030",$C$20,"Amount_BS")/1000)+(_xll.DBR("CXMD:FTM_DATA_BALANCE_SHEET","Total_Customer_Supplier",F$21,$C$19,ori,"TOTAL PRODUCT","B-451110",$C$20,"Amount_BS")/1000)+(_xll.DBR("CXMD:FTM_DATA_BALANCE_SHEET","Total_Customer_Supplier",F$21,$C$19,ori,"TOTAL PRODUCT","B-451210",$C$20,"Amount_BS")/1000)+(_xll.DBR("CXMD:FTM_DATA_BALANCE_SHEET","Total_Customer_Supplier",F$21,$C$19,ori,"TOTAL PRODUCT","B-451220",$C$20,"Amount_BS")/1000)+(_xll.DBR("CXMD:FTM_DATA_BALANCE_SHEET","Total_Customer_Supplier",F$21,$C$19,ori,"TOTAL PRODUCT","B-451310",$C$20,"Amount_BS")/1000)+(_xll.DBR("CXMD:FTM_DATA_BALANCE_SHEET","Total_Customer_Supplier",F$21,$C$19,ori,"TOTAL PRODUCT","B-451450",$C$20,"Amount_BS")/1000)+(_xll.DBR("CXMD:FTM_DATA_BALANCE_SHEET","Total_Customer_Supplier",F$21,$C$19,ori,"TOTAL PRODUCT","B-451510",$C$20,"Amount_BS")/1000)+(_xll.DBR("CXMD:FTM_DATA_BALANCE_SHEET","Total_Customer_Supplier",F$21,$C$19,ori,"TOTAL PRODUCT","B-451610",$C$20,"Amount_BS")/1000)+(_xll.DBR("CXMD:FTM_DATA_BALANCE_SHEET","Total_Customer_Supplier",F$21,$C$19,ori,"TOTAL PRODUCT","B-451620",$C$20,"Amount_BS")/1000) -> 33087.795 | G35: =(_xll.DBR("CXMD:FTM_DATA_BALANCE_SHEET","Total_Customer_Supplier",G$21,$C$19,ori,"TOTAL PRODUCT","B-451010",$C$20,"Amount_BS")/1000)+(_xll.DBR("CXMD:FTM_DATA_BALANCE_SHEET","Total_Customer_Supplier",G$21,$C$19,ori,"TOTAL PRODUCT","B-451020",$C$20,"Amount_BS")/1000)+(_xll.DBR("CXMD:FTM_DATA_BALANCE_SHEET","Total_Customer_Supplier",G$21,$C$19,ori,"TOTAL PRODUCT","B-451030",$C$20,"Amount_BS")/1000)+(_xll.DBR("CXMD:FTM_DATA_BALANCE_SHEET","Total_Customer_Supplier",G$21,$C$19,ori,"TOTAL PRODUCT","B-451110",$C$20,"Amount_BS")/1000)+(_xll.DBR("CXMD:FTM_DATA_BALANCE_SHEET","Total_Customer_Supplier",G$21,$C$19,ori,"TOTAL PRODUCT","B-451210",$C$20,"Amount_BS")/1000)+(_xll.DBR("CXMD:FTM_DATA_BALANCE_SHEET","Total_Customer_Supplier",G$21,$C$19,ori,"TOTAL PRODUCT","B-451220",$C$20,"Amount_BS")/1000)+(_xll.DBR("CXMD:FTM_DATA_BALANCE_SHEET","Total_Customer_Supplier",G$21,$C$19,ori,"TOTAL PRODUCT","B-451310",$C$20,"Amount_BS")/1000)+(_xll.DBR("CXMD:FTM_DATA_BALANCE_SHEET","Total_Customer_Supplier",G$21,$C$19,ori,"TOTAL PRODUCT","B-451450",$C$20,"Amount_BS")/1000)+(_xll.DBR("CXMD:FTM_DATA_BALANCE_SHEET","Total_Customer_Supplier",G$21,$C$19,ori,"TOTAL PRODUCT","B-451510",$C$20,"Amount_BS")/1000)+(_xll.DBR("CXMD:FTM_DATA_BALANCE_SHEET","Total_Customer_Supplier",G$21,$C$19,ori,"TOTAL PRODUCT","B-451610",$C$20,"Amount_BS")/1000)+(_xll.DBR("CXMD:FTM_DATA_BALANCE_SHEET","Total_Customer_Supplier",G$21,$C$19,ori,"TOTAL PRODUCT","B-451620",$C$20,"Amount_BS")/1000) -> 31767.686 | H35: =(_xll.DBR("CXMD:FTM_DATA_BALANCE_SHEET","Total_Customer_Supplier",H$21,$C$19,ori,"TOTAL PRODUCT","B-451010",$C$20,"Amount_BS")/1000)+(_xll.DBR("CXMD:FTM_DATA_BALANCE_SHEET","Total_Customer_Supplier",H$21,$C$19,ori,"TOTAL PRODUCT","B-451020",$C$20,"Amount_BS")/1000)+(_xll.DBR("CXMD:FTM_DATA_BALANCE_SHEET","Total_Customer_Supplier",H$21,$C$19,ori,"TOTAL PRODUCT","B-451030",$C$20,"Amount_BS")/1000)+(_xll.DBR("CXMD:FTM_DATA_BALANCE_SHEET","Total_Customer_Supplier",H$21,$C$19,ori,"TOTAL PRODUCT","B-451110",$C$20,"Amount_BS")/1000)+(_xll.DBR("CXMD:FTM_DATA_BALANCE_SHEET","Total_Customer_Supplier",H$21,$C$19,ori,"TOTAL PRODUCT","B-451210",$C$20,"Amount_BS")/1000)+(_xll.DBR("CXMD:FTM_DATA_BALANCE_SHEET","Total_Customer_Supplier",H$21,$C$19,ori,"TOTAL PRODUCT","B-451220",$C$20,"Amount_BS")/1000)+(_xll.DBR("CXMD:FTM_DATA_BALANCE_SHEET","Total_Customer_Supplier",H$21,$C$19,ori,"TOTAL PRODUCT","B-451310",$C$20,"Amount_BS")/1000)+(_xll.DBR("CXMD:FTM_DATA_BALANCE_SHEET","Total_Customer_Supplier",H$21,$C$19,ori,"TOTAL PRODUCT","B-451450",$C$20,"Amount_BS")/1000)+(_xll.DBR("CXMD:FTM_DATA_BALANCE_SHEET","Total_Customer_Supplier",H$21,$C$19,ori,"TOTAL PRODUCT","B-451510",$C$20,"Amount_BS")/1000)+(_xll.DBR("CXMD:FTM_DATA_BALANCE_SHEET","Total_Customer_Supplier",H$21,$C$19,ori,"TOTAL PRODUCT","B-451610",$C$20,"Amount_BS")/1000)+(_xll.DBR("CXMD:FTM_DATA_BALANCE_SHEET","Total_Customer_Supplier",H$21,$C$19,ori,"TOTAL PRODUCT","B-451620",$C$20,"Amount_BS")/1000) -> 32533.924 | I35: =(_xll.DBR("CXMD:FTM_DATA_BALANCE_SHEET","Total_Customer_Supplier",I$21,$C$19,ori,"TOTAL PRODUCT","B-451010",$C$20,"Amount_BS")/1000)+(_xll.DBR("CXMD:FTM_DATA_BALANCE_SHEET","Total_Customer_Supplier",I$21,$C$19,ori,"TOTAL PRODUCT","B-451020",$C$20,"Amount_BS")/1000)+(_xll.DBR("CXMD:FTM_DATA_BALANCE_SHEET","Total_Customer_Supplier",I$21,$C$19,ori,"TOTAL PRODUCT","B-451030",$C$20,"Amount_BS")/1000)+(_xll.DBR("CXMD:FTM_DATA_BALANCE_SHEET","Total_Customer_Supplier",I$21,$C$19,ori,"TOTAL PRODUCT","B-451110",$C$20,"Amount_BS")/1000)+(_xll.DBR("CXMD:FTM_DATA_BALANCE_SHEET","Total_Customer_Supplier",I$21,$C$19,ori,"TOTAL PRODUCT","B-451210",$C$20,"Amount_BS")/1000)+(_xll.DBR("CXMD:FTM_DATA_BALANCE_SHEET","Total_Customer_Supplier",I$21,$C$19,ori,"TOTAL PRODUCT","B-451220",$C$20,"Amount_BS")/1000)+(_xll.DBR("CXMD:FTM_DATA_BALANCE_SHEET","Total_Customer_Supplier",I$21,$C$19,ori,"TOTAL PRODUCT","B-451310",$C$20,"Amount_BS")/1000)+(_xll.DBR("CXMD:FTM_DATA_BALANCE_SHEET","Total_Customer_Supplier",I$21,$C$19,ori,"TOTAL PRODUCT","B-451450",$C$20,"Amount_BS")/1000)+(_xll.DBR("CXMD:FTM_DATA_BALANCE_SHEET","Total_Customer_Supplier",I$21,$C$19,ori,"TOTAL PRODUCT","B-451510",$C$20,"Amount_BS")/1000)+(_xll.DBR("CXMD:FTM_DATA_BALANCE_SHEET","Total_Customer_Supplier",I$21,$C$19,ori,"TOTAL PRODUCT","B-451610",$C$20,"Amount_BS")/1000)+(_xll.DBR("CXMD:FTM_DATA_BALANCE_SHEET","Total_Customer_Supplier",I$21,$C$19,ori,"TOTAL PRODUCT","B-451620",$C$20,"Amount_BS")/1000) -> 30905.344 | J35: =(_xll.DBR("CXMD:FTM_DATA_BALANCE_SHEET","Total_Customer_Supplier",J$21,$C$19,ori,"TOTAL PRODUCT","B-451010",$C$20,"Amount_BS")/1000)+(_xll.DBR("CXMD:FTM_DATA_BALANCE_SHEET","Total_Customer_Supplier",J$21,$C$19,ori,"TOTAL PRODUCT","B-451020",$C$20,"Amount_BS")/1000)+(_xll.DBR("CXMD:FTM_DATA_BALANCE_SHEET","Total_Customer_Supplier",J$21,$C$19,ori,"TOTAL PRODUCT","B-451030",$C$20,"Amount_BS")/1000)+(_xll.DBR("CXMD:FTM_DATA_BALANCE_SHEET","Total_Customer_Supplier",J$21,$C$19,ori,"TOTAL PRODUCT","B-451110",$C$20,"Amount_BS")/1000)+(_xll.DBR("CXMD:FTM_DATA_BALANCE_SHEET","Total_Customer_Supplier",J$21,$C$19,ori,"TOTAL PRODUCT","B-451210",$C$20,"Amount_BS")/1000)+(_xll.DBR("CXMD:FTM_DATA_BALANCE_SHEET","Total_Customer_Supplier",J$21,$C$19,ori,"TOTAL PRODUCT","B-451220",$C$20,"Amount_BS")/1000)+(_xll.DBR("CXMD:FTM_DATA_BALANCE_SHEET","Total_Customer_Supplier",J$21,$C$19,ori,"TOTAL PRODUCT","B-451310",$C$20,"Amount_BS")/1000)+(_xll.DBR("CXMD:FTM_DATA_BALANCE_SHEET","Total_Customer_Supplier",J$21,$C$19,ori,"TOTAL PRODUCT","B-451450",$C$20,"Amount_BS")/1000)+(_xll.DBR("CXMD:FTM_DATA_BALANCE_SHEET","Total_Customer_Supplier",J$21,$C$19,ori,"TOTAL PRODUCT","B-451510",$C$20,"Amount_BS")/1000)+(_xll.DBR("CXMD:FTM_DATA_BALANCE_SHEET","Total_Customer_Supplier",J$21,$C$19,ori,"TOTAL PRODUCT","B-451610",$C$20,"Amount_BS")/1000)+(_xll.DBR("CXMD:FTM_DATA_BALANCE_SHEET","Total_Customer_Supplier",J$21,$C$19,ori,"TOTAL PRODUCT","B-451620",$C$20,"Amount_BS")/1000) -> 28625.412 | K35: =(_xll.DBR("CXMD:FTM_DATA_BALANCE_SHEET","Total_Customer_Supplier",K$21,$C$19,ori,"TOTAL PRODUCT","B-451010",$C$20,"Amount_BS")/1000)+(_xll.DBR("CXMD:FTM_DATA_BALANCE_SHEET","Total_Customer_Supplier",K$21,$C$19,ori,"TOTAL PRODUCT","B-451020",$C$20,"Amount_BS")/1000)+(_xll.DBR("CXMD:FTM_DATA_BALANCE_SHEET","Total_Customer_Supplier",K$21,$C$19,ori,"TOTAL PRODUCT","B-451030",$C$20,"Amount_BS")/1000)+(_xll.DBR("CXMD:FTM_DATA_BALANCE_SHEET","Total_Customer_Supplier",K$21,$C$19,ori,"TOTAL PRODUCT","B-451110",$C$20,"Amount_BS")/1000)+(_xll.DBR("CXMD:FTM_DATA_BALANCE_SHEET","Total_Customer_Supplier",K$21,$C$19,ori,"TOTAL PRODUCT","B-451210",$C$20,"Amount_BS")/1000)+(_xll.DBR("CXMD:FTM_DATA_BALANCE_SHEET","Total_Customer_Supplier",K$21,$C$19,ori,"TOTAL PRODUCT","B-451220",$C$20,"Amount_BS")/1000)+(_xll.DBR("CXMD:FTM_DATA_BALANCE_SHEET","Total_Customer_Supplier",K$21,$C$19,ori,"TOTAL PRODUCT","B-451310",$C$20,"Amount_BS")/1000)+(_xll.DBR("CXMD:FTM_DATA_BALANCE_SHEET","Total_Customer_Supplier",K$21,$C$19,ori,"TOTAL PRODUCT","B-451450",$C$20,"Amount_BS")/1000)+(_xll.DBR("CXMD:FTM_DATA_BALANCE_SHEET","Total_Customer_Supplier",K$21,$C$19,ori,"TOTAL PRODUCT","B-451510",$C$20,"Amount_BS")/1000)+(_xll.DBR("CXMD:FTM_DATA_BALANCE_SHEET","Total_Customer_Supplier",K$21,$C$19,ori,"TOTAL PRODUCT","B-451610",$C$20,"Amount_BS")/1000)+(_xll.DBR("CXMD:FTM_DATA_BALANCE_SHEET","Total_Customer_Supplier",K$21,$C$19,ori,"TOTAL PRODUCT","B-451620",$C$20,"Amount_BS")/1000) -> 26762.875 | ... O35: =(_xll.DBR("CXMD:FTM_DATA_BALANCE_SHEET","Total_Customer_Supplier",O$21,$C$19,ori,"TOTAL PRODUCT","B-451010",$C$20,"Amount_BS")/1000)+(_xll.DBR("CXMD:FTM_DATA_BALANCE_SHEET","Total_Customer_Supplier",O$21,$C$19,ori,"TOTAL PRODUCT","B-451020",$C$20,"Amount_BS")/1000)+(_xll.DBR("CXMD:FTM_DATA_BALANCE_SHEET","Total_Customer_Supplier",O$21,$C$19,ori,"TOTAL PRODUCT","B-451030",$C$20,"Amount_BS")/1000)+(_xll.DBR("CXMD:FTM_DATA_BALANCE_SHEET","Total_Customer_Supplier",O$21,$C$19,ori,"TOTAL PRODUCT","B-451110",$C$20,"Amount_BS")/1000)+(_xll.DBR("CXMD:FTM_DATA_BALANCE_SHEET","Total_Customer_Supplier",O$21,$C$19,ori,"TOTAL PRODUCT","B-451210",$C$20,"Amount_BS")/1000)+(_xll.DBR("CXMD:FTM_DATA_BALANCE_SHEET","Total_Customer_Supplier",O$21,$C$19,ori,"TOTAL PRODUCT","B-451220",$C$20,"Amount_BS")/1000)+(_xll.DBR("CXMD:FTM_DATA_BALANCE_SHEET","Total_Customer_Supplier",O$21,$C$19,ori,"TOTAL PRODUCT","B-451310",$C$20,"Amount_BS")/1000)+(_xll.DBR("CXMD:FTM_DATA_BALANCE_SHEET","Total_Customer_Supplier",O$21,$C$19,ori,"TOTAL PRODUCT","B-451450",$C$20,"Amount_BS")/1000)+(_xll.DBR("CXMD:FTM_DATA_BALANCE_SHEET","Total_Customer_Supplier",O$21,$C$19,ori,"TOTAL PRODUCT","B-451510",$C$20,"Amount_BS")/1000)+(_xll.DBR("CXMD:FTM_DATA_BALANCE_SHEET","Total_Customer_Supplier",O$21,$C$19,ori,"TOTAL PRODUCT","B-451610",$C$20,"Amount_BS")/1000)+(_xll.DBR("CXMD:FTM_DATA_BALANCE_SHEET","Total_Customer_Supplier",O$21,$C$19,ori,"TOTAL PRODUCT","B-451620",$C$20,"Amount_BS")/1000) -> 31415.092 | P35: =SUM(D35:O35) -> 371754.65
C36: % of corporate output | D36: =IF(D25<>0,D35/D25,0) -> 0.088981621 | E36: =IF(E25<>0,E35/E25,0) -> 0.07944128 | F36: =IF(F25<>0,F35/F25,0) -> 0.089021541 | G36: =IF(G25<>0,G35/G25,0) -> 0.099988831 | H36: =IF(H25<>0,H35/H25,0) -> 0.084964092 | I36: =IF(I25<>0,I35/I25,0) -> 0.083232174 | J36: =IF(J25<>0,J35/J25,0) -> 0.079251445 | K36: =IF(K25<>0,K35/K25,0) -> 0.073798271 | ... P36: =IF(P25<>0,P35/P25,0) -> 0.091046334
B37: G - 453900 - FX GAIN/LOSS | C37: Profit and Loss | D37: =_xll.DBR("CXMD:FTM_DATA_BALANCE_SHEET","Total_Customer_Supplier",D$21,$C$19,ori,"TOTAL PRODUCT","B-453010",$C$20,"Amount_BS")/1000 -> -14389.183 | E37: =_xll.DBR("CXMD:FTM_DATA_BALANCE_SHEET","Total_Customer_Supplier",E$21,$C$19,ori,"TOTAL PRODUCT","B-453010",$C$20,"Amount_BS")/1000 -> 4247.0622 | F37: =_xll.DBR("CXMD:FTM_DATA_BALANCE_SHEET","Total_Customer_Supplier",F$21,$C$19,ori,"TOTAL PRODUCT","B-453010",$C$20,"Amount_BS")/1000 -> 2508.6431 | G37: =_xll.DBR("CXMD:FTM_DATA_BALANCE_SHEET","Total_Customer_Supplier",G$21,$C$19,ori,"TOTAL PRODUCT","B-453010",$C$20,"Amount_BS")/1000 -> 599.29278 | H37: =_xll.DBR("CXMD:FTM_DATA_BALANCE_SHEET","Total_Customer_Supplier",H$21,$C$19,ori,"TOTAL PRODUCT","B-453010",$C$20,"Amount_BS")/1000 -> -466.32202 | I37: =_xll.DBR("CXMD:FTM_DATA_BALANCE_SHEET","Total_Customer_Supplier",I$21,$C$19,ori,"TOTAL PRODUCT","B-453010",$C$20,"Amount_BS")/1000 -> 96.67575 | J37: =_xll.DBR("CXMD:FTM_DATA_BALANCE_SHEET","Total_Customer_Supplier",J$21,$C$19,ori,"TOTAL PRODUCT","B-453010",$C$20,"Amount_BS")/1000 -> 2041.2399 | K37: =_xll.DBR("CXMD:FTM_DATA_BALANCE_SHEET","Total_Customer_Supplier",K$21,$C$19,ori,"TOTAL PRODUCT","B-453010",$C$20,"Amount_BS")/1000 -> -1527.4297 | ... O37: =_xll.DBR("CXMD:FTM_DATA_BALANCE_SHEET","Total_Customer_Supplier",O$21,$C$19,ori,"TOTAL PRODUCT","B-453010",$C$20,"Amount_BS")/1000 -> 2811.9654 | P37: =SUM(D37:O37) -> -3499.1707
B38: G - 479000 - DEPREC. PROV. | C38: Profit and Loss | D38: =(_xll.DBR("CXMD:FTM_DATA_BALANCE_SHEET","Total_Customer_Supplier",D$21,$C$19,ori,"TOTAL PRODUCT","B-470010",$C$20,"Amount_BS")/1000)+(_xll.DBR("CXMD:FTM_DATA_BALANCE_SHEET","Total_Customer_Supplier",D$21,$C$19,ori,"TOTAL PRODUCT","B-475010",$C$20,"Amount_BS")/1000) -> 3386.485 | E38: =(_xll.DBR("CXMD:FTM_DATA_BALANCE_SHEET","Total_Customer_Supplier",E$21,$C$19,ori,"TOTAL PRODUCT","B-470010",$C$20,"Amount_BS")/1000)+(_xll.DBR("CXMD:FTM_DATA_BALANCE_SHEET","Total_Customer_Supplier",E$21,$C$19,ori,"TOTAL PRODUCT","B-475010",$C$20,"Amount_BS")/1000) -> 3446.382 | F38: =(_xll.DBR("CXMD:FTM_DATA_BALANCE_SHEET","Total_Customer_Supplier",F$21,$C$19,ori,"TOTAL PRODUCT","B-470010",$C$20,"Amount_BS")/1000)+(_xll.DBR("CXMD:FTM_DATA_BALANCE_SHEET","Total_Customer_Supplier",F$21,$C$19,ori,"TOTAL PRODUCT","B-475010",$C$20,"Amount_BS")/1000) -> 3248.5829 | G38: =(_xll.DBR("CXMD:FTM_DATA_BALANCE_SHEET","Total_Customer_Supplier",G$21,$C$19,ori,"TOTAL PRODUCT","B-470010",$C$20,"Amount_BS")/1000)+(_xll.DBR("CXMD:FTM_DATA_BALANCE_SHEET","Total_Customer_Supplier",G$21,$C$19,ori,"TOTAL PRODUCT","B-475010",$C$20,"Amount_BS")/1000) -> 3315.1649 | H38: =(_xll.DBR("CXMD:FTM_DATA_BALANCE_SHEET","Total_Customer_Supplier",H$21,$C$19,ori,"TOTAL PRODUCT","B-470010",$C$20,"Amount_BS")/1000)+(_xll.DBR("CXMD:FTM_DATA_BALANCE_SHEET","Total_Customer_Supplier",H$21,$C$19,ori,"TOTAL PRODUCT","B-475010",$C$20,"Amount_BS")/1000) -> 3356.0762 | I38: =(_xll.DBR("CXMD:FTM_DATA_BALANCE_SHEET","Total_Customer_Supplier",I$21,$C$19,ori,"TOTAL PRODUCT","B-470010",$C$20,"Amount_BS")/1000)+(_xll.DBR("CXMD:FTM_DATA_BALANCE_SHEET","Total_Customer_Supplier",I$21,$C$19,ori,"TOTAL PRODUCT","B-475010",$C$20,"Amount_BS")/1000) -> 3390.1403 | J38: =(_xll.DBR("CXMD:FTM_DATA_BALANCE_SHEET","Total_Customer_Supplier",J$21,$C$19,ori,"TOTAL PRODUCT","B-470010",$C$20,"Amount_BS")/1000)+(_xll.DBR("CXMD:FTM_DATA_BALANCE_SHEET","Total_Customer_Supplier",J$21,$C$19,ori,"TOTAL PRODUCT","B-475010",$C$20,"Amount_BS")/1000) -> 3385.8418 | K38: =(_xll.DBR("CXMD:FTM_DATA_BALANCE_SHEET","Total_Customer_Supplier",K$21,$C$19,ori,"TOTAL PRODUCT","B-470010",$C$20,"Amount_BS")/1000)+(_xll.DBR("CXMD:FTM_DATA_BALANCE_SHEET","Total_Customer_Supplier",K$21,$C$19,ori,"TOTAL PRODUCT","B-475010",$C$20,"Amount_BS")/1000) -> 3432.8227 | ... O38: =(_xll.DBR("CXMD:FTM_DATA_BALANCE_SHEET","Total_Customer_Supplier",O$21,$C$19,ori,"TOTAL PRODUCT","B-470010",$C$20,"Amount_BS")/1000)+(_xll.DBR("CXMD:FTM_DATA_BALANCE_SHEET","Total_Customer_Supplier",O$21,$C$19,ori,"TOTAL PRODUCT","B-475010",$C$20,"Amount_BS")/1000) -> 3300.1832 | P38: =SUM(D38:O38) -> 39702.352
B39: Ebit without Management fees | D39: =D27-D29-D33-D35-D37-D38-D28 -> 86917.47 | E39: =E27-E29-E33-E35-E37-E38-E28 -> 70173.044 | F39: =F27-F29-F33-F35-F37-F38-F28 -> 42198.06 | G39: =G27-G29-G33-G35-G37-G38-G28 -> 36734.624 | H39: =H27-H29-H33-H35-H37-H38-H28 -> 68398.344 | I39: =I27-I29-I33-I35-I37-I38-I28 -> 62307.064 | J39: =J27-J29-J33-J35-J37-J38-J28 -> 70679.445 | K39: =K27-K29-K33-K35-K37-K38-K28 -> 106805.41 | ... O39: =O27-O29-O33-O35-O37-O38-O28 -> 16398.408 | P39: =SUM(D39:O39) -> 693916.26
C40: % of net sales | D40: =IF(D23<>0,D39/D23,0) -> 0.24154242 | E40: =IF(E23<>0,E39/E23,0) -> 0.20617793 | F40: =IF(F23<>0,F39/F23,0) -> 0.11924864 | G40: =IF(G23<>0,G39/G23,0) -> 0.11364577 | H40: =IF(H23<>0,H39/H23,0) -> 0.19029443 | I40: =IF(I23<>0,I39/I23,0) -> 0.16401183 | J40: =IF(J23<>0,J39/J23,0) -> 0.18595233 | K40: =IF(K23<>0,K39/K23,0) -> 0.29433219 | ... P40: =IF(P23<>0,P39/P23,0) -> 0.170384
B41: G - 569199 - OTHER INCOME/EXPENSES | C41: Profit and Loss | D41: =(_xll.DBR("CXMD:FTM_DATA_BALANCE_SHEET","Total_Customer_Supplier",D$21,$C$19,ori,"TOTAL PRODUCT","B-560020",$C$20,"Amount_BS")/1000)+(_xll.DBR("CXMD:FTM_DATA_BALANCE_SHEET","Total_Customer_Supplier",D$21,$C$19,ori,"TOTAL PRODUCT","B-561010",$C$20,"Amount_BS")/1000) -> 462.46413 | E41: =(_xll.DBR("CXMD:FTM_DATA_BALANCE_SHEET","Total_Customer_Supplier",E$21,$C$19,ori,"TOTAL PRODUCT","B-560020",$C$20,"Amount_BS")/1000)+(_xll.DBR("CXMD:FTM_DATA_BALANCE_SHEET","Total_Customer_Supplier",E$21,$C$19,ori,"TOTAL PRODUCT","B-561010",$C$20,"Amount_BS")/1000) -> 462.46413 | F41: =(_xll.DBR("CXMD:FTM_DATA_BALANCE_SHEET","Total_Customer_Supplier",F$21,$C$19,ori,"TOTAL PRODUCT","B-560020",$C$20,"Amount_BS")/1000)+(_xll.DBR("CXMD:FTM_DATA_BALANCE_SHEET","Total_Customer_Supplier",F$21,$C$19,ori,"TOTAL PRODUCT","B-561010",$C$20,"Amount_BS")/1000) -> 462.46413 | G41: =(_xll.DBR("CXMD:FTM_DATA_BALANCE_SHEET","Total_Customer_Supplier",G$21,$C$19,ori,"TOTAL PRODUCT","B-560020",$C$20,"Amount_BS")/1000)+(_xll.DBR("CXMD:FTM_DATA_BALANCE_SHEET","Total_Customer_Supplier",G$21,$C$19,ori,"TOTAL PRODUCT","B-561010",$C$20,"Amount_BS")/1000) -> 799.42713 | H41: =(_xll.DBR("CXMD:FTM_DATA_BALANCE_SHEET","Total_Customer_Supplier",H$21,$C$19,ori,"TOTAL PRODUCT","B-560020",$C$20,"Amount_BS")/1000)+(_xll.DBR("CXMD:FTM_DATA_BALANCE_SHEET","Total_Customer_Supplier",H$21,$C$19,ori,"TOTAL PRODUCT","B-561010",$C$20,"Amount_BS")/1000) -> 462.46413 | I41: =(_xll.DBR("CXMD:FTM_DATA_BALANCE_SHEET","Total_Customer_Supplier",I$21,$C$19,ori,"TOTAL PRODUCT","B-560020",$C$20,"Amount_BS")/1000)+(_xll.DBR("CXMD:FTM_DATA_BALANCE_SHEET","Total_Customer_Supplier",I$21,$C$19,ori,"TOTAL PRODUCT","B-561010",$C$20,"Amount_BS")/1000) -> 462.46413 | J41: =(_xll.DBR("CXMD:FTM_DATA_BALANCE_SHEET","Total_Customer_Supplier",J$21,$C$19,ori,"TOTAL PRODUCT","B-560020",$C$20,"Amount_BS")/1000)+(_xll.DBR("CXMD:FTM_DATA_BALANCE_SHEET","Total_Customer_Supplier",J$21,$C$19,ori,"TOTAL PRODUCT","B-561010",$C$20,"Amount_BS")/1000) -> 462.46413 | K41: =(_xll.DBR("CXMD:FTM_DATA_BALANCE_SHEET","Total_Customer_Supplier",K$21,$C$19,ori,"TOTAL PRODUCT","B-560020",$C$20,"Amount_BS")/1000)+(_xll.DBR("CXMD:FTM_DATA_BALANCE_SHEET","Total_Customer_Supplier",K$21,$C$19,ori,"TOTAL PRODUCT","B-561010",$C$20,"Amount_BS")/1000) -> 462.46413 | ... O41: =(_xll.DBR("CXMD:FTM_DATA_BALANCE_SHEET","Total_Customer_Supplier",O$21,$C$19,ori,"TOTAL PRODUCT","B-560020",$C$20,"Amount_BS")/1000)+(_xll.DBR("CXMD:FTM_DATA_BALANCE_SHEET","Total_Customer_Supplier",O$21,$C$19,ori,"TOTAL PRODUCT","B-561010",$C$20,"Amount_BS")/1000) -> 98.3356 | P41: =SUM(D41:O41) -> 5895.958
B42: Ebit including Management fees | D42: =D39-D41 -> 86455.006 | E42: =E39-E41 -> 69710.58 | F42: =F39-F41 -> 41735.596 | G42: =G39-G41 -> 35935.197 | H42: =H39-H41 -> 67935.88 | I42: =I39-I41 -> 61844.6 | J42: =J39-J41 -> 70216.981 | K42: =K39-K41 -> 106342.95 | ... O42: =O39-O41 -> 16300.072 | P42: =SUM(D42:O42) -> 688020.3
C43: % of net sales | D43: =IF(D23<>0,D42/D23,0) -> 0.24025724 | E43: =IF(E23<>0,E42/E23,0) -> 0.20481915 | F43: =IF(F23<>0,F42/F23,0) -> 0.11794175 | G43: =IF(G23<>0,G42/G23,0) -> 0.11117259 | H43: =IF(H23<>0,H42/H23,0) -> 0.18900778 | I43: =IF(I23<>0,I42/I23,0) -> 0.16279448 | J43: =IF(J23<>0,J42/J23,0) -> 0.18473562 | K43: =IF(K23<>0,K42/K23,0) -> 0.29305774 | ... P43: =IF(P23<>0,P42/P23,0) -> 0.1689363

Sheet P&L Month YTD by CC summary
B18: Origin_Company | C18: =origine -> Total Origin Company | H18: P&L Month YTD _ summary
B19: Actuality | C19: ='P&L Month by CC summary'!C19 -> AC2022
B20: Allocation | C20: ='P&L Month by CC summary'!C20 -> Total Allocation
C21: in K Local Currency | D21: YTD_January | E21: YTD_February | F21: YTD_March | G21: YTD_April | H21: YTD_May | I21: YTD_June | J21: YTD_July | K21: YTD_August | L21: YTD_September | M21: YTD_October | N21: YTD_November | O21: YTD_December
B22: Bucher Account
B23: G - 309000 - NET SALES | C23: Profit and Loss | D23: =_xll.DBR("CXMD:FTM_DATA_BALANCE_SHEET","Total_Customer_Supplier",D$21,$C$19,ori,"TOTAL PRODUCT","B-300010",$C$20,"Amount_BS")*-1/1000 -> 359843.49 | E23: =_xll.DBR("CXMD:FTM_DATA_BALANCE_SHEET","Total_Customer_Supplier",E$21,$C$19,ori,"TOTAL PRODUCT","B-300010",$C$20,"Amount_BS")*-1/1000 -> 700195.37 | F23: =_xll.DBR("CXMD:FTM_DATA_BALANCE_SHEET","Total_Customer_Supplier",F$21,$C$19,ori,"TOTAL PRODUCT","B-300010",$C$20,"Amount_BS")*-1/1000 -> 1054061.5 | G23: =_xll.DBR("CXMD:FTM_DATA_BALANCE_SHEET","Total_Customer_Supplier",G$21,$C$19,ori,"TOTAL PRODUCT","B-300010",$C$20,"Amount_BS")*-1/1000 -> 1377299.5 | H23: =_xll.DBR("CXMD:FTM_DATA_BALANCE_SHEET","Total_Customer_Supplier",H$21,$C$19,ori,"TOTAL PRODUCT","B-300010",$C$20,"Amount_BS")*-1/1000 -> 1736733.8 | I23: =_xll.DBR("CXMD:FTM_DATA_BALANCE_SHEET","Total_Customer_Supplier",I$21,$C$19,ori,"TOTAL PRODUCT","B-300010",$C$20,"Amount_BS")*-1/1000 -> 2116627.5 | J23: =_xll.DBR("CXMD:FTM_DATA_BALANCE_SHEET","Total_Customer_Supplier",J$21,$C$19,ori,"TOTAL PRODUCT","B-300010",$C$20,"Amount_BS")*-1/1000 -> 2496721.9 | K23: =_xll.DBR("CXMD:FTM_DATA_BALANCE_SHEET","Total_Customer_Supplier",K$21,$C$19,ori,"TOTAL PRODUCT","B-300010",$C$20,"Amount_BS")*-1/1000 -> 2859595.6 | ... O23: =_xll.DBR("CXMD:FTM_DATA_BALANCE_SHEET","Total_Customer_Supplier",O$21,$C$19,ori,"TOTAL PRODUCT","B-300010",$C$20,"Amount_BS")*-1/1000 -> 4072661.1
B24: G - 319000 - NET VARIATION OF STOCK | C24: Profit and Loss | D24: =_xll.DBR("CXMD:FTM_DATA_BALANCE_SHEET","Total_Customer_Supplier",D$21,$C$19,ori,"TOTAL PRODUCT","B-310010",$C$20,"Amount_BS")*-1/1000 -> -30807.778 | E24: =_xll.DBR("CXMD:FTM_DATA_BALANCE_SHEET","Total_Customer_Supplier",E$21,$C$19,ori,"TOTAL PRODUCT","B-310010",$C$20,"Amount_BS")*-1/1000 -> -38508.695 | F24: =_xll.DBR("CXMD:FTM_DATA_BALANCE_SHEET","Total_Customer_Supplier",F$21,$C$19,ori,"TOTAL PRODUCT","B-310010",$C$20,"Amount_BS")*-1/1000 -> -20691.849 | G24: =_xll.DBR("CXMD:FTM_DATA_BALANCE_SHEET","Total_Customer_Supplier",G$21,$C$19,ori,"TOTAL PRODUCT","B-310010",$C$20,"Amount_BS")*-1/1000 -> -26217.428 | H24: =_xll.DBR("CXMD:FTM_DATA_BALANCE_SHEET","Total_Customer_Supplier",H$21,$C$19,ori,"TOTAL PRODUCT","B-310010",$C$20,"Amount_BS")*-1/1000 -> -2737.9111 | I24: =_xll.DBR("CXMD:FTM_DATA_BALANCE_SHEET","Total_Customer_Supplier",I$21,$C$19,ori,"TOTAL PRODUCT","B-310010",$C$20,"Amount_BS")*-1/1000 -> -11316.758 | J24: =_xll.DBR("CXMD:FTM_DATA_BALANCE_SHEET","Total_Customer_Supplier",J$21,$C$19,ori,"TOTAL PRODUCT","B-310010",$C$20,"Amount_BS")*-1/1000 -> -30213.846 | K24: =_xll.DBR("CXMD:FTM_DATA_BALANCE_SHEET","Total_Customer_Supplier",K$21,$C$19,ori,"TOTAL PRODUCT","B-310010",$C$20,"Amount_BS")*-1/1000 -> -30438.473 | ... O24: =_xll.DBR("CXMD:FTM_DATA_BALANCE_SHEET","Total_Customer_Supplier",O$21,$C$19,ori,"TOTAL PRODUCT","B-310010",$C$20,"Amount_BS")*-1/1000 -> 10475.845
B25: G-329000 Corporate output | D25: =D23+D24 -> 329035.72 | E25: =E23+E24 -> 661686.67 | F25: =F23+F24 -> 1033369.7 | G25: =G23+G24 -> 1351082 | H25: =H23+H24 -> 1733995.9 | I25: =I23+I24 -> 2105310.7 | J25: =J23+J24 -> 2466508.1 | K25: =K23+K24 -> 2829157.2 | ... O25: =O23+O24 -> 4083136.9
B26: G - 339000 - OPERATING INCOME | C26: Profit and Loss | D26: =_xll.DBR("CXMD:FTM_DATA_BALANCE_SHEET","Total_Customer_Supplier",D$21,$C$19,ori,"TOTAL PRODUCT","B-330010",$C$20,"Amount_BS")*-1/1000 -> 4042.3655 | E26: =_xll.DBR("CXMD:FTM_DATA_BALANCE_SHEET","Total_Customer_Supplier",E$21,$C$19,ori,"TOTAL PRODUCT","B-330010",$C$20,"Amount_BS")*-1/1000 -> 8583.2908 | F26: =_xll.DBR("CXMD:FTM_DATA_BALANCE_SHEET","Total_Customer_Supplier",F$21,$C$19,ori,"TOTAL PRODUCT","B-330010",$C$20,"Amount_BS")*-1/1000 -> 13431.463 | G26: =_xll.DBR("CXMD:FTM_DATA_BALANCE_SHEET","Total_Customer_Supplier",G$21,$C$19,ori,"TOTAL PRODUCT","B-330010",$C$20,"Amount_BS")*-1/1000 -> 17830.42 | H26: =_xll.DBR("CXMD:FTM_DATA_BALANCE_SHEET","Total_Customer_Supplier",H$21,$C$19,ori,"TOTAL PRODUCT","B-330010",$C$20,"Amount_BS")*-1/1000 -> 22213.297 | I26: =_xll.DBR("CXMD:FTM_DATA_BALANCE_SHEET","Total_Customer_Supplier",I$21,$C$19,ori,"TOTAL PRODUCT","B-330010",$C$20,"Amount_BS")*-1/1000 -> 26939.953 | J26: =_xll.DBR("CXMD:FTM_DATA_BALANCE_SHEET","Total_Customer_Supplier",J$21,$C$19,ori,"TOTAL PRODUCT","B-330010",$C$20,"Amount_BS")*-1/1000 -> 31469.609 | K26: =_xll.DBR("CXMD:FTM_DATA_BALANCE_SHEET","Total_Customer_Supplier",K$21,$C$19,ori,"TOTAL PRODUCT","B-330010",$C$20,"Amount_BS")*-1/1000 -> 35826.213 | ... O26: =_xll.DBR("CXMD:FTM_DATA_BALANCE_SHEET","Total_Customer_Supplier",O$21,$C$19,ori,"TOTAL PRODUCT","B-330010",$C$20,"Amount_BS")*-1/1000 -> 52175.87
B27: REVENUE | D27: =D25+D26 -> 333078.08 | E27: =E25+E26 -> 670269.96 | F27: =F25+F26 -> 1046801.2 | G27: =G25+G26 -> 1368912.5 | H27: =H25+H26 -> 1756209.2 | I27: =I25+I26 -> 2132250.7 | J27: =J25+J26 -> 2497977.7 | K27: =K25+K26 -> 2864983.4 | ... O27: =O25+O26 -> 4135312.8
B28: G - 452000 - VARIATION OF PROVISIONS | C28: Profit and Loss | D28: =(_xll.DBR("CXMD:FTM_DATA_BALANCE_SHEET","Total_Customer_Supplier",D$21,$C$19,ori,"TOTAL PRODUCT","B-452010",$C$20,"Amount_BS")/1000)+(_xll.DBR("CXMD:FTM_DATA_BALANCE_SHEET","Total_Customer_Supplier",D$21,$C$19,ori,"TOTAL PRODUCT","B-452210",$C$20,"Amount_BS")/1000) -> 442.07326 | E28: =(_xll.DBR("CXMD:FTM_DATA_BALANCE_SHEET","Total_Customer_Supplier",E$21,$C$19,ori,"TOTAL PRODUCT","B-452010",$C$20,"Amount_BS")/1000)+(_xll.DBR("CXMD:FTM_DATA_BALANCE_SHEET","Total_Customer_Supplier",E$21,$C$19,ori,"TOTAL PRODUCT","B-452210",$C$20,"Amount_BS")/1000) -> 247.15668 | F28: =(_xll.DBR("CXMD:FTM_DATA_BALANCE_SHEET","Total_Customer_Supplier",F$21,$C$19,ori,"TOTAL PRODUCT","B-452010",$C$20,"Amount_BS")/1000)+(_xll.DBR("CXMD:FTM_DATA_BALANCE_SHEET","Total_Customer_Supplier",F$21,$C$19,ori,"TOTAL PRODUCT","B-452210",$C$20,"Amount_BS")/1000) -> 1860.5594 | G28: =(_xll.DBR("CXMD:FTM_DATA_BALANCE_SHEET","Total_Customer_Supplier",G$21,$C$19,ori,"TOTAL PRODUCT","B-452010",$C$20,"Amount_BS")/1000)+(_xll.DBR("CXMD:FTM_DATA_BALANCE_SHEET","Total_Customer_Supplier",G$21,$C$19,ori,"TOTAL PRODUCT","B-452210",$C$20,"Amount_BS")/1000) -> 3118.3911 | H28: =(_xll.DBR("CXMD:FTM_DATA_BALANCE_SHEET","Total_Customer_Supplier",H$21,$C$19,ori,"TOTAL PRODUCT","B-452010",$C$20,"Amount_BS")/1000)+(_xll.DBR("CXMD:FTM_DATA_BALANCE_SHEET","Total_Customer_Supplier",H$21,$C$19,ori,"TOTAL PRODUCT","B-452210",$C$20,"Amount_BS")/1000) -> 3052.1005 | I28: =(_xll.DBR("CXMD:FTM_DATA_BALANCE_SHEET","Total_Customer_Supplier",I$21,$C$19,ori,"TOTAL PRODUCT","B-452010",$C$20,"Amount_BS")/1000)+(_xll.DBR("CXMD:FTM_DATA_BALANCE_SHEET","Total_Customer_Supplier",I$21,$C$19,ori,"TOTAL PRODUCT","B-452210",$C$20,"Amount_BS")/1000) -> 3596.8589 | J28: =(_xll.DBR("CXMD:FTM_DATA_BALANCE_SHEET","Total_Customer_Supplier",J$21,$C$19,ori,"TOTAL PRODUCT","B-452010",$C$20,"Amount_BS")/1000)+(_xll.DBR("CXMD:FTM_DATA_BALANCE_SHEET","Total_Customer_Supplier",J$21,$C$19,ori,"TOTAL PRODUCT","B-452210",$C$20,"Amount_BS")/1000) -> 5073.9976 | K28: =(_xll.DBR("CXMD:FTM_DATA_BALANCE_SHEET","Total_Customer_Supplier",K$21,$C$19,ori,"TOTAL PRODUCT","B-452010",$C$20,"Amount_BS")/1000)+(_xll.DBR("CXMD:FTM_DATA_BALANCE_SHEET","Total_Customer_Supplier",K$21,$C$19,ori,"TOTAL PRODUCT","B-452210",$C$20,"Amount_BS")/1000) -> 5982.9797 | ... O28: =(_xll.DBR("CXMD:FTM_DATA_BALANCE_SHEET","Total_Customer_Supplier",O$21,$C$19,ori,"TOTAL PRODUCT","B-452010",$C$20,"Amount_BS")/1000)+(_xll.DBR("CXMD:FTM_DATA_BALANCE_SHEET","Total_Customer_Supplier",O$21,$C$19,ori,"TOTAL PRODUCT","B-452210",$C$20,"Amount_BS")/1000) -> 29689.028
