Workbook
Name TM1REBUILDOPTION: 1
Name TM1RPTDATARNGARPT1: 'SOM detailed_Global Market'!$25:$180
Name TM1RPTDATARNGARPT1: 'SOM detailed_Kuhn Scope'!$31:$31
Name TM1RPTDATARNGARPT1: 'SOM Summary_Kuhn Scope'!$27:$49
Name TM1RPTFMTIDCOL: 'SOM detailed_Global Market'!$A$1:$A$8
Name TM1RPTFMTIDCOL: 'SOM detailed_Kuhn Scope'!$A$1:$A$8
Name TM1RPTFMTIDCOL: 'SOM Summary_Kuhn Scope'!$A$1:$A$8
Name TM1RPTFMTRNG: 'SOM detailed_Global Market'!$B$1:$AL$8
Name TM1RPTFMTRNG: 'SOM detailed_Kuhn Scope'!$G$1:$AK$8
Name TM1RPTFMTRNG: 'SOM Summary_Kuhn Scope'!$B$1:$AF$8

Sheet Cognos_Office_Connection_Cache

Sheet SOM Summary_Kuhn Scope
A1: [Begin Format Range]
A2: =0 -> 0
A3: =1 -> 1
A4: =2 -> 2
A5: =3 -> 3
A6: D
A7: N
A8: [End Format Range]
B9: =_xll.TM1RPTVIEW("CXMD:OTC_DATA_MARKET_ANALYSIS:ARPT1", 0, _xll.TM1RPTTITLE("CXMD:Currency",$C$17), _xll.TM1RPTTITLE("CXMD:DIM_Prev_IC_mapping",$C$18), _xll.TM1RPTTITLE("CXMD:DIM_Origin_Company",$C$20), _xll.TM1RPTTITLE("CXMD:DIM_Country",$C$21),TM1RPTFMTRNG,TM1RPTFMTIDCOL) -> CXMD:OTC_DATA_MARKET_ANALYSIS:ARPT1
B17: Currency | C17: =_xll.SUBNM("CXMD:Currency","Par défaut","CD_LC","Description EN") -> Local currency
B18: Prev_IC_mapping | C18: =_xll.SUBNM("CXMD:DIM_Prev_IC_mapping","","Others") -> Others
B19: MARKET SHARES - 4 PERIODS
B20: Origin_Company | C20: =_xll.SUBNM("CXMD:DIM_Origin_Company","","D","Name EN") -> KUHN GERMANY
B21: Country | C21: =_xll.SUBNM("CXMD:DIM_Country","","C-101","Country Name EN") -> GERMANY
C24: =_xll.SUBNM("CXMD:Actuality","","AC2020","Description EN") -> AC2020 | F24: =_xll.SUBNM("CXMD:Actuality","","AC2020","Description EN") -> AC2020 | I24: Market Share % | K24: =_xll.SUBNM("CXMD:Actuality","","AC2021","Description EN") -> AC2021 | N24: =_xll.SUBNM("CXMD:Actuality","","AC2021","Description EN") -> AC2021 | Q24: Market Share % | S24: =_xll.SUBNM("CXMD:Actuality","","FC3_2022","Description EN") -> FC3_2022 | V24: =_xll.SUBNM("CXMD:Actuality","","FC3_2022","Description EN") -> FC3_2022 | Y24: Market Share % | AA24: =_xll.SUBNM("CXMD:Actuality","","BU2023draft") -> BU2023draft | AD24: =_xll.SUBNM("CXMD:Actuality","","BU2023draft") -> BU2023draft | AG24: Market Share %
C25: KUHN Sales | F25: KUHN_Scope | K25: KUHN Sales | N25: KUHN_Scope | S25: KUHN Sales | V25: KUHN_Scope | AA25: KUHN Sales | AD25: KUHN_Scope
C26: QTY | D26: Unit.Price | E26: SALES | F26: QTY | G26: Unit.Price | H26: SALES | I26: QTY | J26: SALES | K26: QTY | L26: Unit.Price | M26: SALES | N26: QTY | O26: Unit.Price | P26: SALES | Q26: QTY | R26: SALES | S26: QTY | T26: Unit.Price | U26: SALES | V26: QTY | W26: Unit.Price | X26: SALES | Y26: QTY | Z26: SALES | AA26: QTY | AB26: Unit.Price | AC26: SALES | AD26: QTY | AE26: Unit.Price | AF26: SALES | AG26: QTY | AH26: SALES
A27: =IF(_xll.TM1RPTELISCONSOLIDATED($B$27,$B27),IF(_xll.TM1RPTELLEV($B$27,$B27)<=3,_xll.TM1RPTELLEV($B$27,$B27),"D"),"N") -> 0 | B27: =_xll.TM1RPTROW($B$9,"CXMD:DIM_Configuration","Par défaut","TOTAL PRODUCT","Description EN",0) -> TOTAL PRODUCT | C27: =_xll.DBRW($B$9,$C$17,$C$18,C$25,C$24,$C$20,$C$21,$B27,C$26) -> 0 | D27: =_xll.DBRW($B$9,$C$17,$C$18,C$25,C$24,$C$20,$C$21,$B27,D$26) -> 0 | E27: =_xll.DBRW($B$9,$C$17,$C$18,C$25,C$24,$C$20,$C$21,$B27,E$26) -> 0 | F27: =_xll.DBRW($B$9,$C$17,$C$18,F$25,F$24,$C$20,$C$21,$B27,F$26) -> 0 | G27: =_xll.DBRW($B$9,$C$17,$C$18,F$25,F$24,$C$20,$C$21,$B27,G$26) -> 0 | H27: =_xll.DBRW($B$9,$C$17,$C$18,F$25,F$24,$C$20,$C$21,$B27,H$26) -> 0 | I27: =IF(F27<>0,C27/F27,0) -> 0 | J27: =IF(H27<>0,E27/H27,0) -> 0 | K27: =_xll.DBRW($B$9,$C$17,$C$18,K$25,K$24,$C$20,$C$21,$B27,K$26) -> 0 | L27: =_xll.DBRW($B$9,$C$17,$C$18,K$25,K$24,$C$20,$C$21,$B27,L$26) -> 0 | M27: =_xll.DBRW($B$9,$C$17,$C$18,K$25,K$24,$C$20,$C$21,$B27,M$26) -> 0 | N27: =_xll.DBRW($B$9,$C$17,$C$18,N$25,N$24,$C$20,$C$21,$B27,N$26) -> 0 | O27: =_xll.DBRW($B$9,$C$17,$C$18,N$25,N$24,$C$20,$C$21,$B27,O$26) -> 0 | P27: =_xll.DBRW($B$9,$C$17,$C$18,N$25,N$24,$C$20,$C$21,$B27,P$26) -> 0 | Q27: =IF(N27<>0,K27/N27,0) -> 0 | R27: =IF(P27<>0,M27/P27,0) -> 0 | S27: =_xll.DBRW($B$9,$C$17,$C$18,S$25,S$24,$C$20,$C$21,$B27,S$26) -> 0 | T27: =_xll.DBRW($B$9,$C$17,$C$18,S$25,S$24,$C$20,$C$21,$B27,T$26) -> 0 | U27: =_xll.DBRW($B$9,$C$17,$C$18,S$25,S$24,$C$20,$C$21,$B27,U$26) -> 0 | V27: =_xll.DBRW($B$9,$C$17,$C$18,V$25,V$24,$C$20,$C$21,$B27,V$26) -> 0 | W27: =_xll.DBRW($B$9,$C$17,$C$18,V$25,V$24,$C$20,$C$21,$B27,W$26) -> 0 | X27: =_xll.DBRW($B$9,$C$17,$C$18,V$25,V$24,$C$20,$C$21,$B27,X$26) -> 0 | Y27: =IF(V27<>0,S27/V27,0) -> 0 | Z27: =IF(X27<>0,U27/X27,0) -> 0 | AA27: =_xll.DBRW($B$9,$C$17,$C$18,AA$25,AA$24,$C$20,$C$21,$B27,AA$26) -> 0 | AB27: =_xll.DBRW($B$9,$C$17,$C$18,AA$25,AA$24,$C$20,$C$21,$B27,AB$26) -> 0 | AC27: =_xll.DBRW($B$9,$C$17,$C$18,AA$25,AA$24,$C$20,$C$21,$B27,AC$26) -> 0 | AD27: =_xll.DBRW($B$9,$C$17,$C$18,AD$25,AD$24,$C$20,$C$21,$B27,AD$26) -> 0 | AE27: =_xll.DBRW($B$9,$C$17,$C$18,AD$25,AD$24,$C$20,$C$21,$B27,AE$26) -> 0 | AF27: =_xll.DBRW($B$9,$C$17,$C$18,AD$25,AD$24,$C$20,$C$21,$B27,AF$26) -> 0 | AG27: =IF(AD27<>0,AA27/AD27,0) -> 0 | AH27: =IF(AF27<>0,AC27/AF27,0) -> 0
A28: =IF(_xll.TM1RPTELISCONSOLIDATED($B$27,$B28),IF(_xll.TM1RPTELLEV($B$27,$B28)<=3,_xll.TM1RPTELLEV($B$27,$B28),"D"),"N") -> 1 | B28: L - LAB - Ploughing | C28: =_xll.DBRW($B$9,$C$17,$C$18,C$25,C$24,$C$20,$C$21,$B28,C$26) -> 0 | D28: =_xll.DBRW($B$9,$C$17,$C$18,C$25,C$24,$C$20,$C$21,$B28,D$26) -> 0 | E28: =_xll.DBRW($B$9,$C$17,$C$18,C$25,C$24,$C$20,$C$21,$B28,E$26) -> 0 | F28: =_xll.DBRW($B$9,$C$17,$C$18,F$25,F$24,$C$20,$C$21,$B28,F$26) -> 0 | G28: =_xll.DBRW($B$9,$C$17,$C$18,F$25,F$24,$C$20,$C$21,$B28,G$26) -> 0 | H28: =_xll.DBRW($B$9,$C$17,$C$18,F$25,F$24,$C$20,$C$21,$B28,H$26) -> 0 | I28: =IF(F28<>0,C28/F28,0) -> 0 | J28: =IF(H28<>0,E28/H28,0) -> 0 | K28: =_xll.DBRW($B$9,$C$17,$C$18,K$25,K$24,$C$20,$C$21,$B28,K$26) -> 0 | L28: =_xll.DBRW($B$9,$C$17,$C$18,K$25,K$24,$C$20,$C$21,$B28,L$26) -> 0 | M28: =_xll.DBRW($B$9,$C$17,$C$18,K$25,K$24,$C$20,$C$21,$B28,M$26) -> 0 | N28: =_xll.DBRW($B$9,$C$17,$C$18,N$25,N$24,$C$20,$C$21,$B28,N$26) -> 0 | O28: =_xll.DBRW($B$9,$C$17,$C$18,N$25,N$24,$C$20,$C$21,$B28,O$26) -> 0 | P28: =_xll.DBRW($B$9,$C$17,$C$18,N$25,N$24,$C$20,$C$21,$B28,P$26) -> 0 | Q28: =IF(N28<>0,K28/N28,0) -> 0 | R28: =IF(P28<>0,M28/P28,0) -> 0 | S28: =_xll.DBRW($B$9,$C$17,$C$18,S$25,S$24,$C$20,$C$21,$B28,S$26) -> 0 | T28: =_xll.DBRW($B$9,$C$17,$C$18,S$25,S$24,$C$20,$C$21,$B28,T$26) -> 0 | U28: =_xll.DBRW($B$9,$C$17,$C$18,S$25,S$24,$C$20,$C$21,$B28,U$26) -> 0 | V28: =_xll.DBRW($B$9,$C$17,$C$18,V$25,V$24,$C$20,$C$21,$B28,V$26) -> 0 | W28: =_xll.DBRW($B$9,$C$17,$C$18,V$25,V$24,$C$20,$C$21,$B28,W$26) -> 0 | X28: =_xll.DBRW($B$9,$C$17,$C$18,V$25,V$24,$C$20,$C$21,$B28,X$26) -> 0 | Y28: =IF(V28<>0,S28/V28,0) -> 0 | Z28: =IF(X28<>0,U28/X28,0) -> 0 | AA28: =_xll.DBRW($B$9,$C$17,$C$18,AA$25,AA$24,$C$20,$C$21,$B28,AA$26) -> 0 | AB28: =_xll.DBRW($B$9,$C$17,$C$18,AA$25,AA$24,$C$20,$C$21,$B28,AB$26) -> 0 | AC28: =_xll.DBRW($B$9,$C$17,$C$18,AA$25,AA$24,$C$20,$C$21,$B28,AC$26) -> 0 | AD28: =_xll.DBRW($B$9,$C$17,$C$18,AD$25,AD$24,$C$20,$C$21,$B28,AD$26) -> 0 | AE28: =_xll.DBRW($B$9,$C$17,$C$18,AD$25,AD$24,$C$20,$C$21,$B28,AE$26) -> 0 | AF28: =_xll.DBRW($B$9,$C$17,$C$18,AD$25,AD$24,$C$20,$C$21,$B28,AF$26) -> 0 | AG28: =IF(AD28<>0,AA28/AD28,0) -> 0 | AH28: =IF(AF28<>0,AC28/AF28,0) -> 0
A29: =IF(_xll.TM1RPTELISCONSOLIDATED($B$27,$B29),IF(_xll.TM1RPTELLEV($B$27,$B29)<=3,_xll.TM1RPTELLEV($B$27,$B29),"D"),"N") -> 1 | B29: L - SOL - Tillage | C29: =_xll.DBRW($B$9,$C$17,$C$18,C$25,C$24,$C$20,$C$21,$B29,C$26) -> 0 | D29: =_xll.DBRW($B$9,$C$17,$C$18,C$25,C$24,$C$20,$C$21,$B29,D$26) -> 0 | E29: =_xll.DBRW($B$9,$C$17,$C$18,C$25,C$24,$C$20,$C$21,$B29,E$26) -> 0 | F29: =_xll.DBRW($B$9,$C$17,$C$18,F$25,F$24,$C$20,$C$21,$B29,F$26) -> 0 | G29: =_xll.DBRW($B$9,$C$17,$C$18,F$25,F$24,$C$20,$C$21,$B29,G$26) -> 0 | H29: =_xll.DBRW($B$9,$C$17,$C$18,F$25,F$24,$C$20,$C$21,$B29,H$26) -> 0 | I29: =IF(F29<>0,C29/F29,0) -> 0 | J29: =IF(H29<>0,E29/H29,0) -> 0 | K29: =_xll.DBRW($B$9,$C$17,$C$18,K$25,K$24,$C$20,$C$21,$B29,K$26) -> 0 | L29: =_xll.DBRW($B$9,$C$17,$C$18,K$25,K$24,$C$20,$C$21,$B29,L$26) -> 0 | M29: =_xll.DBRW($B$9,$C$17,$C$18,K$25,K$24,$C$20,$C$21,$B29,M$26) -> 0 | N29: =_xll.DBRW($B$9,$C$17,$C$18,N$25,N$24,$C$20,$C$21,$B29,N$26) -> 0 | O29: =_xll.DBRW($B$9,$C$17,$C$18,N$25,N$24,$C$20,$C$21,$B29,O$26) -> 0 | P29: =_xll.DBRW($B$9,$C$17,$C$18,N$25,N$24,$C$20,$C$21,$B29,P$26) -> 0 | Q29: =IF(N29<>0,K29/N29,0) -> 0 | R29: =IF(P29<>0,M29/P29,0) -> 0 | S29: =_xll.DBRW($B$9,$C$17,$C$18,S$25,S$24,$C$20,$C$21,$B29,S$26) -> 0 | T29: =_xll.DBRW($B$9,$C$17,$C$18,S$25,S$24,$C$20,$C$21,$B29,T$26) -> 0 | U29: =_xll.DBRW($B$9,$C$17,$C$18,S$25,S$24,$C$20,$C$21,$B29,U$26) -> 0 | V29: =_xll.DBRW($B$9,$C$17,$C$18,V$25,V$24,$C$20,$C$21,$B29,V$26) -> 0 | W29: =_xll.DBRW($B$9,$C$17,$C$18,V$25,V$24,$C$20,$C$21,$B29,W$26) -> 0 | X29: =_xll.DBRW($B$9,$C$17,$C$18,V$25,V$24,$C$20,$C$21,$B29,X$26) -> 0 | Y29: =IF(V29<>0,S29/V29,0) -> 0 | Z29: =IF(X29<>0,U29/X29,0) -> 0 | AA29: =_xll.DBRW($B$9,$C$17,$C$18,AA$25,AA$24,$C$20,$C$21,$B29,AA$26) -> 0 | AB29: =_xll.DBRW($B$9,$C$17,$C$18,AA$25,AA$24,$C$20,$C$21,$B29,AB$26) -> 0 | AC29: =_xll.DBRW($B$9,$C$17,$C$18,AA$25,AA$24,$C$20,$C$21,$B29,AC$26) -> 0 | AD29: =_xll.DBRW($B$9,$C$17,$C$18,AD$25,AD$24,$C$20,$C$21,$B29,AD$26) -> 0 | AE29: =_xll.DBRW($B$9,$C$17,$C$18,AD$25,AD$24,$C$20,$C$21,$B29,AE$26) -> 0 | AF29: =_xll.DBRW($B$9,$C$17,$C$18,AD$25,AD$24,$C$20,$C$21,$B29,AF$26) -> 0 | AG29: =IF(AD29<>0,AA29/AD29,0) -> 0 | AH29: =IF(AF29<>0,AC29/AF29,0) -> 0
A30: =IF(_xll.TM1RPTELISCONSOLIDATED($B$27,$B30),IF(_xll.TM1RPTELLEV($B$27,$B30)<=3,_xll.TM1RPTELLEV($B$27,$B30),"D"),"N") -> 1 | B30: L - SEM - Seeding | C30: =_xll.DBRW($B$9,$C$17,$C$18,C$25,C$24,$C$20,$C$21,$B30,C$26) -> 0 | D30: =_xll.DBRW($B$9,$C$17,$C$18,C$25,C$24,$C$20,$C$21,$B30,D$26) -> 0 | E30: =_xll.DBRW($B$9,$C$17,$C$18,C$25,C$24,$C$20,$C$21,$B30,E$26) -> 0 | F30: =_xll.DBRW($B$9,$C$17,$C$18,F$25,F$24,$C$20,$C$21,$B30,F$26) -> 0 | G30: =_xll.DBRW($B$9,$C$17,$C$18,F$25,F$24,$C$20,$C$21,$B30,G$26) -> 0 | H30: =_xll.DBRW($B$9,$C$17,$C$18,F$25,F$24,$C$20,$C$21,$B30,H$26) -> 0 | I30: =IF(F30<>0,C30/F30,0) -> 0 | J30: =IF(H30<>0,E30/H30,0) -> 0 | K30: =_xll.DBRW($B$9,$C$17,$C$18,K$25,K$24,$C$20,$C$21,$B30,K$26) -> 0 | L30: =_xll.DBRW($B$9,$C$17,$C$18,K$25,K$24,$C$20,$C$21,$B30,L$26) -> 0 | M30: =_xll.DBRW($B$9,$C$17,$C$18,K$25,K$24,$C$20,$C$21,$B30,M$26) -> 0 | N30: =_xll.DBRW($B$9,$C$17,$C$18,N$25,N$24,$C$20,$C$21,$B30,N$26) -> 0 | O30: =_xll.DBRW($B$9,$C$17,$C$18,N$25,N$24,$C$20,$C$21,$B30,O$26) -> 0 | P30: =_xll.DBRW($B$9,$C$17,$C$18,N$25,N$24,$C$20,$C$21,$B30,P$26) -> 0 | Q30: =IF(N30<>0,K30/N30,0) -> 0 | R30: =IF(P30<>0,M30/P30,0) -> 0 | S30: =_xll.DBRW($B$9,$C$17,$C$18,S$25,S$24,$C$20,$C$21,$B30,S$26) -> 0 | T30: =_xll.DBRW($B$9,$C$17,$C$18,S$25,S$24,$C$20,$C$21,$B30,T$26) -> 0 | U30: =_xll.DBRW($B$9,$C$17,$C$18,S$25,S$24,$C$20,$C$21,$B30,U$26) -> 0 | V30: =_xll.DBRW($B$9,$C$17,$C$18,V$25,V$24,$C$20,$C$21,$B30,V$26) -> 0 | W30: =_xll.DBRW($B$9,$C$17,$C$18,V$25,V$24,$C$20,$C$21,$B30,W$26) -> 0 | X30: =_xll.DBRW($B$9,$C$17,$C$18,V$25,V$24,$C$20,$C$21,$B30,X$26) -> 0 | Y30: =IF(V30<>0,S30/V30,0) -> 0 | Z30: =IF(X30<>0,U30/X30,0) -> 0 | AA30: =_xll.DBRW($B$9,$C$17,$C$18,AA$25,AA$24,$C$20,$C$21,$B30,AA$26) -> 0 | AB30: =_xll.DBRW($B$9,$C$17,$C$18,AA$25,AA$24,$C$20,$C$21,$B30,AB$26) -> 0 | AC30: =_xll.DBRW($B$9,$C$17,$C$18,AA$25,AA$24,$C$20,$C$21,$B30,AC$26) -> 0 | AD30: =_xll.DBRW($B$9,$C$17,$C$18,AD$25,AD$24,$C$20,$C$21,$B30,AD$26) -> 0 | AE30: =_xll.DBRW($B$9,$C$17,$C$18,AD$25,AD$24,$C$20,$C$21,$B30,AE$26) -> 0 | AF30: =_xll.DBRW($B$9,$C$17,$C$18,AD$25,AD$24,$C$20,$C$21,$B30,AF$26) -> 0 | AG30: =IF(AD30<>0,AA30/AD30,0) -> 0 | AH30: =IF(AF30<>0,AC30/AF30,0) -> 0
A31: =IF(_xll.TM1RPTELISCONSOLIDATED($B$27,$B31),IF(_xll.TM1RPTELLEV($B$27,$B31)<=3,_xll.TM1RPTELLEV($B$27,$B31),"D"),"N") -> 1 | B31: L - FER - Fertilisation | C31: =_xll.DBRW($B$9,$C$17,$C$18,C$25,C$24,$C$20,$C$21,$B31,C$26) -> 0 | D31: =_xll.DBRW($B$9,$C$17,$C$18,C$25,C$24,$C$20,$C$21,$B31,D$26) -> 0 | E31: =_xll.DBRW($B$9,$C$17,$C$18,C$25,C$24,$C$20,$C$21,$B31,E$26) -> 0 | F31: =_xll.DBRW($B$9,$C$17,$C$18,F$25,F$24,$C$20,$C$21,$B31,F$26) -> 0 | G31: =_xll.DBRW($B$9,$C$17,$C$18,F$25,F$24,$C$20,$C$21,$B31,G$26) -> 0 | H31: =_xll.DBRW($B$9,$C$17,$C$18,F$25,F$24,$C$20,$C$21,$B31,H$26) -> 0 | I31: =IF(F31<>0,C31/F31,0) -> 0 | J31: =IF(H31<>0,E31/H31,0) -> 0 | K31: =_xll.DBRW($B$9,$C$17,$C$18,K$25,K$24,$C$20,$C$21,$B31,K$26) -> 0 | L31: =_xll.DBRW($B$9,$C$17,$C$18,K$25,K$24,$C$20,$C$21,$B31,L$26) -> 0 | M31: =_xll.DBRW($B$9,$C$17,$C$18,K$25,K$24,$C$20,$C$21,$B31,M$26) -> 0 | N31: =_xll.DBRW($B$9,$C$17,$C$18,N$25,N$24,$C$20,$C$21,$B31,N$26) -> 0 | O31: =_xll.DBRW($B$9,$C$17,$C$18,N$25,N$24,$C$20,$C$21,$B31,O$26) -> 0 | P31: =_xll.DBRW($B$9,$C$17,$C$18,N$25,N$24,$C$20,$C$21,$B31,P$26) -> 0 | Q31: =IF(N31<>0,K31/N31,0) -> 0 | R31: =IF(P31<>0,M31/P31,0) -> 0 | S31: =_xll.DBRW($B$9,$C$17,$C$18,S$25,S$24,$C$20,$C$21,$B31,S$26) -> 0 | T31: =_xll.DBRW($B$9,$C$17,$C$18,S$25,S$24,$C$20,$C$21,$B31,T$26) -> 0 | U31: =_xll.DBRW($B$9,$C$17,$C$18,S$25,S$24,$C$20,$C$21,$B31,U$26) -> 0 | V31: =_xll.DBRW($B$9,$C$17,$C$18,V$25,V$24,$C$20,$C$21,$B31,V$26) -> 0 | W31: =_xll.DBRW($B$9,$C$17,$C$18,V$25,V$24,$C$20,$C$21,$B31,W$26) -> 0 | X31: =_xll.DBRW($B$9,$C$17,$C$18,V$25,V$24,$C$20,$C$21,$B31,X$26) -> 0 | Y31: =IF(V31<>0,S31/V31,0) -> 0 | Z31: =IF(X31<>0,U31/X31,0) -> 0 | AA31: =_xll.DBRW($B$9,$C$17,$C$18,AA$25,AA$24,$C$20,$C$21,$B31,AA$26) -> 0 | AB31: =_xll.DBRW($B$9,$C$17,$C$18,AA$25,AA$24,$C$20,$C$21,$B31,AB$26) -> 0 | AC31: =_xll.DBRW($B$9,$C$17,$C$18,AA$25,AA$24,$C$20,$C$21,$B31,AC$26) -> 0 | AD31: =_xll.DBRW($B$9,$C$17,$C$18,AD$25,AD$24,$C$20,$C$21,$B31,AD$26) -> 0 | AE31: =_xll.DBRW($B$9,$C$17,$C$18,AD$25,AD$24,$C$20,$C$21,$B31,AE$26) -> 0 | AF31: =_xll.DBRW($B$9,$C$17,$C$18,AD$25,AD$24,$C$20,$C$21,$B31,AF$26) -> 0 | AG31: =IF(AD31<>0,AA31/AD31,0) -> 0 | AH31: =IF(AF31<>0,AC31/AF31,0) -> 0
A32: =IF(_xll.TM1RPTELISCONSOLIDATED($B$27,$B32),IF(_xll.TM1RPTELLEV($B$27,$B32)<=3,_xll.TM1RPTELLEV($B$27,$B32),"D"),"N") -> 1 | B32: L - PLV - Spraying | C32: =_xll.DBRW($B$9,$C$17,$C$18,C$25,C$24,$C$20,$C$21,$B32,C$26) -> 0 | D32: =_xll.DBRW($B$9,$C$17,$C$18,C$25,C$24,$C$20,$C$21,$B32,D$26) -> 0 | E32: =_xll.DBRW($B$9,$C$17,$C$18,C$25,C$24,$C$20,$C$21,$B32,E$26) -> 0 | F32: =_xll.DBRW($B$9,$C$17,$C$18,F$25,F$24,$C$20,$C$21,$B32,F$26) -> 0 | G32: =_xll.DBRW($B$9,$C$17,$C$18,F$25,F$24,$C$20,$C$21,$B32,G$26) -> 0 | H32: =_xll.DBRW($B$9,$C$17,$C$18,F$25,F$24,$C$20,$C$21,$B32,H$26) -> 0 | I32: =IF(F32<>0,C32/F32,0) -> 0 | J32: =IF(H32<>0,E32/H32,0) -> 0 | K32: =_xll.DBRW($B$9,$C$17,$C$18,K$25,K$24,$C$20,$C$21,$B32,K$26) -> 0 | L32: =_xll.DBRW($B$9,$C$17,$C$18,K$25,K$24,$C$20,$C$21,$B32,L$26) -> 0 | M32: =_xll.DBRW($B$9,$C$17,$C$18,K$25,K$24,$C$20,$C$21,$B32,M$26) -> 0 | N32: =_xll.DBRW($B$9,$C$17,$C$18,N$25,N$24,$C$20,$C$21,$B32,N$26) -> 0 | O32: =_xll.DBRW($B$9,$C$17,$C$18,N$25,N$24,$C$20,$C$21,$B32,O$26) -> 0 | P32: =_xll.DBRW($B$9,$C$17,$C$18,N$25,N$24,$C$20,$C$21,$B32,P$26) -> 0 | Q32: =IF(N32<>0,K32/N32,0) -> 0 | R32: =IF(P32<>0,M32/P32,0) -> 0 | S32: =_xll.DBRW($B$9,$C$17,$C$18,S$25,S$24,$C$20,$C$21,$B32,S$26) -> 0 | T32: =_xll.DBRW($B$9,$C$17,$C$18,S$25,S$24,$C$20,$C$21,$B32,T$26) -> 0 | U32: =_xll.DBRW($B$9,$C$17,$C$18,S$25,S$24,$C$20,$C$21,$B32,U$26) -> 0 | V32: =_xll.DBRW($B$9,$C$17,$C$18,V$25,V$24,$C$20,$C$21,$B32,V$26) -> 0 | W32: =_xll.DBRW($B$9,$C$17,$C$18,V$25,V$24,$C$20,$C$21,$B32,W$26) -> 0 | X32: =_xll.DBRW($B$9,$C$17,$C$18,V$25,V$24,$C$20,$C$21,$B32,X$26) -> 0 | Y32: =IF(V32<>0,S32/V32,0) -> 0 | Z32: =IF(X32<>0,U32/X32,0) -> 0 | AA32: =_xll.DBRW($B$9,$C$17,$C$18,AA$25,AA$24,$C$20,$C$21,$B32,AA$26) -> 0 | AB32: =_xll.DBRW($B$9,$C$17,$C$18,AA$25,AA$24,$C$20,$C$21,$B32,AB$26) -> 0 | AC32: =_xll.DBRW($B$9,$C$17,$C$18,AA$25,AA$24,$C$20,$C$21,$B32,AC$26) -> 0 | AD32: =_xll.DBRW($B$9,$C$17,$C$18,AD$25,AD$24,$C$20,$C$21,$B32,AD$26) -> 0 | AE32: =_xll.DBRW($B$9,$C$17,$C$18,AD$25,AD$24,$C$20,$C$21,$B32,AE$26) -> 0 | AF32: =_xll.DBRW($B$9,$C$17,$C$18,AD$25,AD$24,$C$20,$C$21,$B32,AF$26) -> 0 | AG32: =IF(AD32<>0,AA32/AD32,0) -> 0 | AH32: =IF(AF32<>0,AC32/AF32,0) -> 0
A33: =IF(_xll.TM1RPTELISCONSOLIDATED($B$27,$B33),IF(_xll.TM1RPTELLEV($B$27,$B33)<=3,_xll.TM1RPTELLEV($B$27,$B33),"D"),"N") -> 1 | B33: L - ENT - Landscape Maintenance | C33: =_xll.DBRW($B$9,$C$17,$C$18,C$25,C$24,$C$20,$C$21,$B33,C$26) -> 0 | D33: =_xll.DBRW($B$9,$C$17,$C$18,C$25,C$24,$C$20,$C$21,$B33,D$26) -> 0 | E33: =_xll.DBRW($B$9,$C$17,$C$18,C$25,C$24,$C$20,$C$21,$B33,E$26) -> 0 | F33: =_xll.DBRW($B$9,$C$17,$C$18,F$25,F$24,$C$20,$C$21,$B33,F$26) -> 0 | G33: =_xll.DBRW($B$9,$C$17,$C$18,F$25,F$24,$C$20,$C$21,$B33,G$26) -> 0 | H33: =_xll.DBRW($B$9,$C$17,$C$18,F$25,F$24,$C$20,$C$21,$B33,H$26) -> 0 | I33: =IF(F33<>0,C33/F33,0) -> 0 | J33: =IF(H33<>0,E33/H33,0) -> 0 | K33: =_xll.DBRW($B$9,$C$17,$C$18,K$25,K$24,$C$20,$C$21,$B33,K$26) -> 0 | L33: =_xll.DBRW($B$9,$C$17,$C$18,K$25,K$24,$C$20,$C$21,$B33,L$26) -> 0 | M33: =_xll.DBRW($B$9,$C$17,$C$18,K$25,K$24,$C$20,$C$21,$B33,M$26) -> 0 | N33: =_xll.DBRW($B$9,$C$17,$C$18,N$25,N$24,$C$20,$C$21,$B33,N$26) -> 0 | O33: =_xll.DBRW($B$9,$C$17,$C$18,N$25,N$24,$C$20,$C$21,$B33,O$26) -> 0 | P33: =_xll.DBRW($B$9,$C$17,$C$18,N$25,N$24,$C$20,$C$21,$B33,P$26) -> 0 | Q33: =IF(N33<>0,K33/N33,0) -> 0 | R33: =IF(P33<>0,M33/P33,0) -> 0 | S33: =_xll.DBRW($B$9,$C$17,$C$18,S$25,S$24,$C$20,$C$21,$B33,S$26) -> 0 | T33: =_xll.DBRW($B$9,$C$17,$C$18,S$25,S$24,$C$20,$C$21,$B33,T$26) -> 0 | U33: =_xll.DBRW($B$9,$C$17,$C$18,S$25,S$24,$C$20,$C$21,$B33,U$26) -> 0 | V33: =_xll.DBRW($B$9,$C$17,$C$18,V$25,V$24,$C$20,$C$21,$B33,V$26) -> 0 | W33: =_xll.DBRW($B$9,$C$17,$C$18,V$25,V$24,$C$20,$C$21,$B33,W$26) -> 0 | X33: =_xll.DBRW($B$9,$C$17,$C$18,V$25,V$24,$C$20,$C$21,$B33,X$26) -> 0 | Y33: =IF(V33<>0,S33/V33,0) -> 0 | Z33: =IF(X33<>0,U33/X33,0) -> 0 | AA33: =_xll.DBRW($B$9,$C$17,$C$18,AA$25,AA$24,$C$20,$C$21,$B33,AA$26) -> 0 | AB33: =_xll.DBRW($B$9,$C$17,$C$18,AA$25,AA$24,$C$20,$C$21,$B33,AB$26) -> 0 | AC33: =_xll.DBRW($B$9,$C$17,$C$18,AA$25,AA$24,$C$20,$C$21,$B33,AC$26) -> 0 | AD33: =_xll.DBRW($B$9,$C$17,$C$18,AD$25,AD$24,$C$20,$C$21,$B33,AD$26) -> 0 | AE33: =_xll.DBRW($B$9,$C$17,$C$18,AD$25,AD$24,$C$20,$C$21,$B33,AE$26) -> 0 | AF33: =_xll.DBRW($B$9,$C$17,$C$18,AD$25,AD$24,$C$20,$C$21,$B33,AF$26) -> 0 | AG33: =IF(AD33<>0,AA33/AD33,0) -> 0 | AH33: =IF(AF33<>0,AC33/AF33,0) -> 0
A34: =IF(_xll.TM1RPTELISCONSOLIDATED($B$27,$B34),IF(_xll.TM1RPTELLEV($B$27,$B34)<=3,_xll.TM1RPTELLEV($B$27,$B34),"D"),"N") -> 1 | B34: L - BRO - Shredders | C34: =_xll.DBRW($B$9,$C$17,$C$18,C$25,C$24,$C$20,$C$21,$B34,C$26) -> 0 | D34: =_xll.DBRW($B$9,$C$17,$C$18,C$25,C$24,$C$20,$C$21,$B34,D$26) -> 0 | E34: =_xll.DBRW($B$9,$C$17,$C$18,C$25,C$24,$C$20,$C$21,$B34,E$26) -> 0 | F34: =_xll.DBRW($B$9,$C$17,$C$18,F$25,F$24,$C$20,$C$21,$B34,F$26) -> 0 | G34: =_xll.DBRW($B$9,$C$17,$C$18,F$25,F$24,$C$20,$C$21,$B34,G$26) -> 0 | H34: =_xll.DBRW($B$9,$C$17,$C$18,F$25,F$24,$C$20,$C$21,$B34,H$26) -> 0 | I34: =IF(F34<>0,C34/F34,0) -> 0 | J34: =IF(H34<>0,E34/H34,0) -> 0 | K34: =_xll.DBRW($B$9,$C$17,$C$18,K$25,K$24,$C$20,$C$21,$B34,K$26) -> 0 | L34: =_xll.DBRW($B$9,$C$17,$C$18,K$25,K$24,$C$20,$C$21,$B34,L$26) -> 0 | M34: =_xll.DBRW($B$9,$C$17,$C$18,K$25,K$24,$C$20,$C$21,$B34,M$26) -> 0 | N34: =_xll.DBRW($B$9,$C$17,$C$18,N$25,N$24,$C$20,$C$21,$B34,N$26) -> 0 | O34: =_xll.DBRW($B$9,$C$17,$C$18,N$25,N$24,$C$20,$C$21,$B34,O$26) -> 0 | P34: =_xll.DBRW($B$9,$C$17,$C$18,N$25,N$24,$C$20,$C$21,$B34,P$26) -> 0 | Q34: =IF(N34<>0,K34/N34,0) -> 0 | R34: =IF(P34<>0,M34/P34,0) -> 0 | S34: =_xll.DBRW($B$9,$C$17,$C$18,S$25,S$24,$C$20,$C$21,$B34,S$26) -> 0 | T34: =_xll.DBRW($B$9,$C$17,$C$18,S$25,S$24,$C$20,$C$21,$B34,T$26) -> 0 | U34: =_xll.DBRW($B$9,$C$17,$C$18,S$25,S$24,$C$20,$C$21,$B34,U$26) -> 0 | V34: =_xll.DBRW($B$9,$C$17,$C$18,V$25,V$24,$C$20,$C$21,$B34,V$26) -> 0 | W34: =_xll.DBRW($B$9,$C$17,$C$18,V$25,V$24,$C$20,$C$21,$B34,W$26) -> 0 | X34: =_xll.DBRW($B$9,$C$17,$C$18,V$25,V$24,$C$20,$C$21,$B34,X$26) -> 0 | Y34: =IF(V34<>0,S34/V34,0) -> 0 | Z34: =IF(X34<>0,U34/X34,0) -> 0 | AA34: =_xll.DBRW($B$9,$C$17,$C$18,AA$25,AA$24,$C$20,$C$21,$B34,AA$26) -> 0 | AB34: =_xll.DBRW($B$9,$C$17,$C$18,AA$25,AA$24,$C$20,$C$21,$B34,AB$26) -> 0 | AC34: =_xll.DBRW($B$9,$C$17,$C$18,AA$25,AA$24,$C$20,$C$21,$B34,AC$26) -> 0 | AD34: =_xll.DBRW($B$9,$C$17,$C$18,AD$25,AD$24,$C$20,$C$21,$B34,AD$26) -> 0 | AE34: =_xll.DBRW($B$9,$C$17,$C$18,AD$25,AD$24,$C$20,$C$21,$B34,AE$26) -> 0 | AF34: =_xll.DBRW($B$9,$C$17,$C$18,AD$25,AD$24,$C$20,$C$21,$B34,AF$26) -> 0 | AG34: =IF(AD34<>0,AA34/AD34,0) -> 0 | AH34: =IF(AF34<>0,AC34/AF34,0) -> 0
A35: =IF(_xll.TM1RPTELISCONSOLIDATED($B$27,$B35),IF(_xll.TM1RPTELLEV($B$27,$B35)<=3,_xll.TM1RPTELLEV($B$27,$B35),"D"),"N") -> 1 | B35: L - RFO - Hay / Silage Making | C35: =_xll.DBRW($B$9,$C$17,$C$18,C$25,C$24,$C$20,$C$21,$B35,C$26) -> 0 | D35: =_xll.DBRW($B$9,$C$17,$C$18,C$25,C$24,$C$20,$C$21,$B35,D$26) -> 0 | E35: =_xll.DBRW($B$9,$C$17,$C$18,C$25,C$24,$C$20,$C$21,$B35,E$26) -> 0 | F35: =_xll.DBRW($B$9,$C$17,$C$18,F$25,F$24,$C$20,$C$21,$B35,F$26) -> 0 | G35: =_xll.DBRW($B$9,$C$17,$C$18,F$25,F$24,$C$20,$C$21,$B35,G$26) -> 0 | H35: =_xll.DBRW($B$9,$C$17,$C$18,F$25,F$24,$C$20,$C$21,$B35,H$26) -> 0 | I35: =IF(F35<>0,C35/F35,0) -> 0 | J35: =IF(H35<>0,E35/H35,0) -> 0 | K35: =_xll.DBRW($B$9,$C$17,$C$18,K$25,K$24,$C$20,$C$21,$B35,K$26) -> 0 | L35: =_xll.DBRW($B$9,$C$17,$C$18,K$25,K$24,$C$20,$C$21,$B35,L$26) -> 0 | M35: =_xll.DBRW($B$9,$C$17,$C$18,K$25,K$24,$C$20,$C$21,$B35,M$26) -> 0 | N35: =_xll.DBRW($B$9,$C$17,$C$18,N$25,N$24,$C$20,$C$21,$B35,N$26) -> 0 | O35: =_xll.DBRW($B$9,$C$17,$C$18,N$25,N$24,$C$20,$C$21,$B35,O$26) -> 0 | P35: =_xll.DBRW($B$9,$C$17,$C$18,N$25,N$24,$C$20,$C$21,$B35,P$26) -> 0 | Q35: =IF(N35<>0,K35/N35,0) -> 0 | R35: =IF(P35<>0,M35/P35,0) -> 0 | S35: =_xll.DBRW($B$9,$C$17,$C$18,S$25,S$24,$C$20,$C$21,$B35,S$26) -> 0 | T35: =_xll.DBRW($B$9,$C$17,$C$18,S$25,S$24,$C$20,$C$21,$B35,T$26) -> 0 | U35: =_xll.DBRW($B$9,$C$17,$C$18,S$25,S$24,$C$20,$C$21,$B35,U$26) -> 0 | V35: =_xll.DBRW($B$9,$C$17,$C$18,V$25,V$24,$C$20,$C$21,$B35,V$26) -> 0 | W35: =_xll.DBRW($B$9,$C$17,$C$18,V$25,V$24,$C$20,$C$21,$B35,W$26) -> 0 | X35: =_xll.DBRW($B$9,$C$17,$C$18,V$25,V$24,$C$20,$C$21,$B35,X$26) -> 0 | Y35: =IF(V35<>0,S35/V35,0) -> 0 | Z35: =IF(X35<>0,U35/X35,0) -> 0 | AA35: =_xll.DBRW($B$9,$C$17,$C$18,AA$25,AA$24,$C$20,$C$21,$B35,AA$26) -> 0 | AB35: =_xll.DBRW($B$9,$C$17,$C$18,AA$25,AA$24,$C$20,$C$21,$B35,AB$26) -> 0 | AC35: =_xll.DBRW($B$9,$C$17,$C$18,AA$25,AA$24,$C$20,$C$21,$B35,AC$26) -> 0 | AD35: =_xll.DBRW($B$9,$C$17,$C$18,AD$25,AD$24,$C$20,$C$21,$B35,AD$26) -> 0 | AE35: =_xll.DBRW($B$9,$C$17,$C$18,AD$25,AD$24,$C$20,$C$21,$B35,AE$26) -> 0 | AF35: =_xll.DBRW($B$9,$C$17,$C$18,AD$25,AD$24,$C$20,$C$21,$B35,AF$26) -> 0 | AG35: =IF(AD35<>0,AA35/AD35,0) -> 0 | AH35: =IF(AF35<>0,AC35/AF35,0) -> 0
A36: =IF(_xll.TM1RPTELISCONSOLIDATED($B$27,$B36),IF(_xll.TM1RPTELLEV($B$27,$B36)<=3,_xll.TM1RPTELLEV($B$27,$B36),"D"),"N") -> 1 | B36: L - PRE - Balers | C36: =_xll.DBRW($B$9,$C$17,$C$18,C$25,C$24,$C$20,$C$21,$B36,C$26) -> 0 | D36: =_xll.DBRW($B$9,$C$17,$C$18,C$25,C$24,$C$20,$C$21,$B36,D$26) -> 0 | E36: =_xll.DBRW($B$9,$C$17,$C$18,C$25,C$24,$C$20,$C$21,$B36,E$26) -> 0 | F36: =_xll.DBRW($B$9,$C$17,$C$18,F$25,F$24,$C$20,$C$21,$B36,F$26) -> 0 | G36: =_xll.DBRW($B$9,$C$17,$C$18,F$25,F$24,$C$20,$C$21,$B36,G$26) -> 0 | H36: =_xll.DBRW($B$9,$C$17,$C$18,F$25,F$24,$C$20,$C$21,$B36,H$26) -> 0 | I36: =IF(F36<>0,C36/F36,0) -> 0 | J36: =IF(H36<>0,E36/H36,0) -> 0 | K36: =_xll.DBRW($B$9,$C$17,$C$18,K$25,K$24,$C$20,$C$21,$B36,K$26) -> 0 | L36: =_xll.DBRW($B$9,$C$17,$C$18,K$25,K$24,$C$20,$C$21,$B36,L$26) -> 0 | M36: =_xll.DBRW($B$9,$C$17,$C$18,K$25,K$24,$C$20,$C$21,$B36,M$26) -> 0 | N36: =_xll.DBRW($B$9,$C$17,$C$18,N$25,N$24,$C$20,$C$21,$B36,N$26) -> 0 | O36: =_xll.DBRW($B$9,$C$17,$C$18,N$25,N$24,$C$20,$C$21,$B36,O$26) -> 0 | P36: =_xll.DBRW($B$9,$C$17,$C$18,N$25,N$24,$C$20,$C$21,$B36,P$26) -> 0 | Q36: =IF(N36<>0,K36/N36,0) -> 0 | R36: =IF(P36<>0,M36/P36,0) -> 0 | S36: =_xll.DBRW($B$9,$C$17,$C$18,S$25,S$24,$C$20,$C$21,$B36,S$26) -> 0 | T36: =_xll.DBRW($B$9,$C$17,$C$18,S$25,S$24,$C$20,$C$21,$B36,T$26) -> 0 | U36: =_xll.DBRW($B$9,$C$17,$C$18,S$25,S$24,$C$20,$C$21,$B36,U$26) -> 0 | V36: =_xll.DBRW($B$9,$C$17,$C$18,V$25,V$24,$C$20,$C$21,$B36,V$26) -> 0 | W36: =_xll.DBRW($B$9,$C$17,$C$18,V$25,V$24,$C$20,$C$21,$B36,W$26) -> 0 | X36: =_xll.DBRW($B$9,$C$17,$C$18,V$25,V$24,$C$20,$C$21,$B36,X$26) -> 0 | Y36: =IF(V36<>0,S36/V36,0) -> 0 | Z36: =IF(X36<>0,U36/X36,0) -> 0 | AA36: =_xll.DBRW($B$9,$C$17,$C$18,AA$25,AA$24,$C$20,$C$21,$B36,AA$26) -> 0 | AB36: =_xll.DBRW($B$9,$C$17,$C$18,AA$25,AA$24,$C$20,$C$21,$B36,AB$26) -> 0 | AC36: =_xll.DBRW($B$9,$C$17,$C$18,AA$25,AA$24,$C$20,$C$21,$B36,AC$26) -> 0 | AD36: =_xll.DBRW($B$9,$C$17,$C$18,AD$25,AD$24,$C$20,$C$21,$B36,AD$26) -> 0 | AE36: =_xll.DBRW($B$9,$C$17,$C$18,AD$25,AD$24,$C$20,$C$21,$B36,AE$26) -> 0 | AF36: =_xll.DBRW($B$9,$C$17,$C$18,AD$25,AD$24,$C$20,$C$21,$B36,AF$26) -> 0 | AG36: =IF(AD36<>0,AA36/AD36,0) -> 0 | AH36: =IF(AF36<>0,AC36/AF36,0) -> 0
A37: =IF(_xll.TM1RPTELISCONSOLIDATED($B$27,$B37),IF(_xll.TM1RPTELLEV($B$27,$B37)<=3,_xll.TM1RPTELLEV($B$27,$B37),"D"),"N") -> 1 | B37: L - ENR - Wrappers | C37: =_xll.DBRW($B$9,$C$17,$C$18,C$25,C$24,$C$20,$C$21,$B37,C$26) -> 0 | D37: =_xll.DBRW($B$9,$C$17,$C$18,C$25,C$24,$C$20,$C$21,$B37,D$26) -> 0 | E37: =_xll.DBRW($B$9,$C$17,$C$18,C$25,C$24,$C$20,$C$21,$B37,E$26) -> 0 | F37: =_xll.DBRW($B$9,$C$17,$C$18,F$25,F$24,$C$20,$C$21,$B37,F$26) -> 0 | G37: =_xll.DBRW($B$9,$C$17,$C$18,F$25,F$24,$C$20,$C$21,$B37,G$26) -> 0 | H37: =_xll.DBRW($B$9,$C$17,$C$18,F$25,F$24,$C$20,$C$21,$B37,H$26) -> 0 | I37: =IF(F37<>0,C37/F37,0) -> 0 | J37: =IF(H37<>0,E37/H37,0) -> 0 | K37: =_xll.DBRW($B$9,$C$17,$C$18,K$25,K$24,$C$20,$C$21,$B37,K$26) -> 0 | L37: =_xll.DBRW($B$9,$C$17,$C$18,K$25,K$24,$C$20,$C$21,$B37,L$26) -> 0 | M37: =_xll.DBRW($B$9,$C$17,$C$18,K$25,K$24,$C$20,$C$21,$B37,M$26) -> 0 | N37: =_xll.DBRW($B$9,$C$17,$C$18,N$25,N$24,$C$20,$C$21,$B37,N$26) -> 0 | O37: =_xll.DBRW($B$9,$C$17,$C$18,N$25,N$24,$C$20,$C$21,$B37,O$26) -> 0 | P37: =_xll.DBRW($B$9,$C$17,$C$18,N$25,N$24,$C$20,$C$21,$B37,P$26) -> 0 | Q37: =IF(N37<>0,K37/N37,0) -> 0 | R37: =IF(P37<>0,M37/P37,0) -> 0 | S37: =_xll.DBRW($B$9,$C$17,$C$18,S$25,S$24,$C$20,$C$21,$B37,S$26) -> 0 | T37: =_xll.DBRW($B$9,$C$17,$C$18,S$25,S$24,$C$20,$C$21,$B37,T$26) -> 0 | U37: =_xll.DBRW($B$9,$C$17,$C$18,S$25,S$24,$C$20,$C$21,$B37,U$26) -> 0 | V37: =_xll.DBRW($B$9,$C$17,$C$18,V$25,V$24,$C$20,$C$21,$B37,V$26) -> 0 | W37: =_xll.DBRW($B$9,$C$17,$C$18,V$25,V$24,$C$20,$C$21,$B37,W$26) -> 0 | X37: =_xll.DBRW($B$9,$C$17,$C$18,V$25,V$24,$C$20,$C$21,$B37,X$26) -> 0 | Y37: =IF(V37<>0,S37/V37,0) -> 0 | Z37: =IF(X37<>0,U37/X37,0) -> 0 | AA37: =_xll.DBRW($B$9,$C$17,$C$18,AA$25,AA$24,$C$20,$C$21,$B37,AA$26) -> 0 | AB37: =_xll.DBRW($B$9,$C$17,$C$18,AA$25,AA$24,$C$20,$C$21,$B37,AB$26) -> 0 | AC37: =_xll.DBRW($B$9,$C$17,$C$18,AA$25,AA$24,$C$20,$C$21,$B37,AC$26) -> 0 | AD37: =_xll.DBRW($B$9,$C$17,$C$18,AD$25,AD$24,$C$20,$C$21,$B37,AD$26) -> 0 | AE37: =_xll.DBRW($B$9,$C$17,$C$18,AD$25,AD$24,$C$20,$C$21,$B37,AE$26) -> 0 | AF37: =_xll.DBRW($B$9,$C$17,$C$18,AD$25,AD$24,$C$20,$C$21,$B37,AF$26) -> 0 | AG37: =IF(AD37<>0,AA37/AD37,0) -> 0 | AH37: =IF(AF37<>0,AC37/AF37,0) -> 0
A38: =IF(_xll.TM1RPTELISCONSOLIDATED($B$27,$B38),IF(_xll.TM1RPTELLEV($B$27,$B38)<=3,_xll.TM1RPTELLEV($B$27,$B38),"D"),"N") -> 1 | B38: L - ENS - Choppers | C38: =_xll.DBRW($B$9,$C$17,$C$18,C$25,C$24,$C$20,$C$21,$B38,C$26) -> 0 | D38: =_xll.DBRW($B$9,$C$17,$C$18,C$25,C$24,$C$20,$C$21,$B38,D$26) -> 0 | E38: =_xll.DBRW($B$9,$C$17,$C$18,C$25,C$24,$C$20,$C$21,$B38,E$26) -> 0 | F38: =_xll.DBRW($B$9,$C$17,$C$18,F$25,F$24,$C$20,$C$21,$B38,F$26) -> 0 | G38: =_xll.DBRW($B$9,$C$17,$C$18,F$25,F$24,$C$20,$C$21,$B38,G$26) -> 0 | H38: =_xll.DBRW($B$9,$C$17,$C$18,F$25,F$24,$C$20,$C$21,$B38,H$26) -> 0 | I38: =IF(F38<>0,C38/F38,0) -> 0 | J38: =IF(H38<>0,E38/H38,0) -> 0 | K38: =_xll.DBRW($B$9,$C$17,$C$18,K$25,K$24,$C$20,$C$21,$B38,K$26) -> 0 | L38: =_xll.DBRW($B$9,$C$17,$C$18,K$25,K$24,$C$20,$C$21,$B38,L$26) -> 0 | M38: =_xll.DBRW($B$9,$C$17,$C$18,K$25,K$24,$C$20,$C$21,$B38,M$26) -> 0 | N38: =_xll.DBRW($B$9,$C$17,$C$18,N$25,N$24,$C$20,$C$21,$B38,N$26) -> 0 | O38: =_xll.DBRW($B$9,$C$17,$C$18,N$25,N$24,$C$20,$C$21,$B38,O$26) -> 0 | P38: =_xll.DBRW($B$9,$C$17,$C$18,N$25,N$24,$C$20,$C$21,$B38,P$26) -> 0 | Q38: =IF(N38<>0,K38/N38,0) -> 0 | R38: =IF(P38<>0,M38/P38,0) -> 0 | S38: =_xll.DBRW($B$9,$C$17,$C$18,S$25,S$24,$C$20,$C$21,$B38,S$26) -> 0 | T38: =_xll.DBRW($B$9,$C$17,$C$18,S$25,S$24,$C$20,$C$21,$B38,T$26) -> 0 | U38: =_xll.DBRW($B$9,$C$17,$C$18,S$25,S$24,$C$20,$C$21,$B38,U$26) -> 0 | V38: =_xll.DBRW($B$9,$C$17,$C$18,V$25,V$24,$C$20,$C$21,$B38,V$26) -> 0 | W38: =_xll.DBRW($B$9,$C$17,$C$18,V$25,V$24,$C$20,$C$21,$B38,W$26) -> 0 | X38: =_xll.DBRW($B$9,$C$17,$C$18,V$25,V$24,$C$20,$C$21,$B38,X$26) -> 0 | Y38: =IF(V38<>0,S38/V38,0) -> 0 | Z38: =IF(X38<>0,U38/X38,0) -> 0 | AA38: =_xll.DBRW($B$9,$C$17,$C$18,AA$25,AA$24,$C$20,$C$21,$B38,AA$26) -> 0 | AB38: =_xll.DBRW($B$9,$C$17,$C$18,AA$25,AA$24,$C$20,$C$21,$B38,AB$26) -> 0 | AC38: =_xll.DBRW($B$9,$C$17,$C$18,AA$25,AA$24,$C$20,$C$21,$B38,AC$26) -> 0 | AD38: =_xll.DBRW($B$9,$C$17,$C$18,AD$25,AD$24,$C$20,$C$21,$B38,AD$26) -> 0 | AE38: =_xll.DBRW($B$9,$C$17,$C$18,AD$25,AD$24,$C$20,$C$21,$B38,AE$26) -> 0 | AF38: =_xll.DBRW($B$9,$C$17,$C$18,AD$25,AD$24,$C$20,$C$21,$B38,AF$26) -> 0 | AG38: =IF(AD38<>0,AA38/AD38,0) -> 0 | AH38: =IF(AF38<>0,AC38/AF38,0) -> 0
A39: =IF(_xll.TM1RPTELISCONSOLIDATED($B$27,$B39),IF(_xll.TM1RPTELLEV($B$27,$B39)<=3,_xll.TM1RPTELLEV($B$27,$B39),"D"),"N") -> 1 | B39: L - LP_GRAIN_CARTS - GRAIN CARTS | C39: =_xll.DBRW($B$9,$C$17,$C$18,C$25,C$24,$C$20,$C$21,$B39,C$26) -> 0 | D39: =_xll.DBRW($B$9,$C$17,$C$18,C$25,C$24,$C$20,$C$21,$B39,D$26) -> 0 | E39: =_xll.DBRW($B$9,$C$17,$C$18,C$25,C$24,$C$20,$C$21,$B39,E$26) -> 0 | F39: =_xll.DBRW($B$9,$C$17,$C$18,F$25,F$24,$C$20,$C$21,$B39,F$26) -> 0 | G39: =_xll.DBRW($B$9,$C$17,$C$18,F$25,F$24,$C$20,$C$21,$B39,G$26) -> 0 | H39: =_xll.DBRW($B$9,$C$17,$C$18,F$25,F$24,$C$20,$C$21,$B39,H$26) -> 0 | I39: =IF(F39<>0,C39/F39,0) -> 0 | J39: =IF(H39<>0,E39/H39,0) -> 0 | K39: =_xll.DBRW($B$9,$C$17,$C$18,K$25,K$24,$C$20,$C$21,$B39,K$26) -> 0 | L39: =_xll.DBRW($B$9,$C$17,$C$18,K$25,K$24,$C$20,$C$21,$B39,L$26) -> 0 | M39: =_xll.DBRW($B$9,$C$17,$C$18,K$25,K$24,$C$20,$C$21,$B39,M$26) -> 0 | N39: =_xll.DBRW($B$9,$C$17,$C$18,N$25,N$24,$C$20,$C$21,$B39,N$26) -> 0 | O39: =_xll.DBRW($B$9,$C$17,$C$18,N$25,N$24,$C$20,$C$21,$B39,O$26) -> 0 | P39: =_xll.DBRW($B$9,$C$17,$C$18,N$25,N$24,$C$20,$C$21,$B39,P$26) -> 0 | Q39: =IF(N39<>0,K39/N39,0) -> 0 | R39: =IF(P39<>0,M39/P39,0) -> 0 | S39: =_xll.DBRW($B$9,$C$17,$C$18,S$25,S$24,$C$20,$C$21,$B39,S$26) -> 0 | T39: =_xll.DBRW($B$9,$C$17,$C$18,S$25,S$24,$C$20,$C$21,$B39,T$26) -> 0 | U39: =_xll.DBRW($B$9,$C$17,$C$18,S$25,S$24,$C$20,$C$21,$B39,U$26) -> 0 | V39: =_xll.DBRW($B$9,$C$17,$C$18,V$25,V$24,$C$20,$C$21,$B39,V$26) -> 0 | W39: =_xll.DBRW($B$9,$C$17,$C$18,V$25,V$24,$C$20,$C$21,$B39,W$26) -> 0 | X39: =_xll.DBRW($B$9,$C$17,$C$18,V$25,V$24,$C$20,$C$21,$B39,X$26) -> 0 | Y39: =IF(V39<>0,S39/V39,0) -> 0 | Z39: =IF(X39<>0,U39/X39,0) -> 0 | AA39: =_xll.DBRW($B$9,$C$17,$C$18,AA$25,AA$24,$C$20,$C$21,$B39,AA$26) -> 0 | AB39: =_xll.DBRW($B$9,$C$17,$C$18,AA$25,AA$24,$C$20,$C$21,$B39,AB$26) -> 0 | AC39: =_xll.DBRW($B$9,$C$17,$C$18,AA$25,AA$24,$C$20,$C$21,$B39,AC$26) -> 0 | AD39: =_xll.DBRW($B$9,$C$17,$C$18,AD$25,AD$24,$C$20,$C$21,$B39,AD$26) -> 0 | AE39: =_xll.DBRW($B$9,$C$17,$C$18,AD$25,AD$24,$C$20,$C$21,$B39,AE$26) -> 0 | AF39: =_xll.DBRW($B$9,$C$17,$C$18,AD$25,AD$24,$C$20,$C$21,$B39,AF$26) -> 0 | AG39: =IF(AD39<>0,AA39/AD39,0) -> 0 | AH39: =IF(AF39<>0,AC39/AF39,0) -> 0
... A49: =IF(_xll.TM1RPTELISCONSOLIDATED($B$27,$B49),IF(_xll.TM1RPTELLEV($B$27,$B49)<=3,_xll.TM1RPTELLEV($B$27,$B49),"D"),"N") -> 1 | B49: L - -2 - Not applicable | C49: =_xll.DBRW($B$9,$C$17,$C$18,C$25,C$24,$C$20,$C$21,$B49,C$26) -> 0 | D49: =_xll.DBRW($B$9,$C$17,$C$18,C$25,C$24,$C$20,$C$21,$B49,D$26) -> 0 | E49: =_xll.DBRW($B$9,$C$17,$C$18,C$25,C$24,$C$20,$C$21,$B49,E$26) -> 0 | F49: =_xll.DBRW($B$9,$C$17,$C$18,F$25,F$24,$C$20,$C$21,$B49,F$26) -> 0 | G49: =_xll.DBRW($B$9,$C$17,$C$18,F$25,F$24,$C$20,$C$21,$B49,G$26) -> 0 | H49: =_xll.DBRW($B$9,$C$17,$C$18,F$25,F$24,$C$20,$C$21,$B49,H$26) -> 0 | I49: =IF(F49<>0,C49/F49,0) -> 0 | J49: =IF(H49<>0,E49/H49,0) -> 0 | K49: =_xll.DBRW($B$9,$C$17,$C$18,K$25,K$24,$C$20,$C$21,$B49,K$26) -> 0 | L49: =_xll.DBRW($B$9,$C$17,$C$18,K$25,K$24,$C$20,$C$21,$B49,L$26) -> 0 | M49: =_xll.DBRW($B$9,$C$17,$C$18,K$25,K$24,$C$20,$C$21,$B49,M$26) -> 0 | N49: =_xll.DBRW($B$9,$C$17,$C$18,N$25,N$24,$C$20,$C$21,$B49,N$26) -> 0 | O49: =_xll.DBRW($B$9,$C$17,$C$18,N$25,N$24,$C$20,$C$21,$B49,O$26) -> 0 | P49: =_xll.DBRW($B$9,$C$17,$C$18,N$25,N$24,$C$20,$C$21,$B49,P$26) -> 0 | Q49: =IF(N49<>0,K49/N49,0) -> 0 | R49: =IF(P49<>0,M49/P49,0) -> 0 | S49: =_xll.DBRW($B$9,$C$17,$C$18,S$25,S$24,$C$20,$C$21,$B49,S$26) -> 0 | T49: =_xll.DBRW($B$9,$C$17,$C$18,S$25,S$24,$C$20,$C$21,$B49,T$26) -> 0 | U49: =_xll.DBRW($B$9,$C$17,$C$18,S$25,S$24,$C$20,$C$21,$B49,U$26) -> 0 | V49: =_xll.DBRW($B$9,$C$17,$C$18,V$25,V$24,$C$20,$C$21,$B49,V$26) -> 0 | W49: =_xll.DBRW($B$9,$C$17,$C$18,V$25,V$24,$C$20,$C$21,$B49,W$26) -> 0 | X49: =_xll.DBRW($B$9,$C$17,$C$18,V$25,V$24,$C$20,$C$21,$B49,X$26) -> 0 | Y49: =IF(V49<>0,S49/V49,0) -> 0 | Z49: =IF(X49<>0,U49/X49,0) -> 0 | AA49: =_xll.DBRW($B$9,$C$17,$C$18,AA$25,AA$24,$C$20,$C$21,$B49,AA$26) -> 0 | AB49: =_xll.DBRW($B$9,$C$17,$C$18,AA$25,AA$24,$C$20,$C$21,$B49,AB$26) -> 0 | AC49: =_xll.DBRW($B$9,$C$17,$C$18,AA$25,AA$24,$C$20,$C$21,$B49,AC$26) -> 0 | AD49: =_xll.DBRW($B$9,$C$17,$C$18,AD$25,AD$24,$C$20,$C$21,$B49,AD$26) -> 0 | AE49: =_xll.DBRW($B$9,$C$17,$C$18,AD$25,AD$24,$C$20,$C$21,$B49,AE$26) -> 0 | AF49: =_xll.DBRW($B$9,$C$17,$C$18,AD$25,AD$24,$C$20,$C$21,$B49,AF$26) -> 0 | AG49: =IF(AD49<>0,AA49/AD49,0) -> 0 | AH49: =IF(AF49<>0,AC49/AF49,0) -> 0

Sheet SOM detailed_Kuhn Scope
A1: [Begin Format Range]
A2: =0 -> 0
A3: =1 -> 1
A4: =2 -> 2
A5: =3 -> 3
A6: D
A7: N
A8: [End Format Range]
G15: =_xll.TM1RPTVIEW("CXMD:OTC_DATA_MARKET_ANALYSIS:ARPT1", 1, _xll.TM1RPTTITLE("CXMD:Currency",$H$21), _xll.TM1RPTTITLE("CXMD:DIM_Prev_IC_mapping",$H$22), _xll.TM1RPTTITLE("CXMD:DIM_Origin_Company",$H$24), _xll.TM1RPTTITLE("CXMD:DIM_Country",$H$25),TM1RPTFMTRNG,TM1RPTFMTIDCOL) -> CXMD:OTC_DATA_MARKET_ANALYSIS:ARPT1
G21: Currency | H21: =_xll.SUBNM("CXMD:Currency","Par défaut","CD_LC","Description EN") -> Local currency
G22: Prev_IC_mapping | H22: =_xll.SUBNM("CXMD:DIM_Prev_IC_mapping","","Others") -> Others
G23: Market Shares - 4 periods
G24: Origin_Company | H24: ='SOM Summary_Kuhn Scope'!C20 -> KUHN GERMANY
G25: Country | H25: ='SOM Summary_Kuhn Scope'!C21 -> GERMANY
H28: ='SOM Summary_Kuhn Scope'!C24 -> AC2020 | N28: Market Shares | P28: ='SOM Summary_Kuhn Scope'!K24 -> AC2021 | V28: Market Shares | X28: ='SOM Summary_Kuhn Scope'!S24 -> FC3_2022 | AD28: Market Shares | AF28: ='SOM Summary_Kuhn Scope'!AD24 -> BU2023draft | AL28: Market Shares
H29: KUHN Sales | K29: KUHN_Scope | P29: KUHN Sales | S29: KUHN_Scope | X29: KUHN Sales | AA29: KUHN_Scope | AF29: KUHN Sales | AI29: KUHN_Scope
H30: QTY | I30: Unit.Price | J30: SALES | K30: QTY | L30: Unit.Price | M30: SALES | N30: QTY | O30: SALES | P30: QTY | Q30: Unit.Price | R30: SALES | S30: QTY | T30: Unit.Price | U30: SALES | V30: QTY | W30: SALES | X30: QTY | Y30: Unit.Price | Z30: SALES | AA30: QTY | AB30: Unit.Price | AC30: SALES | AD30: QTY | AE30: SALES | AF30: QTY | AG30: Unit.Price | AH30: SALES | AI30: QTY | AJ30: Unit.Price | AK30: SALES | AL30: QTY | AM30: SALES
A31: =IF(_xll.TM1RPTELISCONSOLIDATED($G$31,$G31),IF(_xll.TM1RPTELLEV($G$31,$G31)<=3,_xll.TM1RPTELLEV($G$31,$G31),"D"),"N") -> N | G31: =_xll.TM1RPTROW($G$15,"CXMD:DIM_Configuration","Par défaut","TOTAL PRODUCT","Description EN",0) | H31: =_xll.DBRW($G$15,$H$21,$H$22,H$29,H$28,$H$24,$H$25,$G31,H$30) | I31: =_xll.DBRW($G$15,$H$21,$H$22,H$29,H$28,$H$24,$H$25,$G31,I$30) | J31: =_xll.DBRW($G$15,$H$21,$H$22,H$29,H$28,$H$24,$H$25,$G31,J$30) | K31: =_xll.DBRW($G$15,$H$21,$H$22,K$29,H$28,$H$24,$H$25,$G31,K$30) | L31: =_xll.DBRW($G$15,$H$21,$H$22,K$29,H$28,$H$24,$H$25,$G31,L$30) | M31: =_xll.DBRW($G$15,$H$21,$H$22,K$29,H$28,$H$24,$H$25,$G31,M$30) | N31: =IF(K31<>0,H31/K31,0) -> #VALUE! | O31: =IF(M31<>0,J31/M31,0) -> #VALUE! | P31: =_xll.DBRW($G$15,$H$21,$H$22,P$29,P$28,$H$24,$H$25,$G31,P$30) | Q31: =_xll.DBRW($G$15,$H$21,$H$22,P$29,P$28,$H$24,$H$25,$G31,Q$30) | R31: =_xll.DBRW($G$15,$H$21,$H$22,P$29,P$28,$H$24,$H$25,$G31,R$30) | S31: =_xll.DBRW($G$15,$H$21,$H$22,S$29,P$28,$H$24,$H$25,$G31,S$30) | T31: =_xll.DBRW($G$15,$H$21,$H$22,S$29,P$28,$H$24,$H$25,$G31,T$30) | U31: =_xll.DBRW($G$15,$H$21,$H$22,S$29,P$28,$H$24,$H$25,$G31,U$30) | V31: =IF(S31<>0,P31/S31,0) -> #VALUE! | W31: =IF(U31<>0,R31/U31,0) -> #VALUE! | X31: =_xll.DBRW($G$15,$H$21,$H$22,X$29,X$28,$H$24,$H$25,$G31,X$30) | Y31: =_xll.DBRW($G$15,$H$21,$H$22,X$29,X$28,$H$24,$H$25,$G31,Y$30) | Z31: =_xll.DBRW($G$15,$H$21,$H$22,X$29,X$28,$H$24,$H$25,$G31,Z$30) | AA31: =_xll.DBRW($G$15,$H$21,$H$22,AA$29,X$28,$H$24,$H$25,$G31,AA$30) | AB31: =_xll.DBRW($G$15,$H$21,$H$22,AA$29,X$28,$H$24,$H$25,$G31,AB$30) | AC31: =_xll.DBRW($G$15,$H$21,$H$22,AA$29,X$28,$H$24,$H$25,$G31,AC$30) | AD31: =IF(AA31<>0,X31/AA31,0) -> #VALUE! | AE31: =IF(AC31<>0,Z31/AC31,0) -> #VALUE! | AF31: =_xll.DBRW($G$15,$H$21,$H$22,AF$29,AF$28,$H$24,$H$25,$G31,AF$30) | AG31: =_xll.DBRW($G$15,$H$21,$H$22,AF$29,AF$28,$H$24,$H$25,$G31,AG$30) | AH31: =_xll.DBRW($G$15,$H$21,$H$22,AF$29,AF$28,$H$24,$H$25,$G31,AH$30) | AI31: =_xll.DBRW($G$15,$H$21,$H$22,AI$29,AF$28,$H$24,$H$25,$G31,AI$30) | AJ31: =_xll.DBRW($G$15,$H$21,$H$22,AI$29,AF$28,$H$24,$H$25,$G31,AJ$30) | AK31: =_xll.DBRW($G$15,$H$21,$H$22,AI$29,AF$28,$H$24,$H$25,$G31,AK$30) | AL31: =IF(AI31<>0,AF31/AI31,0) -> #VALUE! | AM31: =IF(AK31<>0,AH31/AK31,0) -> #VALUE!

Sheet SOM detailed_Global Market
A1: [Begin Format Range]
A2: =0 -> 0
A3: =1 -> 1
A4: =2 -> 2
A5: =3 -> 3
A6: D
A7: N
A8: [End Format Range]
B9: =_xll.TM1RPTVIEW("CXMD:OTC_DATA_MARKET_ANALYSIS:ARPT1", 0, _xll.TM1RPTTITLE("CXMD:Currency",$C$16), _xll.TM1RPTTITLE("CXMD:DIM_Prev_IC_mapping",$C$17), _xll.TM1RPTTITLE("CXMD:DIM_Origin_Company",$C$18), _xll.TM1RPTTITLE("CXMD:DIM_Country",$C$19),TM1RPTFMTRNG,TM1RPTFMTIDCOL) -> CXMD:OTC_DATA_MARKET_ANALYSIS:ARPT1
B15: Market Shares - 4 periods
B16: Currency | C16: =_xll.SUBNM("CXMD:Currency","Par défaut","CD_LC","Description EN") -> Local currency
B17: Prev_IC_mapping | C17: =_xll.SUBNM("CXMD:DIM_Prev_IC_mapping","Par défaut","Total_Customer_Supplier") -> Total_Customer_Supplier
B18: Origin_Company | C18: ='SOM Summary_Kuhn Scope'!C20 -> KUHN GERMANY
B19: Country | C19: ='SOM Summary_Kuhn Scope'!C21 -> GERMANY
C22: ='SOM Summary_Kuhn Scope'!C24 -> AC2020 | L22: ='SOM Summary_Kuhn Scope'!K24 -> AC2021 | U22: ='SOM Summary_Kuhn Scope'!S24 -> FC3_2022 | AD22: ='SOM Summary_Kuhn Scope'!AD24 -> BU2023draft
C23: Kuhn_scope | F23: Out_of_Scope | I23: Global_Market | L23: Kuhn_scope | O23: Out_of_Scope | R23: Global_Market | U23: Kuhn_scope | X23: Out_of_Scope | AA23: Global_Market | AD23: Kuhn_scope | AG23: Out_of_Scope | AJ23: Global_Market
C24: QTY | D24: Unit.Price | E24: SALES | F24: QTY | G24: Unit.Price | H24: SALES | I24: QTY | J24: Unit.Price | K24: SALES | L24: QTY | M24: Unit.Price | N24: SALES | O24: QTY | P24: Unit.Price | Q24: SALES | R24: QTY | S24: Unit.Price | T24: SALES | U24: QTY | V24: Unit.Price | W24: SALES | X24: QTY | Y24: Unit.Price | Z24: SALES | AA24: QTY | AB24: Unit.Price | AC24: SALES | AD24: QTY | AE24: Unit.Price | AF24: SALES | AG24: QTY | AH24: Unit.Price | AI24: SALES | AJ24: QTY | AK24: Unit.Price | AL24: SALES
A25: =IF(_xll.TM1RPTELISCONSOLIDATED($B$25,$B25),IF(_xll.TM1RPTELLEV($B$25,$B25)<=3,_xll.TM1RPTELLEV($B$25,$B25),"D"),"N") -> 0 | B25: =_xll.TM1RPTROW($B$9,"CXMD:DIM_Configuration","OTC_MARKET_ANALYSIS","","Description EN",0) -> TOTAL PRODUCT | C25: =_xll.DBRW($B$9,$C$16,$C$17,C$23,C$22,$C$18,$C$19,$B25,C$24) -> 0 | D25: =_xll.DBRW($B$9,$C$16,$C$17,C$23,C$22,$C$18,$C$19,$B25,D$24) -> 0 | E25: =_xll.DBRW($B$9,$C$16,$C$17,C$23,C$22,$C$18,$C$19,$B25,E$24) -> 0 | F25: =_xll.DBRW($B$9,$C$16,$C$17,F$23,C$22,$C$18,$C$19,$B25,F$24) -> 0 | G25: =_xll.DBRW($B$9,$C$16,$C$17,F$23,C$22,$C$18,$C$19,$B25,G$24) -> 0 | H25: =_xll.DBRW($B$9,$C$16,$C$17,F$23,C$22,$C$18,$C$19,$B25,H$24) -> 0 | I25: =C25+F25 -> 0 | J25: =IF(I25=0,0,K25/I25) -> 0 | K25: =E25+H25 -> 0 | L25: =_xll.DBRW($B$9,$C$16,$C$17,L$23,L$22,$C$18,$C$19,$B25,L$24) -> 0 | M25: =_xll.DBRW($B$9,$C$16,$C$17,L$23,L$22,$C$18,$C$19,$B25,M$24) -> 0 | N25: =_xll.DBRW($B$9,$C$16,$C$17,L$23,L$22,$C$18,$C$19,$B25,N$24) -> 0 | O25: =_xll.DBRW($B$9,$C$16,$C$17,O$23,L$22,$C$18,$C$19,$B25,O$24) -> 0 | P25: =_xll.DBRW($B$9,$C$16,$C$17,O$23,L$22,$C$18,$C$19,$B25,P$24) -> 0 | Q25: =_xll.DBRW($B$9,$C$16,$C$17,O$23,L$22,$C$18,$C$19,$B25,Q$24) -> 0 | R25: =L25+O25 -> 0 | S25: =IF(R25=0,0,T25/R25) -> 0 | T25: =N25+Q25 -> 0 | U25: =_xll.DBRW($B$9,$C$16,$C$17,U$23,U$22,$C$18,$C$19,$B25,U$24) -> 0 | V25: =_xll.DBRW($B$9,$C$16,$C$17,U$23,U$22,$C$18,$C$19,$B25,V$24) -> 0 | W25: =_xll.DBRW($B$9,$C$16,$C$17,U$23,U$22,$C$18,$C$19,$B25,W$24) -> 0 | X25: =_xll.DBRW($B$9,$C$16,$C$17,X$23,U$22,$C$18,$C$19,$B25,X$24) -> 0 | Y25: =_xll.DBRW($B$9,$C$16,$C$17,X$23,U$22,$C$18,$C$19,$B25,Y$24) -> 0 | Z25: =_xll.DBRW($B$9,$C$16,$C$17,X$23,U$22,$C$18,$C$19,$B25,Z$24) -> 0 | AA25: =U25+X25 -> 0 | AB25: =IF(AA25=0,0,AC25/AA25) -> 0 | AC25: =Z25+W25 -> 0 | AD25: =_xll.DBRW($B$9,$C$16,$C$17,AD$23,AD$22,$C$18,$C$19,$B25,AD$24) -> 0 | AE25: =_xll.DBRW($B$9,$C$16,$C$17,AD$23,AD$22,$C$18,$C$19,$B25,AE$24) -> 0 | AF25: =_xll.DBRW($B$9,$C$16,$C$17,AD$23,AD$22,$C$18,$C$19,$B25,AF$24) -> 0 | AG25: =_xll.DBRW($B$9,$C$16,$C$17,AG$23,AD$22,$C$18,$C$19,$B25,AG$24) -> 0 | AH25: =_xll.DBRW($B$9,$C$16,$C$17,AG$23,AD$22,$C$18,$C$19,$B25,AH$24) -> 0 | AI25: =_xll.DBRW($B$9,$C$16,$C$17,AG$23,AD$22,$C$18,$C$19,$B25,AI$24) -> 0 | AJ25: =AG25+AD25 -> 0 | AK25: =IF(AJ25=0,0,AL25/AJ25) -> 0 | AL25: =AI25+AF25 -> 0
A26: =IF(_xll.TM1RPTELISCONSOLIDATED($B$25,$B26),IF(_xll.TM1RPTELLEV($B$25,$B26)<=3,_xll.TM1RPTELLEV($B$25,$B26),"D"),"N") -> 1 | B26: L - LAB - Ploughing | C26: =_xll.DBRW($B$9,$C$16,$C$17,C$23,C$22,$C$18,$C$19,$B26,C$24) -> 0 | D26: =_xll.DBRW($B$9,$C$16,$C$17,C$23,C$22,$C$18,$C$19,$B26,D$24) -> 0 | E26: =_xll.DBRW($B$9,$C$16,$C$17,C$23,C$22,$C$18,$C$19,$B26,E$24) -> 0 | F26: =_xll.DBRW($B$9,$C$16,$C$17,F$23,C$22,$C$18,$C$19,$B26,F$24) -> 0 | G26: =_xll.DBRW($B$9,$C$16,$C$17,F$23,C$22,$C$18,$C$19,$B26,G$24) -> 0 | H26: =_xll.DBRW($B$9,$C$16,$C$17,F$23,C$22,$C$18,$C$19,$B26,H$24) -> 0 | I26: =C26+F26 -> 0 | J26: =IF(I26=0,0,K26/I26) -> 0 | K26: =E26+H26 -> 0 | L26: =_xll.DBRW($B$9,$C$16,$C$17,L$23,L$22,$C$18,$C$19,$B26,L$24) -> 0 | M26: =_xll.DBRW($B$9,$C$16,$C$17,L$23,L$22,$C$18,$C$19,$B26,M$24) -> 0 | N26: =_xll.DBRW($B$9,$C$16,$C$17,L$23,L$22,$C$18,$C$19,$B26,N$24) -> 0 | O26: =_xll.DBRW($B$9,$C$16,$C$17,O$23,L$22,$C$18,$C$19,$B26,O$24) -> 0 | P26: =_xll.DBRW($B$9,$C$16,$C$17,O$23,L$22,$C$18,$C$19,$B26,P$24) -> 0 | Q26: =_xll.DBRW($B$9,$C$16,$C$17,O$23,L$22,$C$18,$C$19,$B26,Q$24) -> 0 | R26: =L26+O26 -> 0 | S26: =IF(R26=0,0,T26/R26) -> 0 | T26: =N26+Q26 -> 0 | U26: =_xll.DBRW($B$9,$C$16,$C$17,U$23,U$22,$C$18,$C$19,$B26,U$24) -> 0 | V26: =_xll.DBRW($B$9,$C$16,$C$17,U$23,U$22,$C$18,$C$19,$B26,V$24) -> 0 | W26: =_xll.DBRW($B$9,$C$16,$C$17,U$23,U$22,$C$18,$C$19,$B26,W$24) -> 0 | X26: =_xll.DBRW($B$9,$C$16,$C$17,X$23,U$22,$C$18,$C$19,$B26,X$24) -> 0 | Y26: =_xll.DBRW($B$9,$C$16,$C$17,X$23,U$22,$C$18,$C$19,$B26,Y$24) -> 0 | Z26: =_xll.DBRW($B$9,$C$16,$C$17,X$23,U$22,$C$18,$C$19,$B26,Z$24) -> 0 | AA26: =U26+X26 -> 0 | AB26: =IF(AA26=0,0,AC26/AA26) -> 0 | AC26: =Z26+W26 -> 0 | AD26: =_xll.DBRW($B$9,$C$16,$C$17,AD$23,AD$22,$C$18,$C$19,$B26,AD$24) -> 0 | AE26: =_xll.DBRW($B$9,$C$16,$C$17,AD$23,AD$22,$C$18,$C$19,$B26,AE$24) -> 0 | AF26: =_xll.DBRW($B$9,$C$16,$C$17,AD$23,AD$22,$C$18,$C$19,$B26,AF$24) -> 0 | AG26: =_xll.DBRW($B$9,$C$16,$C$17,AG$23,AD$22,$C$18,$C$19,$B26,AG$24) -> 0 | AH26: =_xll.DBRW($B$9,$C$16,$C$17,AG$23,AD$22,$C$18,$C$19,$B26,AH$24) -> 0 | AI26: =_xll.DBRW($B$9,$C$16,$C$17,AG$23,AD$22,$C$18,$C$19,$B26,AI$24) -> 0 | AJ26: =AG26+AD26 -> 0 | AK26: =IF(AJ26=0,0,AL26/AJ26) -> 0 | AL26: =AI26+AF26 -> 0
A27: =IF(_xll.TM1RPTELISCONSOLIDATED($B$25,$B27),IF(_xll.TM1RPTELLEV($B$25,$B27)<=3,_xll.TM1RPTELLEV($B$25,$B27),"D"),"N") -> 2 | B27: F - CRP - Mounted reversible ploughs | C27: =_xll.DBRW($B$9,$C$16,$C$17,C$23,C$22,$C$18,$C$19,$B27,C$24) -> 0 | D27: =_xll.DBRW($B$9,$C$16,$C$17,C$23,C$22,$C$18,$C$19,$B27,D$24) -> 0 | E27: =_xll.DBRW($B$9,$C$16,$C$17,C$23,C$22,$C$18,$C$19,$B27,E$24) -> 0 | F27: =_xll.DBRW($B$9,$C$16,$C$17,F$23,C$22,$C$18,$C$19,$B27,F$24) -> 0 | G27: =_xll.DBRW($B$9,$C$16,$C$17,F$23,C$22,$C$18,$C$19,$B27,G$24) -> 0 | H27: =_xll.DBRW($B$9,$C$16,$C$17,F$23,C$22,$C$18,$C$19,$B27,H$24) -> 0 | I27: =C27+F27 -> 0 | J27: =IF(I27=0,0,K27/I27) -> 0 | K27: =E27+H27 -> 0 | L27: =_xll.DBRW($B$9,$C$16,$C$17,L$23,L$22,$C$18,$C$19,$B27,L$24) -> 0 | M27: =_xll.DBRW($B$9,$C$16,$C$17,L$23,L$22,$C$18,$C$19,$B27,M$24) -> 0 | N27: =_xll.DBRW($B$9,$C$16,$C$17,L$23,L$22,$C$18,$C$19,$B27,N$24) -> 0 | O27: =_xll.DBRW($B$9,$C$16,$C$17,O$23,L$22,$C$18,$C$19,$B27,O$24) -> 0 | P27: =_xll.DBRW($B$9,$C$16,$C$17,O$23,L$22,$C$18,$C$19,$B27,P$24) -> 0 | Q27: =_xll.DBRW($B$9,$C$16,$C$17,O$23,L$22,$C$18,$C$19,$B27,Q$24) -> 0 | R27: =L27+O27 -> 0 | S27: =IF(R27=0,0,T27/R27) -> 0 | T27: =N27+Q27 -> 0 | U27: =_xll.DBRW($B$9,$C$16,$C$17,U$23,U$22,$C$18,$C$19,$B27,U$24) -> 0 | V27: =_xll.DBRW($B$9,$C$16,$C$17,U$23,U$22,$C$18,$C$19,$B27,V$24) -> 0 | W27: =_xll.DBRW($B$9,$C$16,$C$17,U$23,U$22,$C$18,$C$19,$B27,W$24) -> 0 | X27: =_xll.DBRW($B$9,$C$16,$C$17,X$23,U$22,$C$18,$C$19,$B27,X$24) -> 0 | Y27: =_xll.DBRW($B$9,$C$16,$C$17,X$23,U$22,$C$18,$C$19,$B27,Y$24) -> 0 | Z27: =_xll.DBRW($B$9,$C$16,$C$17,X$23,U$22,$C$18,$C$19,$B27,Z$24) -> 0 | AA27: =U27+X27 -> 0 | AB27: =IF(AA27=0,0,AC27/AA27) -> 0 | AC27: =Z27+W27 -> 0 | AD27: =_xll.DBRW($B$9,$C$16,$C$17,AD$23,AD$22,$C$18,$C$19,$B27,AD$24) -> 0 | AE27: =_xll.DBRW($B$9,$C$16,$C$17,AD$23,AD$22,$C$18,$C$19,$B27,AE$24) -> 0 | AF27: =_xll.DBRW($B$9,$C$16,$C$17,AD$23,AD$22,$C$18,$C$19,$B27,AF$24) -> 0 | AG27: =_xll.DBRW($B$9,$C$16,$C$17,AG$23,AD$22,$C$18,$C$19,$B27,AG$24) -> 0 | AH27: =_xll.DBRW($B$9,$C$16,$C$17,AG$23,AD$22,$C$18,$C$19,$B27,AH$24) -> 0 | AI27: =_xll.DBRW($B$9,$C$16,$C$17,AG$23,AD$22,$C$18,$C$19,$B27,AI$24) -> 0 | AJ27: =AG27+AD27 -> 0 | AK27: =IF(AJ27=0,0,AL27/AJ27) -> 0 | AL27: =AI27+AF27 -> 0
A28: =IF(_xll.TM1RPTELISCONSOLIDATED($B$25,$B28),IF(_xll.TM1RPTELLEV($B$25,$B28)<=3,_xll.TM1RPTELLEV($B$25,$B28),"D"),"N") -> 2 | B28: F - RSP - Semi-mounted reversible ploughs | C28: =_xll.DBRW($B$9,$C$16,$C$17,C$23,C$22,$C$18,$C$19,$B28,C$24) -> 0 | D28: =_xll.DBRW($B$9,$C$16,$C$17,C$23,C$22,$C$18,$C$19,$B28,D$24) -> 0 | E28: =_xll.DBRW($B$9,$C$16,$C$17,C$23,C$22,$C$18,$C$19,$B28,E$24) -> 0 | F28: =_xll.DBRW($B$9,$C$16,$C$17,F$23,C$22,$C$18,$C$19,$B28,F$24) -> 0 | G28: =_xll.DBRW($B$9,$C$16,$C$17,F$23,C$22,$C$18,$C$19,$B28,G$24) -> 0 | H28: =_xll.DBRW($B$9,$C$16,$C$17,F$23,C$22,$C$18,$C$19,$B28,H$24) -> 0 | I28: =C28+F28 -> 0 | J28: =IF(I28=0,0,K28/I28) -> 0 | K28: =E28+H28 -> 0 | L28: =_xll.DBRW($B$9,$C$16,$C$17,L$23,L$22,$C$18,$C$19,$B28,L$24) -> 0 | M28: =_xll.DBRW($B$9,$C$16,$C$17,L$23,L$22,$C$18,$C$19,$B28,M$24) -> 0 | N28: =_xll.DBRW($B$9,$C$16,$C$17,L$23,L$22,$C$18,$C$19,$B28,N$24) -> 0 | O28: =_xll.DBRW($B$9,$C$16,$C$17,O$23,L$22,$C$18,$C$19,$B28,O$24) -> 0 | P28: =_xll.DBRW($B$9,$C$16,$C$17,O$23,L$22,$C$18,$C$19,$B28,P$24) -> 0 | Q28: =_xll.DBRW($B$9,$C$16,$C$17,O$23,L$22,$C$18,$C$19,$B28,Q$24) -> 0 | R28: =L28+O28 -> 0 | S28: =IF(R28=0,0,T28/R28) -> 0 | T28: =N28+Q28 -> 0 | U28: =_xll.DBRW($B$9,$C$16,$C$17,U$23,U$22,$C$18,$C$19,$B28,U$24) -> 0 | V28: =_xll.DBRW($B$9,$C$16,$C$17,U$23,U$22,$C$18,$C$19,$B28,V$24) -> 0 | W28: =_xll.DBRW($B$9,$C$16,$C$17,U$23,U$22,$C$18,$C$19,$B28,W$24) -> 0 | X28: =_xll.DBRW($B$9,$C$16,$C$17,X$23,U$22,$C$18,$C$19,$B28,X$24) -> 0 | Y28: =_xll.DBRW($B$9,$C$16,$C$17,X$23,U$22,$C$18,$C$19,$B28,Y$24) -> 0 | Z28: =_xll.DBRW($B$9,$C$16,$C$17,X$23,U$22,$C$18,$C$19,$B28,Z$24) -> 0 | AA28: =U28+X28 -> 0 | AB28: =IF(AA28=0,0,AC28/AA28) -> 0 | AC28: =Z28+W28 -> 0 | AD28: =_xll.DBRW($B$9,$C$16,$C$17,AD$23,AD$22,$C$18,$C$19,$B28,AD$24) -> 0 | AE28: =_xll.DBRW($B$9,$C$16,$C$17,AD$23,AD$22,$C$18,$C$19,$B28,AE$24) -> 0 | AF28: =_xll.DBRW($B$9,$C$16,$C$17,AD$23,AD$22,$C$18,$C$19,$B28,AF$24) -> 0 | AG28: =_xll.DBRW($B$9,$C$16,$C$17,AG$23,AD$22,$C$18,$C$19,$B28,AG$24) -> 0 | AH28: =_xll.DBRW($B$9,$C$16,$C$17,AG$23,AD$22,$C$18,$C$19,$B28,AH$24) -> 0 | AI28: =_xll.DBRW($B$9,$C$16,$C$17,AG$23,AD$22,$C$18,$C$19,$B28,AI$24) -> 0 | AJ28: =AG28+AD28 -> 0 | AK28: =IF(AJ28=0,0,AL28/AJ28) -> 0 | AL28: =AI28+AF28 -> 0
A29: =IF(_xll.TM1RPTELISCONSOLIDATED($B$25,$B29),IF(_xll.TM1RPTELLEV($B$25,$B29)<=3,_xll.TM1RPTELLEV($B$25,$B29),"D"),"N") -> 2 | B29: F - SSP - Semi-mounted conventional ploughs | C29: =_xll.DBRW($B$9,$C$16,$C$17,C$23,C$22,$C$18,$C$19,$B29,C$24) -> 0 | D29: =_xll.DBRW($B$9,$C$16,$C$17,C$23,C$22,$C$18,$C$19,$B29,D$24) -> 0 | E29: =_xll.DBRW($B$9,$C$16,$C$17,C$23,C$22,$C$18,$C$19,$B29,E$24) -> 0 | F29: =_xll.DBRW($B$9,$C$16,$C$17,F$23,C$22,$C$18,$C$19,$B29,F$24) -> 0 | G29: =_xll.DBRW($B$9,$C$16,$C$17,F$23,C$22,$C$18,$C$19,$B29,G$24) -> 0 | H29: =_xll.DBRW($B$9,$C$16,$C$17,F$23,C$22,$C$18,$C$19,$B29,H$24) -> 0 | I29: =C29+F29 -> 0 | J29: =IF(I29=0,0,K29/I29) -> 0 | K29: =E29+H29 -> 0 | L29: =_xll.DBRW($B$9,$C$16,$C$17,L$23,L$22,$C$18,$C$19,$B29,L$24) -> 0 | M29: =_xll.DBRW($B$9,$C$16,$C$17,L$23,L$22,$C$18,$C$19,$B29,M$24) -> 0 | N29: =_xll.DBRW($B$9,$C$16,$C$17,L$23,L$22,$C$18,$C$19,$B29,N$24) -> 0 | O29: =_xll.DBRW($B$9,$C$16,$C$17,O$23,L$22,$C$18,$C$19,$B29,O$24) -> 0 | P29: =_xll.DBRW($B$9,$C$16,$C$17,O$23,L$22,$C$18,$C$19,$B29,P$24) -> 0 | Q29: =_xll.DBRW($B$9,$C$16,$C$17,O$23,L$22,$C$18,$C$19,$B29,Q$24) -> 0 | R29: =L29+O29 -> 0 | S29: =IF(R29=0,0,T29/R29) -> 0 | T29: =N29+Q29 -> 0 | U29: =_xll.DBRW($B$9,$C$16,$C$17,U$23,U$22,$C$18,$C$19,$B29,U$24) -> 0 | V29: =_xll.DBRW($B$9,$C$16,$C$17,U$23,U$22,$C$18,$C$19,$B29,V$24) -> 0 | W29: =_xll.DBRW($B$9,$C$16,$C$17,U$23,U$22,$C$18,$C$19,$B29,W$24) -> 0 | X29: =_xll.DBRW($B$9,$C$16,$C$17,X$23,U$22,$C$18,$C$19,$B29,X$24) -> 0 | Y29: =_xll.DBRW($B$9,$C$16,$C$17,X$23,U$22,$C$18,$C$19,$B29,Y$24) -> 0 | Z29: =_xll.DBRW($B$9,$C$16,$C$17,X$23,U$22,$C$18,$C$19,$B29,Z$24) -> 0 | AA29: =U29+X29 -> 0 | AB29: =IF(AA29=0,0,AC29/AA29) -> 0 | AC29: =Z29+W29 -> 0 | AD29: =_xll.DBRW($B$9,$C$16,$C$17,AD$23,AD$22,$C$18,$C$19,$B29,AD$24) -> 0 | AE29: =_xll.DBRW($B$9,$C$16,$C$17,AD$23,AD$22,$C$18,$C$19,$B29,AE$24) -> 0 | AF29: =_xll.DBRW($B$9,$C$16,$C$17,AD$23,AD$22,$C$18,$C$19,$B29,AF$24) -> 0 | AG29: =_xll.DBRW($B$9,$C$16,$C$17,AG$23,AD$22,$C$18,$C$19,$B29,AG$24) -> 0 | AH29: =_xll.DBRW($B$9,$C$16,$C$17,AG$23,AD$22,$C$18,$C$19,$B29,AH$24) -> 0 | AI29: =_xll.DBRW($B$9,$C$16,$C$17,AG$23,AD$22,$C$18,$C$19,$B29,AI$24) -> 0 | AJ29: =AG29+AD29 -> 0 | AK29: =IF(AJ29=0,0,AL29/AJ29) -> 0 | AL29: =AI29+AF29 -> 0
A30: =IF(_xll.TM1RPTELISCONSOLIDATED($B$25,$B30),IF(_xll.TM1RPTELLEV($B$25,$B30)<=3,_xll.TM1RPTELLEV($B$25,$B30),"D"),"N") -> 2 | B30: F - CROT - Rotary ploughs | C30: =_xll.DBRW($B$9,$C$16,$C$17,C$23,C$22,$C$18,$C$19,$B30,C$24) -> 0 | D30: =_xll.DBRW($B$9,$C$16,$C$17,C$23,C$22,$C$18,$C$19,$B30,D$24) -> 0 | E30: =_xll.DBRW($B$9,$C$16,$C$17,C$23,C$22,$C$18,$C$19,$B30,E$24) -> 0 | F30: =_xll.DBRW($B$9,$C$16,$C$17,F$23,C$22,$C$18,$C$19,$B30,F$24) -> 0 | G30: =_xll.DBRW($B$9,$C$16,$C$17,F$23,C$22,$C$18,$C$19,$B30,G$24) -> 0 | H30: =_xll.DBRW($B$9,$C$16,$C$17,F$23,C$22,$C$18,$C$19,$B30,H$24) -> 0 | I30: =C30+F30 -> 0 | J30: =IF(I30=0,0,K30/I30) -> 0 | K30: =E30+H30 -> 0 | L30: =_xll.DBRW($B$9,$C$16,$C$17,L$23,L$22,$C$18,$C$19,$B30,L$24) -> 0 | M30: =_xll.DBRW($B$9,$C$16,$C$17,L$23,L$22,$C$18,$C$19,$B30,M$24) -> 0 | N30: =_xll.DBRW($B$9,$C$16,$C$17,L$23,L$22,$C$18,$C$19,$B30,N$24) -> 0 | O30: =_xll.DBRW($B$9,$C$16,$C$17,O$23,L$22,$C$18,$C$19,$B30,O$24) -> 0 | P30: =_xll.DBRW($B$9,$C$16,$C$17,O$23,L$22,$C$18,$C$19,$B30,P$24) -> 0 | Q30: =_xll.DBRW($B$9,$C$16,$C$17,O$23,L$22,$C$18,$C$19,$B30,Q$24) -> 0 | R30: =L30+O30 -> 0 | S30: =IF(R30=0,0,T30/R30) -> 0 | T30: =N30+Q30 -> 0 | U30: =_xll.DBRW($B$9,$C$16,$C$17,U$23,U$22,$C$18,$C$19,$B30,U$24) -> 0 | V30: =_xll.DBRW($B$9,$C$16,$C$17,U$23,U$22,$C$18,$C$19,$B30,V$24) -> 0 | W30: =_xll.DBRW($B$9,$C$16,$C$17,U$23,U$22,$C$18,$C$19,$B30,W$24) -> 0 | X30: =_xll.DBRW($B$9,$C$16,$C$17,X$23,U$22,$C$18,$C$19,$B30,X$24) -> 0 | Y30: =_xll.DBRW($B$9,$C$16,$C$17,X$23,U$22,$C$18,$C$19,$B30,Y$24) -> 0 | Z30: =_xll.DBRW($B$9,$C$16,$C$17,X$23,U$22,$C$18,$C$19,$B30,Z$24) -> 0 | AA30: =U30+X30 -> 0 | AB30: =IF(AA30=0,0,AC30/AA30) -> 0 | AC30: =Z30+W30 -> 0 | AD30: =_xll.DBRW($B$9,$C$16,$C$17,AD$23,AD$22,$C$18,$C$19,$B30,AD$24) -> 0 | AE30: =_xll.DBRW($B$9,$C$16,$C$17,AD$23,AD$22,$C$18,$C$19,$B30,AE$24) -> 0 | AF30: =_xll.DBRW($B$9,$C$16,$C$17,AD$23,AD$22,$C$18,$C$19,$B30,AF$24) -> 0 | AG30: =_xll.DBRW($B$9,$C$16,$C$17,AG$23,AD$22,$C$18,$C$19,$B30,AG$24) -> 0 | AH30: =_xll.DBRW($B$9,$C$16,$C$17,AG$23,AD$22,$C$18,$C$19,$B30,AH$24) -> 0 | AI30: =_xll.DBRW($B$9,$C$16,$C$17,AG$23,AD$22,$C$18,$C$19,$B30,AI$24) -> 0 | AJ30: =AG30+AD30 -> 0 | AK30: =IF(AJ30=0,0,AL30/AJ30) -> 0 | AL30: =AI30+AF30 -> 0
A31: =IF(_xll.TM1RPTELISCONSOLIDATED($B$25,$B31),IF(_xll.TM1RPTELLEV($B$25,$B31)<=3,_xll.TM1RPTELLEV($B$25,$B31),"D"),"N") -> 2 | B31: F - F-CORPS - Bodies and skim coulters | C31: =_xll.DBRW($B$9,$C$16,$C$17,C$23,C$22,$C$18,$C$19,$B31,C$24) -> 0 | D31: =_xll.DBRW($B$9,$C$16,$C$17,C$23,C$22,$C$18,$C$19,$B31,D$24) -> 0 | E31: =_xll.DBRW($B$9,$C$16,$C$17,C$23,C$22,$C$18,$C$19,$B31,E$24) -> 0 | F31: =_xll.DBRW($B$9,$C$16,$C$17,F$23,C$22,$C$18,$C$19,$B31,F$24) -> 0 | G31: =_xll.DBRW($B$9,$C$16,$C$17,F$23,C$22,$C$18,$C$19,$B31,G$24) -> 0 | H31: =_xll.DBRW($B$9,$C$16,$C$17,F$23,C$22,$C$18,$C$19,$B31,H$24) -> 0 | I31: =C31+F31 -> 0 | J31: =IF(I31=0,0,K31/I31) -> 0 | K31: =E31+H31 -> 0 | L31: =_xll.DBRW($B$9,$C$16,$C$17,L$23,L$22,$C$18,$C$19,$B31,L$24) -> 0 | M31: =_xll.DBRW($B$9,$C$16,$C$17,L$23,L$22,$C$18,$C$19,$B31,M$24) -> 0 | N31: =_xll.DBRW($B$9,$C$16,$C$17,L$23,L$22,$C$18,$C$19,$B31,N$24) -> 0 | O31: =_xll.DBRW($B$9,$C$16,$C$17,O$23,L$22,$C$18,$C$19,$B31,O$24) -> 0 | P31: =_xll.DBRW($B$9,$C$16,$C$17,O$23,L$22,$C$18,$C$19,$B31,P$24) -> 0 | Q31: =_xll.DBRW($B$9,$C$16,$C$17,O$23,L$22,$C$18,$C$19,$B31,Q$24) -> 0 | R31: =L31+O31 -> 0 | S31: =IF(R31=0,0,T31/R31) -> 0 | T31: =N31+Q31 -> 0 | U31: =_xll.DBRW($B$9,$C$16,$C$17,U$23,U$22,$C$18,$C$19,$B31,U$24) -> 0 | V31: =_xll.DBRW($B$9,$C$16,$C$17,U$23,U$22,$C$18,$C$19,$B31,V$24) -> 0 | W31: =_xll.DBRW($B$9,$C$16,$C$17,U$23,U$22,$C$18,$C$19,$B31,W$24) -> 0 | X31: =_xll.DBRW($B$9,$C$16,$C$17,X$23,U$22,$C$18,$C$19,$B31,X$24) -> 0 | Y31: =_xll.DBRW($B$9,$C$16,$C$17,X$23,U$22,$C$18,$C$19,$B31,Y$24) -> 0 | Z31: =_xll.DBRW($B$9,$C$16,$C$17,X$23,U$22,$C$18,$C$19,$B31,Z$24) -> 0 | AA31: =U31+X31 -> 0 | AB31: =IF(AA31=0,0,AC31/AA31) -> 0 | AC31: =Z31+W31 -> 0 | AD31: =_xll.DBRW($B$9,$C$16,$C$17,AD$23,AD$22,$C$18,$C$19,$B31,AD$24) -> 0 | AE31: =_xll.DBRW($B$9,$C$16,$C$17,AD$23,AD$22,$C$18,$C$19,$B31,AE$24) -> 0 | AF31: =_xll.DBRW($B$9,$C$16,$C$17,AD$23,AD$22,$C$18,$C$19,$B31,AF$24) -> 0 | AG31: =_xll.DBRW($B$9,$C$16,$C$17,AG$23,AD$22,$C$18,$C$19,$B31,AG$24) -> 0 | AH31: =_xll.DBRW($B$9,$C$16,$C$17,AG$23,AD$22,$C$18,$C$19,$B31,AH$24) -> 0 | AI31: =_xll.DBRW($B$9,$C$16,$C$17,AG$23,AD$22,$C$18,$C$19,$B31,AI$24) -> 0 | AJ31: =AG31+AD31 -> 0 | AK31: =IF(AJ31=0,0,AL31/AJ31) -> 0 | AL31: =AI31+AF31 -> 0
A32: =IF(_xll.TM1RPTELISCONSOLIDATED($B$25,$B32),IF(_xll.TM1RPTELLEV($B$25,$B32)<=3,_xll.TM1RPTELLEV($B$25,$B32),"D"),"N") -> 2 | B32: F - PC-LAB - Ploughing | C32: =_xll.DBRW($B$9,$C$16,$C$17,C$23,C$22,$C$18,$C$19,$B32,C$24) -> 0 | D32: =_xll.DBRW($B$9,$C$16,$C$17,C$23,C$22,$C$18,$C$19,$B32,D$24) -> 0 | E32: =_xll.DBRW($B$9,$C$16,$C$17,C$23,C$22,$C$18,$C$19,$B32,E$24) -> 0 | F32: =_xll.DBRW($B$9,$C$16,$C$17,F$23,C$22,$C$18,$C$19,$B32,F$24) -> 0 | G32: =_xll.DBRW($B$9,$C$16,$C$17,F$23,C$22,$C$18,$C$19,$B32,G$24) -> 0 | H32: =_xll.DBRW($B$9,$C$16,$C$17,F$23,C$22,$C$18,$C$19,$B32,H$24) -> 0 | I32: =C32+F32 -> 0 | J32: =IF(I32=0,0,K32/I32) -> 0 | K32: =E32+H32 -> 0 | L32: =_xll.DBRW($B$9,$C$16,$C$17,L$23,L$22,$C$18,$C$19,$B32,L$24) -> 0 | M32: =_xll.DBRW($B$9,$C$16,$C$17,L$23,L$22,$C$18,$C$19,$B32,M$24) -> 0 | N32: =_xll.DBRW($B$9,$C$16,$C$17,L$23,L$22,$C$18,$C$19,$B32,N$24) -> 0 | O32: =_xll.DBRW($B$9,$C$16,$C$17,O$23,L$22,$C$18,$C$19,$B32,O$24) -> 0 | P32: =_xll.DBRW($B$9,$C$16,$C$17,O$23,L$22,$C$18,$C$19,$B32,P$24) -> 0 | Q32: =_xll.DBRW($B$9,$C$16,$C$17,O$23,L$22,$C$18,$C$19,$B32,Q$24) -> 0 | R32: =L32+O32 -> 0 | S32: =IF(R32=0,0,T32/R32) -> 0 | T32: =N32+Q32 -> 0 | U32: =_xll.DBRW($B$9,$C$16,$C$17,U$23,U$22,$C$18,$C$19,$B32,U$24) -> 0 | V32: =_xll.DBRW($B$9,$C$16,$C$17,U$23,U$22,$C$18,$C$19,$B32,V$24) -> 0 | W32: =_xll.DBRW($B$9,$C$16,$C$17,U$23,U$22,$C$18,$C$19,$B32,W$24) -> 0 | X32: =_xll.DBRW($B$9,$C$16,$C$17,X$23,U$22,$C$18,$C$19,$B32,X$24) -> 0 | Y32: =_xll.DBRW($B$9,$C$16,$C$17,X$23,U$22,$C$18,$C$19,$B32,Y$24) -> 0 | Z32: =_xll.DBRW($B$9,$C$16,$C$17,X$23,U$22,$C$18,$C$19,$B32,Z$24) -> 0 | AA32: =U32+X32 -> 0 | AB32: =IF(AA32=0,0,AC32/AA32) -> 0 | AC32: =Z32+W32 -> 0 | AD32: =_xll.DBRW($B$9,$C$16,$C$17,AD$23,AD$22,$C$18,$C$19,$B32,AD$24) -> 0 | AE32: =_xll.DBRW($B$9,$C$16,$C$17,AD$23,AD$22,$C$18,$C$19,$B32,AE$24) -> 0 | AF32: =_xll.DBRW($B$9,$C$16,$C$17,AD$23,AD$22,$C$18,$C$19,$B32,AF$24) -> 0 | AG32: =_xll.DBRW($B$9,$C$16,$C$17,AG$23,AD$22,$C$18,$C$19,$B32,AG$24) -> 0 | AH32: =_xll.DBRW($B$9,$C$16,$C$17,AG$23,AD$22,$C$18,$C$19,$B32,AH$24) -> 0 | AI32: =_xll.DBRW($B$9,$C$16,$C$17,AG$23,AD$22,$C$18,$C$19,$B32,AI$24) -> 0 | AJ32: =AG32+AD32 -> 0 | AK32: =IF(AJ32=0,0,AL32/AJ32) -> 0 | AL32: =AI32+AF32 -> 0
A33: =IF(_xll.TM1RPTELISCONSOLIDATED($B$25,$B33),IF(_xll.TM1RPTELLEV($B$25,$B33)<=3,_xll.TM1RPTELLEV($B$25,$B33),"D"),"N") -> 1 | B33: L - SOL - Tillage | C33: =_xll.DBRW($B$9,$C$16,$C$17,C$23,C$22,$C$18,$C$19,$B33,C$24) -> 0 | D33: =_xll.DBRW($B$9,$C$16,$C$17,C$23,C$22,$C$18,$C$19,$B33,D$24) -> 0 | E33: =_xll.DBRW($B$9,$C$16,$C$17,C$23,C$22,$C$18,$C$19,$B33,E$24) -> 0 | F33: =_xll.DBRW($B$9,$C$16,$C$17,F$23,C$22,$C$18,$C$19,$B33,F$24) -> 0 | G33: =_xll.DBRW($B$9,$C$16,$C$17,F$23,C$22,$C$18,$C$19,$B33,G$24) -> 0 | H33: =_xll.DBRW($B$9,$C$16,$C$17,F$23,C$22,$C$18,$C$19,$B33,H$24) -> 0 | I33: =C33+F33 -> 0 | J33: =IF(I33=0,0,K33/I33) -> 0 | K33: =E33+H33 -> 0 | L33: =_xll.DBRW($B$9,$C$16,$C$17,L$23,L$22,$C$18,$C$19,$B33,L$24) -> 0 | M33: =_xll.DBRW($B$9,$C$16,$C$17,L$23,L$22,$C$18,$C$19,$B33,M$24) -> 0 | N33: =_xll.DBRW($B$9,$C$16,$C$17,L$23,L$22,$C$18,$C$19,$B33,N$24) -> 0 | O33: =_xll.DBRW($B$9,$C$16,$C$17,O$23,L$22,$C$18,$C$19,$B33,O$24) -> 0 | P33: =_xll.DBRW($B$9,$C$16,$C$17,O$23,L$22,$C$18,$C$19,$B33,P$24) -> 0 | Q33: =_xll.DBRW($B$9,$C$16,$C$17,O$23,L$22,$C$18,$C$19,$B33,Q$24) -> 0 | R33: =L33+O33 -> 0 | S33: =IF(R33=0,0,T33/R33) -> 0 | T33: =N33+Q33 -> 0 | U33: =_xll.DBRW($B$9,$C$16,$C$17,U$23,U$22,$C$18,$C$19,$B33,U$24) -> 0 | V33: =_xll.DBRW($B$9,$C$16,$C$17,U$23,U$22,$C$18,$C$19,$B33,V$24) -> 0 | W33: =_xll.DBRW($B$9,$C$16,$C$17,U$23,U$22,$C$18,$C$19,$B33,W$24) -> 0 | X33: =_xll.DBRW($B$9,$C$16,$C$17,X$23,U$22,$C$18,$C$19,$B33,X$24) -> 0 | Y33: =_xll.DBRW($B$9,$C$16,$C$17,X$23,U$22,$C$18,$C$19,$B33,Y$24) -> 0 | Z33: =_xll.DBRW($B$9,$C$16,$C$17,X$23,U$22,$C$18,$C$19,$B33,Z$24) -> 0 | AA33: =U33+X33 -> 0 | AB33: =IF(AA33=0,0,AC33/AA33) -> 0 | AC33: =Z33+W33 -> 0 | AD33: =_xll.DBRW($B$9,$C$16,$C$17,AD$23,AD$22,$C$18,$C$19,$B33,AD$24) -> 0 | AE33: =_xll.DBRW($B$9,$C$16,$C$17,AD$23,AD$22,$C$18,$C$19,$B33,AE$24) -> 0 | AF33: =_xll.DBRW($B$9,$C$16,$C$17,AD$23,AD$22,$C$18,$C$19,$B33,AF$24) -> 0 | AG33: =_xll.DBRW($B$9,$C$16,$C$17,AG$23,AD$22,$C$18,$C$19,$B33,AG$24) -> 0 | AH33: =_xll.DBRW($B$9,$C$16,$C$17,AG$23,AD$22,$C$18,$C$19,$B33,AH$24) -> 0 | AI33: =_xll.DBRW($B$9,$C$16,$C$17,AG$23,AD$22,$C$18,$C$19,$B33,AI$24) -> 0 | AJ33: =AG33+AD33 -> 0 | AK33: =IF(AJ33=0,0,AL33/AJ33) -> 0 | AL33: =AI33+AF33 -> 0
