Workbook
Name TM1REBUILDOPTION: 1
Name TM1RPTDATARNGARPT1: 'Market shares detailed'!$31:$186
Name TM1RPTDATARNGARPT1: 'Market shares summary'!$28:$50
Name TM1RPTDATARNGARPT1: 'Sales Analysis Detailed'!$23:$23
Name TM1RPTDATARNGARPT1: 'Sales Analysis Summary'!$27:$27
Name TM1RPTFMTIDCOL: 'Market shares detailed'!$A$1:$A$8
Name TM1RPTFMTIDCOL: 'Market shares summary'!$A$1:$A$8
Name TM1RPTFMTIDCOL: 'Sales Analysis Detailed'!$A$1:$A$8
Name TM1RPTFMTIDCOL: 'Sales Analysis Summary'!$A$1:$A$8
Name TM1RPTFMTRNG: 'Market shares detailed'!$G$1:$AK$8
Name TM1RPTFMTRNG: 'Market shares summary'!$B$1:$AF$8
Name TM1RPTFMTRNG: 'Sales Analysis Detailed'!$B$1:$O$8
Name TM1RPTFMTRNG: 'Sales Analysis Summary'!$B$1:$Q$8

Sheet Sales Analysis Summary
A1: [Begin Format Range]
A2: =0 -> 0
A3: =1 -> 1
A4: =2 -> 2
A5: =3 -> 3
A6: D
A7: N
A8: [End Format Range]
B9: =_xll.TM1RPTVIEW("CXMD:FTM_DATA_MARGIN:ARPT1", 1, _xll.TM1RPTTITLE("CXMD:Month",$C$20), _xll.TM1RPTTITLE("CXMD:DIM_Origin_Company",$C$21), _xll.TM1RPTTITLE("CXMD:DIM_Allocation",$C$22), _xll.TM1RPTTITLE("CXMD:DIM_Customer_Supplier",$C$18),TM1RPTFMTRNG,TM1RPTFMTIDCOL) -> CXMD:FTM_DATA_MARGIN:ARPT1
B18: Customer_Supplier | C18: =_xll.SUBNM("CXMD:DIM_Customer_Supplier","","Others") -> Others
B19: Sales performance analysis - summary
B20: Month | C20: =_xll.SUBNM("CXMD:Month","","Total_Month") -> Total_Month
B21: Origin_Company | C21: =_xll.SUBNM("CXMD:DIM_Origin_Company","","KUHN GERMANY","Name EN") -> KUHN GERMANY
B22: Allocation | C22: =CONCATENATE(_xll.DBRA("CXMD:DIM_Origin_Company",C21,"Origin Company"),"_SALES") -> D_SALES
C25: =_xll.SUBNM("CXMD:Actuality","Actuality","AC2018","Description EN") -> AC2018 | E25: % of net sales machines + parts | F25: =_xll.SUBNM("CXMD:Actuality","","BU2019draft","Description EN") -> BU2019draft | H25: SALES % | I25: % of net sales machines + parts | J25: =_xll.SUBNM("CXMD:Actuality","","FC3_2019","Description EN") -> FC3_2019 | L25: SALES % | M25: % of net sales machines + parts | N25: =_xll.SUBNM("CXMD:Actuality","","BU2020Draft","Description EN") -> BU2020Draft | P25: SALES % | Q25: % of net sales machines + parts
C26: QTY | D26: SALES | F26: QTY | G26: SALES | H26: N-1 | J26: QTY | K26: SALES | L26: N-1 | N26: QTY | O26: SALES | P26: N-1
A27: =IF(_xll.TM1RPTELISCONSOLIDATED($B$27,$B27),IF(_xll.TM1RPTELLEV($B$27,$B27)<=3,_xll.TM1RPTELLEV($B$27,$B27),"D"),"N") -> N | B27: =_xll.TM1RPTROW($B$9,"CXMD:DIM_Configuration","Product_Line","","Description EN",0) | C27: =_xll.DBRW($B$9,$C$20,C$25,$C$21,$C$22,$C$18,$B27,C$26) | D27: =_xll.DBRW($B$9,$C$20,D$25,$C$21,$C$22,$C$18,$B27,D$26) | E27: =D27/$D$27 -> #VALUE! | F27: =_xll.DBRW($B$9,$C$20,F$25,$C$21,$C$22,$C$18,$B27,F$26) | G27: =_xll.DBRW($B$9,$C$20,F$25,$C$21,$C$22,$C$18,$B27,G$26) | H27: =IF(D27<>0,(G27-D27)/D27,0) -> #VALUE! | I27: =G27/$G$27 -> #VALUE! | J27: =_xll.DBRW($B$9,$C$20,J$25,$C$21,$C$22,$C$18,$B27,J$26) | K27: =_xll.DBRW($B$9,$C$20,J$25,$C$21,$C$22,$C$18,$B27,K$26) | L27: =IF(G27<>0,(K27-G27)/G27,0) -> #VALUE! | M27: =K27/$K$27 -> #VALUE! | N27: =_xll.DBRW($B$9,$C$20,N$25,$C$21,$C$22,$C$18,$B27,N$26) | O27: =_xll.DBRW($B$9,$C$20,N$25,$C$21,$C$22,$C$18,$B27,O$26) | P27: =IF(K27<>0,(O27-K27)/K27,0) -> #VALUE! | Q27: =O27/$O$27 -> #VALUE!

Sheet Sales Analysis Detailed
A1: [Begin Format Range]
A2: =0 -> 0
A3: =1 -> 1
A4: =2 -> 2
A5: =3 -> 3
A6: D
A7: N
A8: [End Format Range]
B9: =_xll.TM1RPTVIEW("CXMD:FTM_DATA_MARGIN:ARPT1", 1, _xll.TM1RPTTITLE("CXMD:Month",$C$16), _xll.TM1RPTTITLE("CXMD:DIM_Origin_Company",$C$17), _xll.TM1RPTTITLE("CXMD:DIM_Allocation",$C$18), _xll.TM1RPTTITLE("CXMD:DIM_Customer_Supplier",$C$15),TM1RPTFMTRNG,TM1RPTFMTIDCOL) -> CXMD:FTM_DATA_MARGIN:ARPT1
B14: Sales performance analysis
B15: Customer_Supplier | C15: =_xll.SUBNM("CXMD:DIM_Customer_Supplier","","Others") -> Others
B16: Month | C16: =_xll.SUBNM("CXMD:Month","","Total_Month") -> Total_Month
B17: Origin_Company | C17: ='Sales Analysis Summary'!C21 -> KUHN GERMANY
B18: Allocation | C18: =_xll.SUBNM("CXMD:DIM_Allocation","","Total Allocation","Allocation EN") -> Total Allocation
C21: ='Sales Analysis Summary'!C25 -> AC2018 | E21: % of net sales machines+ parts | F21: ='Sales Analysis Summary'!F25 -> BU2019draft | H21: SALES % N-1 | I21: % of net sales machines+ parts | J21: ='Sales Analysis Summary'!J25 -> FC3_2019 | L21: SALES % N-1 | M21: % of net sales machines+ parts | N21: ='Sales Analysis Summary'!N25 -> BU2020Draft | P21: SALES % N-1 | Q21: % of net sales machines+ parts
C22: QTY | D22: SALES | F22: QTY | G22: SALES | J22: QTY | K22: SALES | N22: QTY | O22: SALES
A23: =IF(_xll.TM1RPTELISCONSOLIDATED($B$23,$B23),IF(_xll.TM1RPTELLEV($B$23,$B23)<=3,_xll.TM1RPTELLEV($B$23,$B23),"D"),"N") -> N | B23: =_xll.TM1RPTROW($B$9,"CXMD:DIM_Configuration","Product_Market_Shares_BUD_Meeting","","Description EN",0) | C23: =_xll.DBRW($B$9,$C$16,C$21,$C$17,$C$18,$C$15,$B23,C$22) | D23: =_xll.DBRW($B$9,$C$16,C$21,$C$17,$C$18,$C$15,$B23,D$22) | E23: =D23/$D$23 -> #VALUE! | F23: =_xll.DBRW($B$9,$C$16,F$21,$C$17,$C$18,$C$15,$B23,F$22) | G23: =_xll.DBRW($B$9,$C$16,F$21,$C$17,$C$18,$C$15,$B23,G$22) | H23: =IF(D23<>0,(G23-D23)/D23,0) -> #VALUE! | I23: =G23/$G$23 -> #VALUE! | J23: =_xll.DBRW($B$9,$C$16,J$21,$C$17,$C$18,$C$15,$B23,J$22) | K23: =_xll.DBRW($B$9,$C$16,J$21,$C$17,$C$18,$C$15,$B23,K$22) | L23: =IF(G23<>0,(K23-G23)/G23,0) -> #VALUE! | M23: =K23/$K$23 -> #VALUE! | N23: =_xll.DBRW($B$9,$C$16,N$21,$C$17,$C$18,$C$15,$B23,N$22) | O23: =_xll.DBRW($B$9,$C$16,N$21,$C$17,$C$18,$C$15,$B23,O$22) | P23: =IF(K23<>0,(O23-K23)/K23,0) -> #VALUE! | Q23: =O23/$K$23 -> #VALUE!

Sheet {AR}01 (2)
B23: TOTAL PRODUCT
B24: L - 000 -
B25: L - 700000 - PLOUGHING
B26: F - 700000 - PLOUGHING
B27: F - 700100 - MOUNTED REV. PLOUGHS
B28: F - 700200 - SEMI-MOUNTED REV. PLOUGHS
B29: F - 700300 - SEMI MOUNTED PLOUGHS
B30: L - 701000 - TILLAGE
B31: F - 701000 - TILLAGE
B32: F - 701100 - DEEP WORKING CULTIVATORS
B33: S - 701100 - DEEP WORKING CULTIVATORS
B34: S - 701110 - SUB SOILER
... B162: L - NA - Not Available

Sheet Market shares summary
A1: [Begin Format Range]
A2: =0 -> 0
A3: =1 -> 1
A4: =2 -> 2
A5: =3 -> 3
A6: D
A7: N
A8: [End Format Range]
B9: =_xll.TM1RPTVIEW("CXMD:OTC_DATA_MARKET_ANALYSIS:ARPT1", 0, _xll.TM1RPTTITLE("CXMD:Currency",$C$18), _xll.TM1RPTTITLE("CXMD:DIM_Prev_IC_mapping",$C$19), _xll.TM1RPTTITLE("CXMD:DIM_Origin_Company",$C$21), _xll.TM1RPTTITLE("CXMD:DIM_Country",$C$22),TM1RPTFMTRNG,TM1RPTFMTIDCOL) -> CXMD:OTC_DATA_MARKET_ANALYSIS:ARPT1
B18: Currency | C18: =_xll.SUBNM("CXMD:Currency","Par défaut","CD_LC","Description EN") -> Local currency
B19: Prev_IC_mapping | C19: =_xll.SUBNM("CXMD:Prev_IC_mapping","","Others") -> Others
B20: MARKET SHARES - 4 PERIODS
B21: Origin_Company | C21: =_xll.SUBNM("CXMD:DIM_Origin_Company","","KUHN GERMANY","Name EN") -> KUHN GERMANY
B22: Country | C22: =_xll.SUBNM("CXMD:DIM_Country","Total Country SOM","C-101","Country Name") -> ALLEMAGNE
C25: =_xll.SUBNM("CXMD:Actuality","Actuality_Market_Share","AC2018","Description EN") -> AC2018 | F25: =_xll.SUBNM("CXMD:Actuality","Actuality_Market_Share","AC2018","Description EN") -> AC2018 | I25: Market Share % | K25: =_xll.SUBNM("CXMD:Actuality","Actuality_Market_Share","BU2019draft","Description EN") -> BU2019draft | N25: =_xll.SUBNM("CXMD:Actuality","Actuality_Market_Share","BU2019draft","Description EN") -> BU2019draft | Q25: Market Share % | S25: =_xll.SUBNM("CXMD:Actuality","Actuality_Market_Share","FC3_2019","Description EN") -> FC3_2019 | V25: =_xll.SUBNM("CXMD:Actuality","Actuality_Market_Share","FC3_2019","Description EN") -> FC3_2019 | Y25: Market Share % | AA25: =_xll.SUBNM("CXMD:Actuality","Actuality_Market_Share","BU2020Draft","Description EN") -> BU2020Draft | AD25: =_xll.SUBNM("CXMD:Actuality","Actuality_Market_Share","BU2020Draft","Description EN") -> BU2020Draft | AG25: Market Share %
C26: KUHN Sales | F26: KUHN_Scope | K26: KUHN Sales | N26: KUHN_Scope | S26: KUHN Sales | V26: KUHN_Scope | AA26: KUHN Sales | AD26: KUHN_Scope
C27: QTY | D27: Unit.Price | E27: SALES | F27: QTY | G27: Unit.Price | H27: SALES | I27: QTY | J27: SALES | K27: QTY | L27: Unit.Price | M27: SALES | N27: QTY | O27: Unit.Price | P27: SALES | Q27: QTY | R27: SALES | S27: QTY | T27: Unit.Price | U27: SALES | V27: QTY | W27: Unit.Price | X27: SALES | Y27: QTY | Z27: SALES | AA27: QTY | AB27: Unit.Price | AC27: SALES | AD27: QTY | AE27: Unit.Price | AF27: SALES | AG27: QTY | AH27: SALES
A28: =IF(_xll.TM1RPTELISCONSOLIDATED($B$28,$B28),IF(_xll.TM1RPTELLEV($B$28,$B28)<=3,_xll.TM1RPTELLEV($B$28,$B28),"D"),"N") -> 0 | B28: =_xll.TM1RPTROW($B$9,"CXMD:DIM_Configuration","Product_Line","","Description EN",0) -> TOTAL PRODUCT | C28: =_xll.DBRW($B$9,$C$18,$C$19,C$26,C$25,$C$21,$C$22,$B28,C$27) -> 0 | D28: =_xll.DBRW($B$9,$C$18,$C$19,C$26,C$25,$C$21,$C$22,$B28,D$27) -> 0 | E28: =_xll.DBRW($B$9,$C$18,$C$19,C$26,C$25,$C$21,$C$22,$B28,E$27) -> 0 | F28: =_xll.DBRW($B$9,$C$18,$C$19,F$26,F$25,$C$21,$C$22,$B28,F$27) -> 0 | G28: =_xll.DBRW($B$9,$C$18,$C$19,F$26,F$25,$C$21,$C$22,$B28,G$27) -> 0 | H28: =_xll.DBRW($B$9,$C$18,$C$19,F$26,F$25,$C$21,$C$22,$B28,H$27) -> 0 | I28: =IF(F28<>0,C28/F28,0) -> 0 | J28: =IF(H28<>0,E28/H28,0) -> 0 | K28: =_xll.DBRW($B$9,$C$18,$C$19,K$26,K$25,$C$21,$C$22,$B28,K$27) -> 0 | L28: =_xll.DBRW($B$9,$C$18,$C$19,K$26,K$25,$C$21,$C$22,$B28,L$27) -> 0 | M28: =_xll.DBRW($B$9,$C$18,$C$19,K$26,K$25,$C$21,$C$22,$B28,M$27) -> 0 | N28: =_xll.DBRW($B$9,$C$18,$C$19,N$26,N$25,$C$21,$C$22,$B28,N$27) -> 0 | O28: =_xll.DBRW($B$9,$C$18,$C$19,N$26,N$25,$C$21,$C$22,$B28,O$27) -> 0 | P28: =_xll.DBRW($B$9,$C$18,$C$19,N$26,N$25,$C$21,$C$22,$B28,P$27) -> 0 | Q28: =IF(N28<>0,K28/N28,0) -> 0 | R28: =IF(P28<>0,M28/P28,0) -> 0 | S28: =_xll.DBRW($B$9,$C$18,$C$19,S$26,S$25,$C$21,$C$22,$B28,S$27) -> 0 | T28: =_xll.DBRW($B$9,$C$18,$C$19,S$26,S$25,$C$21,$C$22,$B28,T$27) -> 0 | U28: =_xll.DBRW($B$9,$C$18,$C$19,S$26,S$25,$C$21,$C$22,$B28,U$27) -> 0 | V28: =_xll.DBRW($B$9,$C$18,$C$19,V$26,V$25,$C$21,$C$22,$B28,V$27) -> 0 | W28: =_xll.DBRW($B$9,$C$18,$C$19,V$26,V$25,$C$21,$C$22,$B28,W$27) -> 0 | X28: =_xll.DBRW($B$9,$C$18,$C$19,V$26,V$25,$C$21,$C$22,$B28,X$27) -> 0 | Y28: =IF(V28<>0,S28/V28,0) -> 0 | Z28: =IF(X28<>0,U28/X28,0) -> 0 | AA28: =_xll.DBRW($B$9,$C$18,$C$19,AA$26,AA$25,$C$21,$C$22,$B28,AA$27) -> 0 | AB28: =_xll.DBRW($B$9,$C$18,$C$19,AA$26,AA$25,$C$21,$C$22,$B28,AB$27) -> 0 | AC28: =_xll.DBRW($B$9,$C$18,$C$19,AA$26,AA$25,$C$21,$C$22,$B28,AC$27) -> 0 | AD28: =_xll.DBRW($B$9,$C$18,$C$19,AD$26,AD$25,$C$21,$C$22,$B28,AD$27) -> 0 | AE28: =_xll.DBRW($B$9,$C$18,$C$19,AD$26,AD$25,$C$21,$C$22,$B28,AE$27) -> 0 | AF28: =_xll.DBRW($B$9,$C$18,$C$19,AD$26,AD$25,$C$21,$C$22,$B28,AF$27) -> 0 | AG28: =IF(AD28<>0,AA28/AD28,0) -> 0 | AH28: =IF(AF28<>0,AC28/AF28,0) -> 0
A29: =IF(_xll.TM1RPTELISCONSOLIDATED($B$28,$B29),IF(_xll.TM1RPTELLEV($B$28,$B29)<=3,_xll.TM1RPTELLEV($B$28,$B29),"D"),"N") -> 1 | B29: L - LAB - Ploughing | C29: =_xll.DBRW($B$9,$C$18,$C$19,C$26,C$25,$C$21,$C$22,$B29,C$27) -> 0 | D29: =_xll.DBRW($B$9,$C$18,$C$19,C$26,C$25,$C$21,$C$22,$B29,D$27) -> 0 | E29: =_xll.DBRW($B$9,$C$18,$C$19,C$26,C$25,$C$21,$C$22,$B29,E$27) -> 0 | F29: =_xll.DBRW($B$9,$C$18,$C$19,F$26,F$25,$C$21,$C$22,$B29,F$27) -> 0 | G29: =_xll.DBRW($B$9,$C$18,$C$19,F$26,F$25,$C$21,$C$22,$B29,G$27) -> 0 | H29: =_xll.DBRW($B$9,$C$18,$C$19,F$26,F$25,$C$21,$C$22,$B29,H$27) -> 0 | I29: =IF(F29<>0,C29/F29,0) -> 0 | J29: =IF(H29<>0,E29/H29,0) -> 0 | K29: =_xll.DBRW($B$9,$C$18,$C$19,K$26,K$25,$C$21,$C$22,$B29,K$27) -> 0 | L29: =_xll.DBRW($B$9,$C$18,$C$19,K$26,K$25,$C$21,$C$22,$B29,L$27) -> 0 | M29: =_xll.DBRW($B$9,$C$18,$C$19,K$26,K$25,$C$21,$C$22,$B29,M$27) -> 0 | N29: =_xll.DBRW($B$9,$C$18,$C$19,N$26,N$25,$C$21,$C$22,$B29,N$27) -> 0 | O29: =_xll.DBRW($B$9,$C$18,$C$19,N$26,N$25,$C$21,$C$22,$B29,O$27) -> 0 | P29: =_xll.DBRW($B$9,$C$18,$C$19,N$26,N$25,$C$21,$C$22,$B29,P$27) -> 0 | Q29: =IF(N29<>0,K29/N29,0) -> 0 | R29: =IF(P29<>0,M29/P29,0) -> 0 | S29: =_xll.DBRW($B$9,$C$18,$C$19,S$26,S$25,$C$21,$C$22,$B29,S$27) -> 0 | T29: =_xll.DBRW($B$9,$C$18,$C$19,S$26,S$25,$C$21,$C$22,$B29,T$27) -> 0 | U29: =_xll.DBRW($B$9,$C$18,$C$19,S$26,S$25,$C$21,$C$22,$B29,U$27) -> 0 | V29: =_xll.DBRW($B$9,$C$18,$C$19,V$26,V$25,$C$21,$C$22,$B29,V$27) -> 0 | W29: =_xll.DBRW($B$9,$C$18,$C$19,V$26,V$25,$C$21,$C$22,$B29,W$27) -> 0 | X29: =_xll.DBRW($B$9,$C$18,$C$19,V$26,V$25,$C$21,$C$22,$B29,X$27) -> 0 | Y29: =IF(V29<>0,S29/V29,0) -> 0 | Z29: =IF(X29<>0,U29/X29,0) -> 0 | AA29: =_xll.DBRW($B$9,$C$18,$C$19,AA$26,AA$25,$C$21,$C$22,$B29,AA$27) -> 0 | AB29: =_xll.DBRW($B$9,$C$18,$C$19,AA$26,AA$25,$C$21,$C$22,$B29,AB$27) -> 0 | AC29: =_xll.DBRW($B$9,$C$18,$C$19,AA$26,AA$25,$C$21,$C$22,$B29,AC$27) -> 0 | AD29: =_xll.DBRW($B$9,$C$18,$C$19,AD$26,AD$25,$C$21,$C$22,$B29,AD$27) -> 0 | AE29: =_xll.DBRW($B$9,$C$18,$C$19,AD$26,AD$25,$C$21,$C$22,$B29,AE$27) -> 0 | AF29: =_xll.DBRW($B$9,$C$18,$C$19,AD$26,AD$25,$C$21,$C$22,$B29,AF$27) -> 0 | AG29: =IF(AD29<>0,AA29/AD29,0) -> 0 | AH29: =IF(AF29<>0,AC29/AF29,0) -> 0
A30: =IF(_xll.TM1RPTELISCONSOLIDATED($B$28,$B30),IF(_xll.TM1RPTELLEV($B$28,$B30)<=3,_xll.TM1RPTELLEV($B$28,$B30),"D"),"N") -> 1 | B30: L - SOL - Tillage | C30: =_xll.DBRW($B$9,$C$18,$C$19,C$26,C$25,$C$21,$C$22,$B30,C$27) -> 0 | D30: =_xll.DBRW($B$9,$C$18,$C$19,C$26,C$25,$C$21,$C$22,$B30,D$27) -> 0 | E30: =_xll.DBRW($B$9,$C$18,$C$19,C$26,C$25,$C$21,$C$22,$B30,E$27) -> 0 | F30: =_xll.DBRW($B$9,$C$18,$C$19,F$26,F$25,$C$21,$C$22,$B30,F$27) -> 0 | G30: =_xll.DBRW($B$9,$C$18,$C$19,F$26,F$25,$C$21,$C$22,$B30,G$27) -> 0 | H30: =_xll.DBRW($B$9,$C$18,$C$19,F$26,F$25,$C$21,$C$22,$B30,H$27) -> 0 | I30: =IF(F30<>0,C30/F30,0) -> 0 | J30: =IF(H30<>0,E30/H30,0) -> 0 | K30: =_xll.DBRW($B$9,$C$18,$C$19,K$26,K$25,$C$21,$C$22,$B30,K$27) -> 0 | L30: =_xll.DBRW($B$9,$C$18,$C$19,K$26,K$25,$C$21,$C$22,$B30,L$27) -> 0 | M30: =_xll.DBRW($B$9,$C$18,$C$19,K$26,K$25,$C$21,$C$22,$B30,M$27) -> 0 | N30: =_xll.DBRW($B$9,$C$18,$C$19,N$26,N$25,$C$21,$C$22,$B30,N$27) -> 0 | O30: =_xll.DBRW($B$9,$C$18,$C$19,N$26,N$25,$C$21,$C$22,$B30,O$27) -> 0 | P30: =_xll.DBRW($B$9,$C$18,$C$19,N$26,N$25,$C$21,$C$22,$B30,P$27) -> 0 | Q30: =IF(N30<>0,K30/N30,0) -> 0 | R30: =IF(P30<>0,M30/P30,0) -> 0 | S30: =_xll.DBRW($B$9,$C$18,$C$19,S$26,S$25,$C$21,$C$22,$B30,S$27) -> 0 | T30: =_xll.DBRW($B$9,$C$18,$C$19,S$26,S$25,$C$21,$C$22,$B30,T$27) -> 0 | U30: =_xll.DBRW($B$9,$C$18,$C$19,S$26,S$25,$C$21,$C$22,$B30,U$27) -> 0 | V30: =_xll.DBRW($B$9,$C$18,$C$19,V$26,V$25,$C$21,$C$22,$B30,V$27) -> 0 | W30: =_xll.DBRW($B$9,$C$18,$C$19,V$26,V$25,$C$21,$C$22,$B30,W$27) -> 0 | X30: =_xll.DBRW($B$9,$C$18,$C$19,V$26,V$25,$C$21,$C$22,$B30,X$27) -> 0 | Y30: =IF(V30<>0,S30/V30,0) -> 0 | Z30: =IF(X30<>0,U30/X30,0) -> 0 | AA30: =_xll.DBRW($B$9,$C$18,$C$19,AA$26,AA$25,$C$21,$C$22,$B30,AA$27) -> 0 | AB30: =_xll.DBRW($B$9,$C$18,$C$19,AA$26,AA$25,$C$21,$C$22,$B30,AB$27) -> 0 | AC30: =_xll.DBRW($B$9,$C$18,$C$19,AA$26,AA$25,$C$21,$C$22,$B30,AC$27) -> 0 | AD30: =_xll.DBRW($B$9,$C$18,$C$19,AD$26,AD$25,$C$21,$C$22,$B30,AD$27) -> 0 | AE30: =_xll.DBRW($B$9,$C$18,$C$19,AD$26,AD$25,$C$21,$C$22,$B30,AE$27) -> 0 | AF30: =_xll.DBRW($B$9,$C$18,$C$19,AD$26,AD$25,$C$21,$C$22,$B30,AF$27) -> 0 | AG30: =IF(AD30<>0,AA30/AD30,0) -> 0 | AH30: =IF(AF30<>0,AC30/AF30,0) -> 0
A31: =IF(_xll.TM1RPTELISCONSOLIDATED($B$28,$B31),IF(_xll.TM1RPTELLEV($B$28,$B31)<=3,_xll.TM1RPTELLEV($B$28,$B31),"D"),"N") -> 1 | B31: L - SEM - Seeding | C31: =_xll.DBRW($B$9,$C$18,$C$19,C$26,C$25,$C$21,$C$22,$B31,C$27) -> 0 | D31: =_xll.DBRW($B$9,$C$18,$C$19,C$26,C$25,$C$21,$C$22,$B31,D$27) -> 0 | E31: =_xll.DBRW($B$9,$C$18,$C$19,C$26,C$25,$C$21,$C$22,$B31,E$27) -> 0 | F31: =_xll.DBRW($B$9,$C$18,$C$19,F$26,F$25,$C$21,$C$22,$B31,F$27) -> 0 | G31: =_xll.DBRW($B$9,$C$18,$C$19,F$26,F$25,$C$21,$C$22,$B31,G$27) -> 0 | H31: =_xll.DBRW($B$9,$C$18,$C$19,F$26,F$25,$C$21,$C$22,$B31,H$27) -> 0 | I31: =IF(F31<>0,C31/F31,0) -> 0 | J31: =IF(H31<>0,E31/H31,0) -> 0 | K31: =_xll.DBRW($B$9,$C$18,$C$19,K$26,K$25,$C$21,$C$22,$B31,K$27) -> 0 | L31: =_xll.DBRW($B$9,$C$18,$C$19,K$26,K$25,$C$21,$C$22,$B31,L$27) -> 0 | M31: =_xll.DBRW($B$9,$C$18,$C$19,K$26,K$25,$C$21,$C$22,$B31,M$27) -> 0 | N31: =_xll.DBRW($B$9,$C$18,$C$19,N$26,N$25,$C$21,$C$22,$B31,N$27) -> 0 | O31: =_xll.DBRW($B$9,$C$18,$C$19,N$26,N$25,$C$21,$C$22,$B31,O$27) -> 0 | P31: =_xll.DBRW($B$9,$C$18,$C$19,N$26,N$25,$C$21,$C$22,$B31,P$27) -> 0 | Q31: =IF(N31<>0,K31/N31,0) -> 0 | R31: =IF(P31<>0,M31/P31,0) -> 0 | S31: =_xll.DBRW($B$9,$C$18,$C$19,S$26,S$25,$C$21,$C$22,$B31,S$27) -> 0 | T31: =_xll.DBRW($B$9,$C$18,$C$19,S$26,S$25,$C$21,$C$22,$B31,T$27) -> 0 | U31: =_xll.DBRW($B$9,$C$18,$C$19,S$26,S$25,$C$21,$C$22,$B31,U$27) -> 0 | V31: =_xll.DBRW($B$9,$C$18,$C$19,V$26,V$25,$C$21,$C$22,$B31,V$27) -> 0 | W31: =_xll.DBRW($B$9,$C$18,$C$19,V$26,V$25,$C$21,$C$22,$B31,W$27) -> 0 | X31: =_xll.DBRW($B$9,$C$18,$C$19,V$26,V$25,$C$21,$C$22,$B31,X$27) -> 0 | Y31: =IF(V31<>0,S31/V31,0) -> 0 | Z31: =IF(X31<>0,U31/X31,0) -> 0 | AA31: =_xll.DBRW($B$9,$C$18,$C$19,AA$26,AA$25,$C$21,$C$22,$B31,AA$27) -> 0 | AB31: =_xll.DBRW($B$9,$C$18,$C$19,AA$26,AA$25,$C$21,$C$22,$B31,AB$27) -> 0 | AC31: =_xll.DBRW($B$9,$C$18,$C$19,AA$26,AA$25,$C$21,$C$22,$B31,AC$27) -> 0 | AD31: =_xll.DBRW($B$9,$C$18,$C$19,AD$26,AD$25,$C$21,$C$22,$B31,AD$27) -> 0 | AE31: =_xll.DBRW($B$9,$C$18,$C$19,AD$26,AD$25,$C$21,$C$22,$B31,AE$27) -> 0 | AF31: =_xll.DBRW($B$9,$C$18,$C$19,AD$26,AD$25,$C$21,$C$22,$B31,AF$27) -> 0 | AG31: =IF(AD31<>0,AA31/AD31,0) -> 0 | AH31: =IF(AF31<>0,AC31/AF31,0) -> 0
A32: =IF(_xll.TM1RPTELISCONSOLIDATED($B$28,$B32),IF(_xll.TM1RPTELLEV($B$28,$B32)<=3,_xll.TM1RPTELLEV($B$28,$B32),"D"),"N") -> 1 | B32: L - FER - Fertilisation | C32: =_xll.DBRW($B$9,$C$18,$C$19,C$26,C$25,$C$21,$C$22,$B32,C$27) -> 0 | D32: =_xll.DBRW($B$9,$C$18,$C$19,C$26,C$25,$C$21,$C$22,$B32,D$27) -> 0 | E32: =_xll.DBRW($B$9,$C$18,$C$19,C$26,C$25,$C$21,$C$22,$B32,E$27) -> 0 | F32: =_xll.DBRW($B$9,$C$18,$C$19,F$26,F$25,$C$21,$C$22,$B32,F$27) -> 0 | G32: =_xll.DBRW($B$9,$C$18,$C$19,F$26,F$25,$C$21,$C$22,$B32,G$27) -> 0 | H32: =_xll.DBRW($B$9,$C$18,$C$19,F$26,F$25,$C$21,$C$22,$B32,H$27) -> 0 | I32: =IF(F32<>0,C32/F32,0) -> 0 | J32: =IF(H32<>0,E32/H32,0) -> 0 | K32: =_xll.DBRW($B$9,$C$18,$C$19,K$26,K$25,$C$21,$C$22,$B32,K$27) -> 0 | L32: =_xll.DBRW($B$9,$C$18,$C$19,K$26,K$25,$C$21,$C$22,$B32,L$27) -> 0 | M32: =_xll.DBRW($B$9,$C$18,$C$19,K$26,K$25,$C$21,$C$22,$B32,M$27) -> 0 | N32: =_xll.DBRW($B$9,$C$18,$C$19,N$26,N$25,$C$21,$C$22,$B32,N$27) -> 0 | O32: =_xll.DBRW($B$9,$C$18,$C$19,N$26,N$25,$C$21,$C$22,$B32,O$27) -> 0 | P32: =_xll.DBRW($B$9,$C$18,$C$19,N$26,N$25,$C$21,$C$22,$B32,P$27) -> 0 | Q32: =IF(N32<>0,K32/N32,0) -> 0 | R32: =IF(P32<>0,M32/P32,0) -> 0 | S32: =_xll.DBRW($B$9,$C$18,$C$19,S$26,S$25,$C$21,$C$22,$B32,S$27) -> 0 | T32: =_xll.DBRW($B$9,$C$18,$C$19,S$26,S$25,$C$21,$C$22,$B32,T$27) -> 0 | U32: =_xll.DBRW($B$9,$C$18,$C$19,S$26,S$25,$C$21,$C$22,$B32,U$27) -> 0 | V32: =_xll.DBRW($B$9,$C$18,$C$19,V$26,V$25,$C$21,$C$22,$B32,V$27) -> 0 | W32: =_xll.DBRW($B$9,$C$18,$C$19,V$26,V$25,$C$21,$C$22,$B32,W$27) -> 0 | X32: =_xll.DBRW($B$9,$C$18,$C$19,V$26,V$25,$C$21,$C$22,$B32,X$27) -> 0 | Y32: =IF(V32<>0,S32/V32,0) -> 0 | Z32: =IF(X32<>0,U32/X32,0) -> 0 | AA32: =_xll.DBRW($B$9,$C$18,$C$19,AA$26,AA$25,$C$21,$C$22,$B32,AA$27) -> 0 | AB32: =_xll.DBRW($B$9,$C$18,$C$19,AA$26,AA$25,$C$21,$C$22,$B32,AB$27) -> 0 | AC32: =_xll.DBRW($B$9,$C$18,$C$19,AA$26,AA$25,$C$21,$C$22,$B32,AC$27) -> 0 | AD32: =_xll.DBRW($B$9,$C$18,$C$19,AD$26,AD$25,$C$21,$C$22,$B32,AD$27) -> 0 | AE32: =_xll.DBRW($B$9,$C$18,$C$19,AD$26,AD$25,$C$21,$C$22,$B32,AE$27) -> 0 | AF32: =_xll.DBRW($B$9,$C$18,$C$19,AD$26,AD$25,$C$21,$C$22,$B32,AF$27) -> 0 | AG32: =IF(AD32<>0,AA32/AD32,0) -> 0 | AH32: =IF(AF32<>0,AC32/AF32,0) -> 0
A33: =IF(_xll.TM1RPTELISCONSOLIDATED($B$28,$B33),IF(_xll.TM1RPTELLEV($B$28,$B33)<=3,_xll.TM1RPTELLEV($B$28,$B33),"D"),"N") -> 1 | B33: L - PLV - Spraying | C33: =_xll.DBRW($B$9,$C$18,$C$19,C$26,C$25,$C$21,$C$22,$B33,C$27) -> 0 | D33: =_xll.DBRW($B$9,$C$18,$C$19,C$26,C$25,$C$21,$C$22,$B33,D$27) -> 0 | E33: =_xll.DBRW($B$9,$C$18,$C$19,C$26,C$25,$C$21,$C$22,$B33,E$27) -> 0 | F33: =_xll.DBRW($B$9,$C$18,$C$19,F$26,F$25,$C$21,$C$22,$B33,F$27) -> 0 | G33: =_xll.DBRW($B$9,$C$18,$C$19,F$26,F$25,$C$21,$C$22,$B33,G$27) -> 0 | H33: =_xll.DBRW($B$9,$C$18,$C$19,F$26,F$25,$C$21,$C$22,$B33,H$27) -> 0 | I33: =IF(F33<>0,C33/F33,0) -> 0 | J33: =IF(H33<>0,E33/H33,0) -> 0 | K33: =_xll.DBRW($B$9,$C$18,$C$19,K$26,K$25,$C$21,$C$22,$B33,K$27) -> 0 | L33: =_xll.DBRW($B$9,$C$18,$C$19,K$26,K$25,$C$21,$C$22,$B33,L$27) -> 0 | M33: =_xll.DBRW($B$9,$C$18,$C$19,K$26,K$25,$C$21,$C$22,$B33,M$27) -> 0 | N33: =_xll.DBRW($B$9,$C$18,$C$19,N$26,N$25,$C$21,$C$22,$B33,N$27) -> 0 | O33: =_xll.DBRW($B$9,$C$18,$C$19,N$26,N$25,$C$21,$C$22,$B33,O$27) -> 0 | P33: =_xll.DBRW($B$9,$C$18,$C$19,N$26,N$25,$C$21,$C$22,$B33,P$27) -> 0 | Q33: =IF(N33<>0,K33/N33,0) -> 0 | R33: =IF(P33<>0,M33/P33,0) -> 0 | S33: =_xll.DBRW($B$9,$C$18,$C$19,S$26,S$25,$C$21,$C$22,$B33,S$27) -> 0 | T33: =_xll.DBRW($B$9,$C$18,$C$19,S$26,S$25,$C$21,$C$22,$B33,T$27) -> 0 | U33: =_xll.DBRW($B$9,$C$18,$C$19,S$26,S$25,$C$21,$C$22,$B33,U$27) -> 0 | V33: =_xll.DBRW($B$9,$C$18,$C$19,V$26,V$25,$C$21,$C$22,$B33,V$27) -> 0 | W33: =_xll.DBRW($B$9,$C$18,$C$19,V$26,V$25,$C$21,$C$22,$B33,W$27) -> 0 | X33: =_xll.DBRW($B$9,$C$18,$C$19,V$26,V$25,$C$21,$C$22,$B33,X$27) -> 0 | Y33: =IF(V33<>0,S33/V33,0) -> 0 | Z33: =IF(X33<>0,U33/X33,0) -> 0 | AA33: =_xll.DBRW($B$9,$C$18,$C$19,AA$26,AA$25,$C$21,$C$22,$B33,AA$27) -> 0 | AB33: =_xll.DBRW($B$9,$C$18,$C$19,AA$26,AA$25,$C$21,$C$22,$B33,AB$27) -> 0 | AC33: =_xll.DBRW($B$9,$C$18,$C$19,AA$26,AA$25,$C$21,$C$22,$B33,AC$27) -> 0 | AD33: =_xll.DBRW($B$9,$C$18,$C$19,AD$26,AD$25,$C$21,$C$22,$B33,AD$27) -> 0 | AE33: =_xll.DBRW($B$9,$C$18,$C$19,AD$26,AD$25,$C$21,$C$22,$B33,AE$27) -> 0 | AF33: =_xll.DBRW($B$9,$C$18,$C$19,AD$26,AD$25,$C$21,$C$22,$B33,AF$27) -> 0 | AG33: =IF(AD33<>0,AA33/AD33,0) -> 0 | AH33: =IF(AF33<>0,AC33/AF33,0) -> 0
A34: =IF(_xll.TM1RPTELISCONSOLIDATED($B$28,$B34),IF(_xll.TM1RPTELLEV($B$28,$B34)<=3,_xll.TM1RPTELLEV($B$28,$B34),"D"),"N") -> 1 | B34: L - ENT - Landscape Maintenance | C34: =_xll.DBRW($B$9,$C$18,$C$19,C$26,C$25,$C$21,$C$22,$B34,C$27) -> 0 | D34: =_xll.DBRW($B$9,$C$18,$C$19,C$26,C$25,$C$21,$C$22,$B34,D$27) -> 0 | E34: =_xll.DBRW($B$9,$C$18,$C$19,C$26,C$25,$C$21,$C$22,$B34,E$27) -> 0 | F34: =_xll.DBRW($B$9,$C$18,$C$19,F$26,F$25,$C$21,$C$22,$B34,F$27) -> 0 | G34: =_xll.DBRW($B$9,$C$18,$C$19,F$26,F$25,$C$21,$C$22,$B34,G$27) -> 0 | H34: =_xll.DBRW($B$9,$C$18,$C$19,F$26,F$25,$C$21,$C$22,$B34,H$27) -> 0 | I34: =IF(F34<>0,C34/F34,0) -> 0 | J34: =IF(H34<>0,E34/H34,0) -> 0 | K34: =_xll.DBRW($B$9,$C$18,$C$19,K$26,K$25,$C$21,$C$22,$B34,K$27) -> 0 | L34: =_xll.DBRW($B$9,$C$18,$C$19,K$26,K$25,$C$21,$C$22,$B34,L$27) -> 0 | M34: =_xll.DBRW($B$9,$C$18,$C$19,K$26,K$25,$C$21,$C$22,$B34,M$27) -> 0 | N34: =_xll.DBRW($B$9,$C$18,$C$19,N$26,N$25,$C$21,$C$22,$B34,N$27) -> 0 | O34: =_xll.DBRW($B$9,$C$18,$C$19,N$26,N$25,$C$21,$C$22,$B34,O$27) -> 0 | P34: =_xll.DBRW($B$9,$C$18,$C$19,N$26,N$25,$C$21,$C$22,$B34,P$27) -> 0 | Q34: =IF(N34<>0,K34/N34,0) -> 0 | R34: =IF(P34<>0,M34/P34,0) -> 0 | S34: =_xll.DBRW($B$9,$C$18,$C$19,S$26,S$25,$C$21,$C$22,$B34,S$27) -> 0 | T34: =_xll.DBRW($B$9,$C$18,$C$19,S$26,S$25,$C$21,$C$22,$B34,T$27) -> 0 | U34: =_xll.DBRW($B$9,$C$18,$C$19,S$26,S$25,$C$21,$C$22,$B34,U$27) -> 0 | V34: =_xll.DBRW($B$9,$C$18,$C$19,V$26,V$25,$C$21,$C$22,$B34,V$27) -> 0 | W34: =_xll.DBRW($B$9,$C$18,$C$19,V$26,V$25,$C$21,$C$22,$B34,W$27) -> 0 | X34: =_xll.DBRW($B$9,$C$18,$C$19,V$26,V$25,$C$21,$C$22,$B34,X$27) -> 0 | Y34: =IF(V34<>0,S34/V34,0) -> 0 | Z34: =IF(X34<>0,U34/X34,0) -> 0 | AA34: =_xll.DBRW($B$9,$C$18,$C$19,AA$26,AA$25,$C$21,$C$22,$B34,AA$27) -> 0 | AB34: =_xll.DBRW($B$9,$C$18,$C$19,AA$26,AA$25,$C$21,$C$22,$B34,AB$27) -> 0 | AC34: =_xll.DBRW($B$9,$C$18,$C$19,AA$26,AA$25,$C$21,$C$22,$B34,AC$27) -> 0 | AD34: =_xll.DBRW($B$9,$C$18,$C$19,AD$26,AD$25,$C$21,$C$22,$B34,AD$27) -> 0 | AE34: =_xll.DBRW($B$9,$C$18,$C$19,AD$26,AD$25,$C$21,$C$22,$B34,AE$27) -> 0 | AF34: =_xll.DBRW($B$9,$C$18,$C$19,AD$26,AD$25,$C$21,$C$22,$B34,AF$27) -> 0 | AG34: =IF(AD34<>0,AA34/AD34,0) -> 0 | AH34: =IF(AF34<>0,AC34/AF34,0) -> 0
A35: =IF(_xll.TM1RPTELISCONSOLIDATED($B$28,$B35),IF(_xll.TM1RPTELLEV($B$28,$B35)<=3,_xll.TM1RPTELLEV($B$28,$B35),"D"),"N") -> 1 | B35: L - BRO - Shredders | C35: =_xll.DBRW($B$9,$C$18,$C$19,C$26,C$25,$C$21,$C$22,$B35,C$27) -> 0 | D35: =_xll.DBRW($B$9,$C$18,$C$19,C$26,C$25,$C$21,$C$22,$B35,D$27) -> 0 | E35: =_xll.DBRW($B$9,$C$18,$C$19,C$26,C$25,$C$21,$C$22,$B35,E$27) -> 0 | F35: =_xll.DBRW($B$9,$C$18,$C$19,F$26,F$25,$C$21,$C$22,$B35,F$27) -> 0 | G35: =_xll.DBRW($B$9,$C$18,$C$19,F$26,F$25,$C$21,$C$22,$B35,G$27) -> 0 | H35: =_xll.DBRW($B$9,$C$18,$C$19,F$26,F$25,$C$21,$C$22,$B35,H$27) -> 0 | I35: =IF(F35<>0,C35/F35,0) -> 0 | J35: =IF(H35<>0,E35/H35,0) -> 0 | K35: =_xll.DBRW($B$9,$C$18,$C$19,K$26,K$25,$C$21,$C$22,$B35,K$27) -> 0 | L35: =_xll.DBRW($B$9,$C$18,$C$19,K$26,K$25,$C$21,$C$22,$B35,L$27) -> 0 | M35: =_xll.DBRW($B$9,$C$18,$C$19,K$26,K$25,$C$21,$C$22,$B35,M$27) -> 0 | N35: =_xll.DBRW($B$9,$C$18,$C$19,N$26,N$25,$C$21,$C$22,$B35,N$27) -> 0 | O35: =_xll.DBRW($B$9,$C$18,$C$19,N$26,N$25,$C$21,$C$22,$B35,O$27) -> 0 | P35: =_xll.DBRW($B$9,$C$18,$C$19,N$26,N$25,$C$21,$C$22,$B35,P$27) -> 0 | Q35: =IF(N35<>0,K35/N35,0) -> 0 | R35: =IF(P35<>0,M35/P35,0) -> 0 | S35: =_xll.DBRW($B$9,$C$18,$C$19,S$26,S$25,$C$21,$C$22,$B35,S$27) -> 0 | T35: =_xll.DBRW($B$9,$C$18,$C$19,S$26,S$25,$C$21,$C$22,$B35,T$27) -> 0 | U35: =_xll.DBRW($B$9,$C$18,$C$19,S$26,S$25,$C$21,$C$22,$B35,U$27) -> 0 | V35: =_xll.DBRW($B$9,$C$18,$C$19,V$26,V$25,$C$21,$C$22,$B35,V$27) -> 0 | W35: =_xll.DBRW($B$9,$C$18,$C$19,V$26,V$25,$C$21,$C$22,$B35,W$27) -> 0 | X35: =_xll.DBRW($B$9,$C$18,$C$19,V$26,V$25,$C$21,$C$22,$B35,X$27) -> 0 | Y35: =IF(V35<>0,S35/V35,0) -> 0 | Z35: =IF(X35<>0,U35/X35,0) -> 0 | AA35: =_xll.DBRW($B$9,$C$18,$C$19,AA$26,AA$25,$C$21,$C$22,$B35,AA$27) -> 0 | AB35: =_xll.DBRW($B$9,$C$18,$C$19,AA$26,AA$25,$C$21,$C$22,$B35,AB$27) -> 0 | AC35: =_xll.DBRW($B$9,$C$18,$C$19,AA$26,AA$25,$C$21,$C$22,$B35,AC$27) -> 0 | AD35: =_xll.DBRW($B$9,$C$18,$C$19,AD$26,AD$25,$C$21,$C$22,$B35,AD$27) -> 0 | AE35: =_xll.DBRW($B$9,$C$18,$C$19,AD$26,AD$25,$C$21,$C$22,$B35,AE$27) -> 0 | AF35: =_xll.DBRW($B$9,$C$18,$C$19,AD$26,AD$25,$C$21,$C$22,$B35,AF$27) -> 0 | AG35: =IF(AD35<>0,AA35/AD35,0) -> 0 | AH35: =IF(AF35<>0,AC35/AF35,0) -> 0
A36: =IF(_xll.TM1RPTELISCONSOLIDATED($B$28,$B36),IF(_xll.TM1RPTELLEV($B$28,$B36)<=3,_xll.TM1RPTELLEV($B$28,$B36),"D"),"N") -> 1 | B36: L - RFO - Hay / Silage Making | C36: =_xll.DBRW($B$9,$C$18,$C$19,C$26,C$25,$C$21,$C$22,$B36,C$27) -> 0 | D36: =_xll.DBRW($B$9,$C$18,$C$19,C$26,C$25,$C$21,$C$22,$B36,D$27) -> 0 | E36: =_xll.DBRW($B$9,$C$18,$C$19,C$26,C$25,$C$21,$C$22,$B36,E$27) -> 0 | F36: =_xll.DBRW($B$9,$C$18,$C$19,F$26,F$25,$C$21,$C$22,$B36,F$27) -> 0 | G36: =_xll.DBRW($B$9,$C$18,$C$19,F$26,F$25,$C$21,$C$22,$B36,G$27) -> 0 | H36: =_xll.DBRW($B$9,$C$18,$C$19,F$26,F$25,$C$21,$C$22,$B36,H$27) -> 0 | I36: =IF(F36<>0,C36/F36,0) -> 0 | J36: =IF(H36<>0,E36/H36,0) -> 0 | K36: =_xll.DBRW($B$9,$C$18,$C$19,K$26,K$25,$C$21,$C$22,$B36,K$27) -> 0 | L36: =_xll.DBRW($B$9,$C$18,$C$19,K$26,K$25,$C$21,$C$22,$B36,L$27) -> 0 | M36: =_xll.DBRW($B$9,$C$18,$C$19,K$26,K$25,$C$21,$C$22,$B36,M$27) -> 0 | N36: =_xll.DBRW($B$9,$C$18,$C$19,N$26,N$25,$C$21,$C$22,$B36,N$27) -> 0 | O36: =_xll.DBRW($B$9,$C$18,$C$19,N$26,N$25,$C$21,$C$22,$B36,O$27) -> 0 | P36: =_xll.DBRW($B$9,$C$18,$C$19,N$26,N$25,$C$21,$C$22,$B36,P$27) -> 0 | Q36: =IF(N36<>0,K36/N36,0) -> 0 | R36: =IF(P36<>0,M36/P36,0) -> 0 | S36: =_xll.DBRW($B$9,$C$18,$C$19,S$26,S$25,$C$21,$C$22,$B36,S$27) -> 0 | T36: =_xll.DBRW($B$9,$C$18,$C$19,S$26,S$25,$C$21,$C$22,$B36,T$27) -> 0 | U36: =_xll.DBRW($B$9,$C$18,$C$19,S$26,S$25,$C$21,$C$22,$B36,U$27) -> 0 | V36: =_xll.DBRW($B$9,$C$18,$C$19,V$26,V$25,$C$21,$C$22,$B36,V$27) -> 0 | W36: =_xll.DBRW($B$9,$C$18,$C$19,V$26,V$25,$C$21,$C$22,$B36,W$27) -> 0 | X36: =_xll.DBRW($B$9,$C$18,$C$19,V$26,V$25,$C$21,$C$22,$B36,X$27) -> 0 | Y36: =IF(V36<>0,S36/V36,0) -> 0 | Z36: =IF(X36<>0,U36/X36,0) -> 0 | AA36: =_xll.DBRW($B$9,$C$18,$C$19,AA$26,AA$25,$C$21,$C$22,$B36,AA$27) -> 0 | AB36: =_xll.DBRW($B$9,$C$18,$C$19,AA$26,AA$25,$C$21,$C$22,$B36,AB$27) -> 0 | AC36: =_xll.DBRW($B$9,$C$18,$C$19,AA$26,AA$25,$C$21,$C$22,$B36,AC$27) -> 0 | AD36: =_xll.DBRW($B$9,$C$18,$C$19,AD$26,AD$25,$C$21,$C$22,$B36,AD$27) -> 0 | AE36: =_xll.DBRW($B$9,$C$18,$C$19,AD$26,AD$25,$C$21,$C$22,$B36,AE$27) -> 0 | AF36: =_xll.DBRW($B$9,$C$18,$C$19,AD$26,AD$25,$C$21,$C$22,$B36,AF$27) -> 0 | AG36: =IF(AD36<>0,AA36/AD36,0) -> 0 | AH36: =IF(AF36<>0,AC36/AF36,0) -> 0
A37: =IF(_xll.TM1RPTELISCONSOLIDATED($B$28,$B37),IF(_xll.TM1RPTELLEV($B$28,$B37)<=3,_xll.TM1RPTELLEV($B$28,$B37),"D"),"N") -> 1 | B37: L - PRE - Balers | C37: =_xll.DBRW($B$9,$C$18,$C$19,C$26,C$25,$C$21,$C$22,$B37,C$27) -> 0 | D37: =_xll.DBRW($B$9,$C$18,$C$19,C$26,C$25,$C$21,$C$22,$B37,D$27) -> 0 | E37: =_xll.DBRW($B$9,$C$18,$C$19,C$26,C$25,$C$21,$C$22,$B37,E$27) -> 0 | F37: =_xll.DBRW($B$9,$C$18,$C$19,F$26,F$25,$C$21,$C$22,$B37,F$27) -> 0 | G37: =_xll.DBRW($B$9,$C$18,$C$19,F$26,F$25,$C$21,$C$22,$B37,G$27) -> 0 | H37: =_xll.DBRW($B$9,$C$18,$C$19,F$26,F$25,$C$21,$C$22,$B37,H$27) -> 0 | I37: =IF(F37<>0,C37/F37,0) -> 0 | J37: =IF(H37<>0,E37/H37,0) -> 0 | K37: =_xll.DBRW($B$9,$C$18,$C$19,K$26,K$25,$C$21,$C$22,$B37,K$27) -> 0 | L37: =_xll.DBRW($B$9,$C$18,$C$19,K$26,K$25,$C$21,$C$22,$B37,L$27) -> 0 | M37: =_xll.DBRW($B$9,$C$18,$C$19,K$26,K$25,$C$21,$C$22,$B37,M$27) -> 0 | N37: =_xll.DBRW($B$9,$C$18,$C$19,N$26,N$25,$C$21,$C$22,$B37,N$27) -> 0 | O37: =_xll.DBRW($B$9,$C$18,$C$19,N$26,N$25,$C$21,$C$22,$B37,O$27) -> 0 | P37: =_xll.DBRW($B$9,$C$18,$C$19,N$26,N$25,$C$21,$C$22,$B37,P$27) -> 0 | Q37: =IF(N37<>0,K37/N37,0) -> 0 | R37: =IF(P37<>0,M37/P37,0) -> 0 | S37: =_xll.DBRW($B$9,$C$18,$C$19,S$26,S$25,$C$21,$C$22,$B37,S$27) -> 0 | T37: =_xll.DBRW($B$9,$C$18,$C$19,S$26,S$25,$C$21,$C$22,$B37,T$27) -> 0 | U37: =_xll.DBRW($B$9,$C$18,$C$19,S$26,S$25,$C$21,$C$22,$B37,U$27) -> 0 | V37: =_xll.DBRW($B$9,$C$18,$C$19,V$26,V$25,$C$21,$C$22,$B37,V$27) -> 0 | W37: =_xll.DBRW($B$9,$C$18,$C$19,V$26,V$25,$C$21,$C$22,$B37,W$27) -> 0 | X37: =_xll.DBRW($B$9,$C$18,$C$19,V$26,V$25,$C$21,$C$22,$B37,X$27) -> 0 | Y37: =IF(V37<>0,S37/V37,0) -> 0 | Z37: =IF(X37<>0,U37/X37,0) -> 0 | AA37: =_xll.DBRW($B$9,$C$18,$C$19,AA$26,AA$25,$C$21,$C$22,$B37,AA$27) -> 0 | AB37: =_xll.DBRW($B$9,$C$18,$C$19,AA$26,AA$25,$C$21,$C$22,$B37,AB$27) -> 0 | AC37: =_xll.DBRW($B$9,$C$18,$C$19,AA$26,AA$25,$C$21,$C$22,$B37,AC$27) -> 0 | AD37: =_xll.DBRW($B$9,$C$18,$C$19,AD$26,AD$25,$C$21,$C$22,$B37,AD$27) -> 0 | AE37: =_xll.DBRW($B$9,$C$18,$C$19,AD$26,AD$25,$C$21,$C$22,$B37,AE$27) -> 0 | AF37: =_xll.DBRW($B$9,$C$18,$C$19,AD$26,AD$25,$C$21,$C$22,$B37,AF$27) -> 0 | AG37: =IF(AD37<>0,AA37/AD37,0) -> 0 | AH37: =IF(AF37<>0,AC37/AF37,0) -> 0
A38: =IF(_xll.TM1RPTELISCONSOLIDATED($B$28,$B38),IF(_xll.TM1RPTELLEV($B$28,$B38)<=3,_xll.TM1RPTELLEV($B$28,$B38),"D"),"N") -> 1 | B38: L - ENR - Wrappers | C38: =_xll.DBRW($B$9,$C$18,$C$19,C$26,C$25,$C$21,$C$22,$B38,C$27) -> 0 | D38: =_xll.DBRW($B$9,$C$18,$C$19,C$26,C$25,$C$21,$C$22,$B38,D$27) -> 0 | E38: =_xll.DBRW($B$9,$C$18,$C$19,C$26,C$25,$C$21,$C$22,$B38,E$27) -> 0 | F38: =_xll.DBRW($B$9,$C$18,$C$19,F$26,F$25,$C$21,$C$22,$B38,F$27) -> 0 | G38: =_xll.DBRW($B$9,$C$18,$C$19,F$26,F$25,$C$21,$C$22,$B38,G$27) -> 0 | H38: =_xll.DBRW($B$9,$C$18,$C$19,F$26,F$25,$C$21,$C$22,$B38,H$27) -> 0 | I38: =IF(F38<>0,C38/F38,0) -> 0 | J38: =IF(H38<>0,E38/H38,0) -> 0 | K38: =_xll.DBRW($B$9,$C$18,$C$19,K$26,K$25,$C$21,$C$22,$B38,K$27) -> 0 | L38: =_xll.DBRW($B$9,$C$18,$C$19,K$26,K$25,$C$21,$C$22,$B38,L$27) -> 0 | M38: =_xll.DBRW($B$9,$C$18,$C$19,K$26,K$25,$C$21,$C$22,$B38,M$27) -> 0 | N38: =_xll.DBRW($B$9,$C$18,$C$19,N$26,N$25,$C$21,$C$22,$B38,N$27) -> 0 | O38: =_xll.DBRW($B$9,$C$18,$C$19,N$26,N$25,$C$21,$C$22,$B38,O$27) -> 0 | P38: =_xll.DBRW($B$9,$C$18,$C$19,N$26,N$25,$C$21,$C$22,$B38,P$27) -> 0 | Q38: =IF(N38<>0,K38/N38,0) -> 0 | R38: =IF(P38<>0,M38/P38,0) -> 0 | S38: =_xll.DBRW($B$9,$C$18,$C$19,S$26,S$25,$C$21,$C$22,$B38,S$27) -> 0 | T38: =_xll.DBRW($B$9,$C$18,$C$19,S$26,S$25,$C$21,$C$22,$B38,T$27) -> 0 | U38: =_xll.DBRW($B$9,$C$18,$C$19,S$26,S$25,$C$21,$C$22,$B38,U$27) -> 0 | V38: =_xll.DBRW($B$9,$C$18,$C$19,V$26,V$25,$C$21,$C$22,$B38,V$27) -> 0 | W38: =_xll.DBRW($B$9,$C$18,$C$19,V$26,V$25,$C$21,$C$22,$B38,W$27) -> 0 | X38: =_xll.DBRW($B$9,$C$18,$C$19,V$26,V$25,$C$21,$C$22,$B38,X$27) -> 0 | Y38: =IF(V38<>0,S38/V38,0) -> 0 | Z38: =IF(X38<>0,U38/X38,0) -> 0 | AA38: =_xll.DBRW($B$9,$C$18,$C$19,AA$26,AA$25,$C$21,$C$22,$B38,AA$27) -> 0 | AB38: =_xll.DBRW($B$9,$C$18,$C$19,AA$26,AA$25,$C$21,$C$22,$B38,AB$27) -> 0 | AC38: =_xll.DBRW($B$9,$C$18,$C$19,AA$26,AA$25,$C$21,$C$22,$B38,AC$27) -> 0 | AD38: =_xll.DBRW($B$9,$C$18,$C$19,AD$26,AD$25,$C$21,$C$22,$B38,AD$27) -> 0 | AE38: =_xll.DBRW($B$9,$C$18,$C$19,AD$26,AD$25,$C$21,$C$22,$B38,AE$27) -> 0 | AF38: =_xll.DBRW($B$9,$C$18,$C$19,AD$26,AD$25,$C$21,$C$22,$B38,AF$27) -> 0 | AG38: =IF(AD38<>0,AA38/AD38,0) -> 0 | AH38: =IF(AF38<>0,AC38/AF38,0) -> 0
A39: =IF(_xll.TM1RPTELISCONSOLIDATED($B$28,$B39),IF(_xll.TM1RPTELLEV($B$28,$B39)<=3,_xll.TM1RPTELLEV($B$28,$B39),"D"),"N") -> 1 | B39: L - ENS - Choppers | C39: =_xll.DBRW($B$9,$C$18,$C$19,C$26,C$25,$C$21,$C$22,$B39,C$27) -> 0 | D39: =_xll.DBRW($B$9,$C$18,$C$19,C$26,C$25,$C$21,$C$22,$B39,D$27) -> 0 | E39: =_xll.DBRW($B$9,$C$18,$C$19,C$26,C$25,$C$21,$C$22,$B39,E$27) -> 0 | F39: =_xll.DBRW($B$9,$C$18,$C$19,F$26,F$25,$C$21,$C$22,$B39,F$27) -> 0 | G39: =_xll.DBRW($B$9,$C$18,$C$19,F$26,F$25,$C$21,$C$22,$B39,G$27) -> 0 | H39: =_xll.DBRW($B$9,$C$18,$C$19,F$26,F$25,$C$21,$C$22,$B39,H$27) -> 0 | I39: =IF(F39<>0,C39/F39,0) -> 0 | J39: =IF(H39<>0,E39/H39,0) -> 0 | K39: =_xll.DBRW($B$9,$C$18,$C$19,K$26,K$25,$C$21,$C$22,$B39,K$27) -> 0 | L39: =_xll.DBRW($B$9,$C$18,$C$19,K$26,K$25,$C$21,$C$22,$B39,L$27) -> 0 | M39: =_xll.DBRW($B$9,$C$18,$C$19,K$26,K$25,$C$21,$C$22,$B39,M$27) -> 0 | N39: =_xll.DBRW($B$9,$C$18,$C$19,N$26,N$25,$C$21,$C$22,$B39,N$27) -> 0 | O39: =_xll.DBRW($B$9,$C$18,$C$19,N$26,N$25,$C$21,$C$22,$B39,O$27) -> 0 | P39: =_xll.DBRW($B$9,$C$18,$C$19,N$26,N$25,$C$21,$C$22,$B39,P$27) -> 0 | Q39: =IF(N39<>0,K39/N39,0) -> 0 | R39: =IF(P39<>0,M39/P39,0) -> 0 | S39: =_xll.DBRW($B$9,$C$18,$C$19,S$26,S$25,$C$21,$C$22,$B39,S$27) -> 0 | T39: =_xll.DBRW($B$9,$C$18,$C$19,S$26,S$25,$C$21,$C$22,$B39,T$27) -> 0 | U39: =_xll.DBRW($B$9,$C$18,$C$19,S$26,S$25,$C$21,$C$22,$B39,U$27) -> 0 | V39: =_xll.DBRW($B$9,$C$18,$C$19,V$26,V$25,$C$21,$C$22,$B39,V$27) -> 0 | W39: =_xll.DBRW($B$9,$C$18,$C$19,V$26,V$25,$C$21,$C$22,$B39,W$27) -> 0 | X39: =_xll.DBRW($B$9,$C$18,$C$19,V$26,V$25,$C$21,$C$22,$B39,X$27) -> 0 | Y39: =IF(V39<>0,S39/V39,0) -> 0 | Z39: =IF(X39<>0,U39/X39,0) -> 0 | AA39: =_xll.DBRW($B$9,$C$18,$C$19,AA$26,AA$25,$C$21,$C$22,$B39,AA$27) -> 0 | AB39: =_xll.DBRW($B$9,$C$18,$C$19,AA$26,AA$25,$C$21,$C$22,$B39,AB$27) -> 0 | AC39: =_xll.DBRW($B$9,$C$18,$C$19,AA$26,AA$25,$C$21,$C$22,$B39,AC$27) -> 0 | AD39: =_xll.DBRW($B$9,$C$18,$C$19,AD$26,AD$25,$C$21,$C$22,$B39,AD$27) -> 0 | AE39: =_xll.DBRW($B$9,$C$18,$C$19,AD$26,AD$25,$C$21,$C$22,$B39,AE$27) -> 0 | AF39: =_xll.DBRW($B$9,$C$18,$C$19,AD$26,AD$25,$C$21,$C$22,$B39,AF$27) -> 0 | AG39: =IF(AD39<>0,AA39/AD39,0) -> 0 | AH39: =IF(AF39<>0,AC39/AF39,0) -> 0
A40: =IF(_xll.TM1RPTELISCONSOLIDATED($B$28,$B40),IF(_xll.TM1RPTELLEV($B$28,$B40)<=3,_xll.TM1RPTELLEV($B$28,$B40),"D"),"N") -> 1 | B40: L - LP_GRAIN_CARTS - GRAIN CARTS | C40: =_xll.DBRW($B$9,$C$18,$C$19,C$26,C$25,$C$21,$C$22,$B40,C$27) -> 0 | D40: =_xll.DBRW($B$9,$C$18,$C$19,C$26,C$25,$C$21,$C$22,$B40,D$27) -> 0 | E40: =_xll.DBRW($B$9,$C$18,$C$19,C$26,C$25,$C$21,$C$22,$B40,E$27) -> 0 | F40: =_xll.DBRW($B$9,$C$18,$C$19,F$26,F$25,$C$21,$C$22,$B40,F$27) -> 0 | G40: =_xll.DBRW($B$9,$C$18,$C$19,F$26,F$25,$C$21,$C$22,$B40,G$27) -> 0 | H40: =_xll.DBRW($B$9,$C$18,$C$19,F$26,F$25,$C$21,$C$22,$B40,H$27) -> 0 | I40: =IF(F40<>0,C40/F40,0) -> 0 | J40: =IF(H40<>0,E40/H40,0) -> 0 | K40: =_xll.DBRW($B$9,$C$18,$C$19,K$26,K$25,$C$21,$C$22,$B40,K$27) -> 0 | L40: =_xll.DBRW($B$9,$C$18,$C$19,K$26,K$25,$C$21,$C$22,$B40,L$27) -> 0 | M40: =_xll.DBRW($B$9,$C$18,$C$19,K$26,K$25,$C$21,$C$22,$B40,M$27) -> 0 | N40: =_xll.DBRW($B$9,$C$18,$C$19,N$26,N$25,$C$21,$C$22,$B40,N$27) -> 0 | O40: =_xll.DBRW($B$9,$C$18,$C$19,N$26,N$25,$C$21,$C$22,$B40,O$27) -> 0 | P40: =_xll.DBRW($B$9,$C$18,$C$19,N$26,N$25,$C$21,$C$22,$B40,P$27) -> 0 | Q40: =IF(N40<>0,K40/N40,0) -> 0 | R40: =IF(P40<>0,M40/P40,0) -> 0 | S40: =_xll.DBRW($B$9,$C$18,$C$19,S$26,S$25,$C$21,$C$22,$B40,S$27) -> 0 | T40: =_xll.DBRW($B$9,$C$18,$C$19,S$26,S$25,$C$21,$C$22,$B40,T$27) -> 0 | U40: =_xll.DBRW($B$9,$C$18,$C$19,S$26,S$25,$C$21,$C$22,$B40,U$27) -> 0 | V40: =_xll.DBRW($B$9,$C$18,$C$19,V$26,V$25,$C$21,$C$22,$B40,V$27) -> 0 | W40: =_xll.DBRW($B$9,$C$18,$C$19,V$26,V$25,$C$21,$C$22,$B40,W$27) -> 0 | X40: =_xll.DBRW($B$9,$C$18,$C$19,V$26,V$25,$C$21,$C$22,$B40,X$27) -> 0 | Y40: =IF(V40<>0,S40/V40,0) -> 0 | Z40: =IF(X40<>0,U40/X40,0) -> 0 | AA40: =_xll.DBRW($B$9,$C$18,$C$19,AA$26,AA$25,$C$21,$C$22,$B40,AA$27) -> 0 | AB40: =_xll.DBRW($B$9,$C$18,$C$19,AA$26,AA$25,$C$21,$C$22,$B40,AB$27) -> 0 | AC40: =_xll.DBRW($B$9,$C$18,$C$19,AA$26,AA$25,$C$21,$C$22,$B40,AC$27) -> 0 | AD40: =_xll.DBRW($B$9,$C$18,$C$19,AD$26,AD$25,$C$21,$C$22,$B40,AD$27) -> 0 | AE40: =_xll.DBRW($B$9,$C$18,$C$19,AD$26,AD$25,$C$21,$C$22,$B40,AE$27) -> 0 | AF40: =_xll.DBRW($B$9,$C$18,$C$19,AD$26,AD$25,$C$21,$C$22,$B40,AF$27) -> 0 | AG40: =IF(AD40<>0,AA40/AD40,0) -> 0 | AH40: =IF(AF40<>0,AC40/AF40,0) -> 0
... A50: =IF(_xll.TM1RPTELISCONSOLIDATED($B$28,$B50),IF(_xll.TM1RPTELLEV($B$28,$B50)<=3,_xll.TM1RPTELLEV($B$28,$B50),"D"),"N") -> 1 | B50: L - -2 - Not applicable | C50: =_xll.DBRW($B$9,$C$18,$C$19,C$26,C$25,$C$21,$C$22,$B50,C$27) -> 0 | D50: =_xll.DBRW($B$9,$C$18,$C$19,C$26,C$25,$C$21,$C$22,$B50,D$27) -> 0 | E50: =_xll.DBRW($B$9,$C$18,$C$19,C$26,C$25,$C$21,$C$22,$B50,E$27) -> 0 | F50: =_xll.DBRW($B$9,$C$18,$C$19,F$26,F$25,$C$21,$C$22,$B50,F$27) -> 0 | G50: =_xll.DBRW($B$9,$C$18,$C$19,F$26,F$25,$C$21,$C$22,$B50,G$27) -> 0 | H50: =_xll.DBRW($B$9,$C$18,$C$19,F$26,F$25,$C$21,$C$22,$B50,H$27) -> 0 | I50: =IF(F50<>0,C50/F50,0) -> 0 | J50: =IF(H50<>0,E50/H50,0) -> 0 | K50: =_xll.DBRW($B$9,$C$18,$C$19,K$26,K$25,$C$21,$C$22,$B50,K$27) -> 0 | L50: =_xll.DBRW($B$9,$C$18,$C$19,K$26,K$25,$C$21,$C$22,$B50,L$27) -> 0 | M50: =_xll.DBRW($B$9,$C$18,$C$19,K$26,K$25,$C$21,$C$22,$B50,M$27) -> 0 | N50: =_xll.DBRW($B$9,$C$18,$C$19,N$26,N$25,$C$21,$C$22,$B50,N$27) -> 0 | O50: =_xll.DBRW($B$9,$C$18,$C$19,N$26,N$25,$C$21,$C$22,$B50,O$27) -> 0 | P50: =_xll.DBRW($B$9,$C$18,$C$19,N$26,N$25,$C$21,$C$22,$B50,P$27) -> 0 | Q50: =IF(N50<>0,K50/N50,0) -> 0 | R50: =IF(P50<>0,M50/P50,0) -> 0 | S50: =_xll.DBRW($B$9,$C$18,$C$19,S$26,S$25,$C$21,$C$22,$B50,S$27) -> 0 | T50: =_xll.DBRW($B$9,$C$18,$C$19,S$26,S$25,$C$21,$C$22,$B50,T$27) -> 0 | U50: =_xll.DBRW($B$9,$C$18,$C$19,S$26,S$25,$C$21,$C$22,$B50,U$27) -> 0 | V50: =_xll.DBRW($B$9,$C$18,$C$19,V$26,V$25,$C$21,$C$22,$B50,V$27) -> 0 | W50: =_xll.DBRW($B$9,$C$18,$C$19,V$26,V$25,$C$21,$C$22,$B50,W$27) -> 0 | X50: =_xll.DBRW($B$9,$C$18,$C$19,V$26,V$25,$C$21,$C$22,$B50,X$27) -> 0 | Y50: =IF(V50<>0,S50/V50,0) -> 0 | Z50: =IF(X50<>0,U50/X50,0) -> 0 | AA50: =_xll.DBRW($B$9,$C$18,$C$19,AA$26,AA$25,$C$21,$C$22,$B50,AA$27) -> 0 | AB50: =_xll.DBRW($B$9,$C$18,$C$19,AA$26,AA$25,$C$21,$C$22,$B50,AB$27) -> 0 | AC50: =_xll.DBRW($B$9,$C$18,$C$19,AA$26,AA$25,$C$21,$C$22,$B50,AC$27) -> 0 | AD50: =_xll.DBRW($B$9,$C$18,$C$19,AD$26,AD$25,$C$21,$C$22,$B50,AD$27) -> 0 | AE50: =_xll.DBRW($B$9,$C$18,$C$19,AD$26,AD$25,$C$21,$C$22,$B50,AE$27) -> 0 | AF50: =_xll.DBRW($B$9,$C$18,$C$19,AD$26,AD$25,$C$21,$C$22,$B50,AF$27) -> 0 | AG50: =IF(AD50<>0,AA50/AD50,0) -> 0 | AH50: =IF(AF50<>0,AC50/AF50,0) -> 0

Sheet {AR}01 (3)
F20: TOTAL PRODUCT
F21: L - 700000 - PLOUGHING
F22: L - 701000 - TILLAGE
F23: L - 702000 - SEEDING
F24: L - 703000 - FERTILISING
F25: L - 704000 - SPRAYING
F26: L - 705000 - LANDSCAPE MAINTENANCE
F27: L - 706000 - SHREDDING
F28: L - 707000 - HAY & FORAGE
F29: L - 708000 - BALERS
F30: L - 709000 - WRAPPERS
F31: L - 712000 - CHOPPERS
... F47: L - NA - Not Available

Sheet Market shares detailed
A1: [Begin Format Range]
A2: =0 -> 0
A3: =1 -> 1
A4: =2 -> 2
A5: =3 -> 3
A6: D
A7: N
A8: [End Format Range]
G15: =_xll.TM1RPTVIEW("CXMD:OTC_DATA_MARKET_ANALYSIS:ARPT1", 1, _xll.TM1RPTTITLE("CXMD:Currency",$H$21), _xll.TM1RPTTITLE("CXMD:DIM_Prev_IC_mapping",$H$22), _xll.TM1RPTTITLE("CXMD:DIM_Origin_Company",$H$24), _xll.TM1RPTTITLE("CXMD:DIM_Country",$H$25),TM1RPTFMTRNG,TM1RPTFMTIDCOL) -> CXMD:OTC_DATA_MARKET_ANALYSIS:ARPT1
G21: Currency | H21: =_xll.SUBNM("CXMD:Currency","Par défaut","CD_LC","Description EN") -> Local currency
G22: Prev_IC_mapping | H22: =_xll.SUBNM("CXMD:Prev_IC_mapping","","Others") -> Others
G23: Market Shares - 4 periods
G24: Origin_Company | H24: ='Market shares summary'!C21 -> KUHN GERMANY
G25: Country | H25: ='Market shares summary'!C22 -> ALLEMAGNE
H28: ='Market shares summary'!C25 -> AC2018 | N28: Market Shares | P28: ='Market shares summary'!K25 -> BU2019draft | V28: Market Shares | X28: ='Market shares summary'!S25 -> FC3_2019 | AD28: Market Shares | AF28: ='Market shares summary'!AD25 -> BU2020Draft | AL28: Market Shares
H29: KUHN Sales | K29: KUHN_Scope | P29: KUHN Sales | S29: KUHN_Scope | X29: KUHN Sales | AA29: KUHN_Scope | AF29: KUHN Sales | AI29: KUHN_Scope
H30: QTY | I30: Unit.Price | J30: SALES | K30: QTY | L30: Unit.Price | M30: SALES | N30: QTY | O30: SALES | P30: QTY | Q30: Unit.Price | R30: SALES | S30: QTY | T30: Unit.Price | U30: SALES | V30: QTY | W30: SALES | X30: QTY | Y30: Unit.Price | Z30: SALES | AA30: QTY | AB30: Unit.Price | AC30: SALES | AD30: QTY | AE30: SALES | AF30: QTY | AG30: Unit.Price | AH30: SALES | AI30: QTY | AJ30: Unit.Price | AK30: SALES | AL30: QTY | AM30: SALES
A31: =IF(_xll.TM1RPTELISCONSOLIDATED($G$31,$G31),IF(_xll.TM1RPTELLEV($G$31,$G31)<=3,_xll.TM1RPTELLEV($G$31,$G31),"D"),"N") -> 0 | G31: =_xll.TM1RPTROW($G$15,"CXMD:DIM_Configuration","Product_Market_Shares_BUD_Meeting","","Description EN",0) -> TOTAL PRODUCT | H31: =_xll.DBRW($G$15,$H$21,$H$22,H$29,H$28,$H$24,$H$25,$G31,H$30) -> 0 | I31: =_xll.DBRW($G$15,$H$21,$H$22,H$29,H$28,$H$24,$H$25,$G31,I$30) -> 0 | J31: =_xll.DBRW($G$15,$H$21,$H$22,H$29,H$28,$H$24,$H$25,$G31,J$30) -> 0 | K31: =_xll.DBRW($G$15,$H$21,$H$22,K$29,H$28,$H$24,$H$25,$G31,K$30) -> 0 | L31: =_xll.DBRW($G$15,$H$21,$H$22,K$29,H$28,$H$24,$H$25,$G31,L$30) -> 0 | M31: =_xll.DBRW($G$15,$H$21,$H$22,K$29,H$28,$H$24,$H$25,$G31,M$30) -> 0 | N31: =IF(K31<>0,H31/K31,0) -> 0 | O31: =IF(M31<>0,J31/M31,0) -> 0 | P31: =_xll.DBRW($G$15,$H$21,$H$22,P$29,P$28,$H$24,$H$25,$G31,P$30) -> 0 | Q31: =_xll.DBRW($G$15,$H$21,$H$22,P$29,P$28,$H$24,$H$25,$G31,Q$30) -> 0 | R31: =_xll.DBRW($G$15,$H$21,$H$22,P$29,P$28,$H$24,$H$25,$G31,R$30) -> 0 | S31: =_xll.DBRW($G$15,$H$21,$H$22,S$29,P$28,$H$24,$H$25,$G31,S$30) -> 0 | T31: =_xll.DBRW($G$15,$H$21,$H$22,S$29,P$28,$H$24,$H$25,$G31,T$30) -> 0 | U31: =_xll.DBRW($G$15,$H$21,$H$22,S$29,P$28,$H$24,$H$25,$G31,U$30) -> 0 | V31: =IF(S31<>0,P31/S31,0) -> 0 | W31: =IF(U31<>0,R31/U31,0) -> 0 | X31: =_xll.DBRW($G$15,$H$21,$H$22,X$29,X$28,$H$24,$H$25,$G31,X$30) -> 0 | Y31: =_xll.DBRW($G$15,$H$21,$H$22,X$29,X$28,$H$24,$H$25,$G31,Y$30) -> 0 | Z31: =_xll.DBRW($G$15,$H$21,$H$22,X$29,X$28,$H$24,$H$25,$G31,Z$30) -> 0 | AA31: =_xll.DBRW($G$15,$H$21,$H$22,AA$29,X$28,$H$24,$H$25,$G31,AA$30) -> 0 | AB31: =_xll.DBRW($G$15,$H$21,$H$22,AA$29,X$28,$H$24,$H$25,$G31,AB$30) -> 0 | AC31: =_xll.DBRW($G$15,$H$21,$H$22,AA$29,X$28,$H$24,$H$25,$G31,AC$30) -> 0 | AD31: =IF(AA31<>0,X31/AA31,0) -> 0 | AE31: =IF(AC31<>0,Z31/AC31,0) -> 0 | AF31: =_xll.DBRW($G$15,$H$21,$H$22,AF$29,AF$28,$H$24,$H$25,$G31,AF$30) -> 0 | AG31: =_xll.DBRW($G$15,$H$21,$H$22,AF$29,AF$28,$H$24,$H$25,$G31,AG$30) -> 0 | AH31: =_xll.DBRW($G$15,$H$21,$H$22,AF$29,AF$28,$H$24,$H$25,$G31,AH$30) -> 0 | AI31: =_xll.DBRW($G$15,$H$21,$H$22,AI$29,AF$28,$H$24,$H$25,$G31,AI$30) -> 0 | AJ31: =_xll.DBRW($G$15,$H$21,$H$22,AI$29,AF$28,$H$24,$H$25,$G31,AJ$30) -> 0 | AK31: =_xll.DBRW($G$15,$H$21,$H$22,AI$29,AF$28,$H$24,$H$25,$G31,AK$30) -> 0 | AL31: =IF(AI31<>0,AF31/AI31,0) -> 0 | AM31: =IF(AK31<>0,AH31/AK31,0) -> 0
A32: =IF(_xll.TM1RPTELISCONSOLIDATED($G$31,$G32),IF(_xll.TM1RPTELLEV($G$31,$G32)<=3,_xll.TM1RPTELLEV($G$31,$G32),"D"),"N") -> 1 | G32: L - LAB - Ploughing | H32: =_xll.DBRW($G$15,$H$21,$H$22,H$29,H$28,$H$24,$H$25,$G32,H$30) -> 0 | I32: =_xll.DBRW($G$15,$H$21,$H$22,H$29,H$28,$H$24,$H$25,$G32,I$30) -> 0 | J32: =_xll.DBRW($G$15,$H$21,$H$22,H$29,H$28,$H$24,$H$25,$G32,J$30) -> 0 | K32: =_xll.DBRW($G$15,$H$21,$H$22,K$29,H$28,$H$24,$H$25,$G32,K$30) -> 0 | L32: =_xll.DBRW($G$15,$H$21,$H$22,K$29,H$28,$H$24,$H$25,$G32,L$30) -> 0 | M32: =_xll.DBRW($G$15,$H$21,$H$22,K$29,H$28,$H$24,$H$25,$G32,M$30) -> 0 | N32: =IF(K32<>0,H32/K32,0) -> 0 | O32: =IF(M32<>0,J32/M32,0) -> 0 | P32: =_xll.DBRW($G$15,$H$21,$H$22,P$29,P$28,$H$24,$H$25,$G32,P$30) -> 0 | Q32: =_xll.DBRW($G$15,$H$21,$H$22,P$29,P$28,$H$24,$H$25,$G32,Q$30) -> 0 | R32: =_xll.DBRW($G$15,$H$21,$H$22,P$29,P$28,$H$24,$H$25,$G32,R$30) -> 0 | S32: =_xll.DBRW($G$15,$H$21,$H$22,S$29,P$28,$H$24,$H$25,$G32,S$30) -> 0 | T32: =_xll.DBRW($G$15,$H$21,$H$22,S$29,P$28,$H$24,$H$25,$G32,T$30) -> 0 | U32: =_xll.DBRW($G$15,$H$21,$H$22,S$29,P$28,$H$24,$H$25,$G32,U$30) -> 0 | V32: =IF(S32<>0,P32/S32,0) -> 0 | W32: =IF(U32<>0,R32/U32,0) -> 0 | X32: =_xll.DBRW($G$15,$H$21,$H$22,X$29,X$28,$H$24,$H$25,$G32,X$30) -> 0 | Y32: =_xll.DBRW($G$15,$H$21,$H$22,X$29,X$28,$H$24,$H$25,$G32,Y$30) -> 0 | Z32: =_xll.DBRW($G$15,$H$21,$H$22,X$29,X$28,$H$24,$H$25,$G32,Z$30) -> 0 | AA32: =_xll.DBRW($G$15,$H$21,$H$22,AA$29,X$28,$H$24,$H$25,$G32,AA$30) -> 0 | AB32: =_xll.DBRW($G$15,$H$21,$H$22,AA$29,X$28,$H$24,$H$25,$G32,AB$30) -> 0 | AC32: =_xll.DBRW($G$15,$H$21,$H$22,AA$29,X$28,$H$24,$H$25,$G32,AC$30) -> 0 | AD32: =IF(AA32<>0,X32/AA32,0) -> 0 | AE32: =IF(AC32<>0,Z32/AC32,0) -> 0 | AF32: =_xll.DBRW($G$15,$H$21,$H$22,AF$29,AF$28,$H$24,$H$25,$G32,AF$30) -> 0 | AG32: =_xll.DBRW($G$15,$H$21,$H$22,AF$29,AF$28,$H$24,$H$25,$G32,AG$30) -> 0 | AH32: =_xll.DBRW($G$15,$H$21,$H$22,AF$29,AF$28,$H$24,$H$25,$G32,AH$30) -> 0 | AI32: =_xll.DBRW($G$15,$H$21,$H$22,AI$29,AF$28,$H$24,$H$25,$G32,AI$30) -> 0 | AJ32: =_xll.DBRW($G$15,$H$21,$H$22,AI$29,AF$28,$H$24,$H$25,$G32,AJ$30) -> 0 | AK32: =_xll.DBRW($G$15,$H$21,$H$22,AI$29,AF$28,$H$24,$H$25,$G32,AK$30) -> 0 | AL32: =IF(AI32<>0,AF32/AI32,0) -> 0 | AM32: =IF(AK32<>0,AH32/AK32,0) -> 0
A33: =IF(_xll.TM1RPTELISCONSOLIDATED($G$31,$G33),IF(_xll.TM1RPTELLEV($G$31,$G33)<=3,_xll.TM1RPTELLEV($G$31,$G33),"D"),"N") -> 2 | G33: F - CRP - Mounted reversible ploughs | H33: =_xll.DBRW($G$15,$H$21,$H$22,H$29,H$28,$H$24,$H$25,$G33,H$30) -> 0 | I33: =_xll.DBRW($G$15,$H$21,$H$22,H$29,H$28,$H$24,$H$25,$G33,I$30) -> 0 | J33: =_xll.DBRW($G$15,$H$21,$H$22,H$29,H$28,$H$24,$H$25,$G33,J$30) -> 0 | K33: =_xll.DBRW($G$15,$H$21,$H$22,K$29,H$28,$H$24,$H$25,$G33,K$30) -> 0 | L33: =_xll.DBRW($G$15,$H$21,$H$22,K$29,H$28,$H$24,$H$25,$G33,L$30) -> 0 | M33: =_xll.DBRW($G$15,$H$21,$H$22,K$29,H$28,$H$24,$H$25,$G33,M$30) -> 0 | N33: =IF(K33<>0,H33/K33,0) -> 0 | O33: =IF(M33<>0,J33/M33,0) -> 0 | P33: =_xll.DBRW($G$15,$H$21,$H$22,P$29,P$28,$H$24,$H$25,$G33,P$30) -> 0 | Q33: =_xll.DBRW($G$15,$H$21,$H$22,P$29,P$28,$H$24,$H$25,$G33,Q$30) -> 0 | R33: =_xll.DBRW($G$15,$H$21,$H$22,P$29,P$28,$H$24,$H$25,$G33,R$30) -> 0 | S33: =_xll.DBRW($G$15,$H$21,$H$22,S$29,P$28,$H$24,$H$25,$G33,S$30) -> 0 | T33: =_xll.DBRW($G$15,$H$21,$H$22,S$29,P$28,$H$24,$H$25,$G33,T$30) -> 0 | U33: =_xll.DBRW($G$15,$H$21,$H$22,S$29,P$28,$H$24,$H$25,$G33,U$30) -> 0 | V33: =IF(S33<>0,P33/S33,0) -> 0 | W33: =IF(U33<>0,R33/U33,0) -> 0 | X33: =_xll.DBRW($G$15,$H$21,$H$22,X$29,X$28,$H$24,$H$25,$G33,X$30) -> 0 | Y33: =_xll.DBRW($G$15,$H$21,$H$22,X$29,X$28,$H$24,$H$25,$G33,Y$30) -> 0 | Z33: =_xll.DBRW($G$15,$H$21,$H$22,X$29,X$28,$H$24,$H$25,$G33,Z$30) -> 0 | AA33: =_xll.DBRW($G$15,$H$21,$H$22,AA$29,X$28,$H$24,$H$25,$G33,AA$30) -> 0 | AB33: =_xll.DBRW($G$15,$H$21,$H$22,AA$29,X$28,$H$24,$H$25,$G33,AB$30) -> 0 | AC33: =_xll.DBRW($G$15,$H$21,$H$22,AA$29,X$28,$H$24,$H$25,$G33,AC$30) -> 0 | AD33: =IF(AA33<>0,X33/AA33,0) -> 0 | AE33: =IF(AC33<>0,Z33/AC33,0) -> 0 | AF33: =_xll.DBRW($G$15,$H$21,$H$22,AF$29,AF$28,$H$24,$H$25,$G33,AF$30) -> 0 | AG33: =_xll.DBRW($G$15,$H$21,$H$22,AF$29,AF$28,$H$24,$H$25,$G33,AG$30) -> 0 | AH33: =_xll.DBRW($G$15,$H$21,$H$22,AF$29,AF$28,$H$24,$H$25,$G33,AH$30) -> 0 | AI33: =_xll.DBRW($G$15,$H$21,$H$22,AI$29,AF$28,$H$24,$H$25,$G33,AI$30) -> 0 | AJ33: =_xll.DBRW($G$15,$H$21,$H$22,AI$29,AF$28,$H$24,$H$25,$G33,AJ$30) -> 0 | AK33: =_xll.DBRW($G$15,$H$21,$H$22,AI$29,AF$28,$H$24,$H$25,$G33,AK$30) -> 0 | AL33: =IF(AI33<>0,AF33/AI33,0) -> 0 | AM33: =IF(AK33<>0,AH33/AK33,0) -> 0
A34: =IF(_xll.TM1RPTELISCONSOLIDATED($G$31,$G34),IF(_xll.TM1RPTELLEV($G$31,$G34)<=3,_xll.TM1RPTELLEV($G$31,$G34),"D"),"N") -> 2 | G34: F - RSP - Semi-mounted reversible ploughs | H34: =_xll.DBRW($G$15,$H$21,$H$22,H$29,H$28,$H$24,$H$25,$G34,H$30) -> 0 | I34: =_xll.DBRW($G$15,$H$21,$H$22,H$29,H$28,$H$24,$H$25,$G34,I$30) -> 0 | J34: =_xll.DBRW($G$15,$H$21,$H$22,H$29,H$28,$H$24,$H$25,$G34,J$30) -> 0 | K34: =_xll.DBRW($G$15,$H$21,$H$22,K$29,H$28,$H$24,$H$25,$G34,K$30) -> 0 | L34: =_xll.DBRW($G$15,$H$21,$H$22,K$29,H$28,$H$24,$H$25,$G34,L$30) -> 0 | M34: =_xll.DBRW($G$15,$H$21,$H$22,K$29,H$28,$H$24,$H$25,$G34,M$30) -> 0 | N34: =IF(K34<>0,H34/K34,0) -> 0 | O34: =IF(M34<>0,J34/M34,0) -> 0 | P34: =_xll.DBRW($G$15,$H$21,$H$22,P$29,P$28,$H$24,$H$25,$G34,P$30) -> 0 | Q34: =_xll.DBRW($G$15,$H$21,$H$22,P$29,P$28,$H$24,$H$25,$G34,Q$30) -> 0 | R34: =_xll.DBRW($G$15,$H$21,$H$22,P$29,P$28,$H$24,$H$25,$G34,R$30) -> 0 | S34: =_xll.DBRW($G$15,$H$21,$H$22,S$29,P$28,$H$24,$H$25,$G34,S$30) -> 0 | T34: =_xll.DBRW($G$15,$H$21,$H$22,S$29,P$28,$H$24,$H$25,$G34,T$30) -> 0 | U34: =_xll.DBRW($G$15,$H$21,$H$22,S$29,P$28,$H$24,$H$25,$G34,U$30) -> 0 | V34: =IF(S34<>0,P34/S34,0) -> 0 | W34: =IF(U34<>0,R34/U34,0) -> 0 | X34: =_xll.DBRW($G$15,$H$21,$H$22,X$29,X$28,$H$24,$H$25,$G34,X$30) -> 0 | Y34: =_xll.DBRW($G$15,$H$21,$H$22,X$29,X$28,$H$24,$H$25,$G34,Y$30) -> 0 | Z34: =_xll.DBRW($G$15,$H$21,$H$22,X$29,X$28,$H$24,$H$25,$G34,Z$30) -> 0 | AA34: =_xll.DBRW($G$15,$H$21,$H$22,AA$29,X$28,$H$24,$H$25,$G34,AA$30) -> 0 | AB34: =_xll.DBRW($G$15,$H$21,$H$22,AA$29,X$28,$H$24,$H$25,$G34,AB$30) -> 0 | AC34: =_xll.DBRW($G$15,$H$21,$H$22,AA$29,X$28,$H$24,$H$25,$G34,AC$30) -> 0 | AD34: =IF(AA34<>0,X34/AA34,0) -> 0 | AE34: =IF(AC34<>0,Z34/AC34,0) -> 0 | AF34: =_xll.DBRW($G$15,$H$21,$H$22,AF$29,AF$28,$H$24,$H$25,$G34,AF$30) -> 0 | AG34: =_xll.DBRW($G$15,$H$21,$H$22,AF$29,AF$28,$H$24,$H$25,$G34,AG$30) -> 0 | AH34: =_xll.DBRW($G$15,$H$21,$H$22,AF$29,AF$28,$H$24,$H$25,$G34,AH$30) -> 0 | AI34: =_xll.DBRW($G$15,$H$21,$H$22,AI$29,AF$28,$H$24,$H$25,$G34,AI$30) -> 0 | AJ34: =_xll.DBRW($G$15,$H$21,$H$22,AI$29,AF$28,$H$24,$H$25,$G34,AJ$30) -> 0 | AK34: =_xll.DBRW($G$15,$H$21,$H$22,AI$29,AF$28,$H$24,$H$25,$G34,AK$30) -> 0 | AL34: =IF(AI34<>0,AF34/AI34,0) -> 0 | AM34: =IF(AK34<>0,AH34/AK34,0) -> 0
A35: =IF(_xll.TM1RPTELISCONSOLIDATED($G$31,$G35),IF(_xll.TM1RPTELLEV($G$31,$G35)<=3,_xll.TM1RPTELLEV($G$31,$G35),"D"),"N") -> 2 | G35: F - SSP - Semi-mounted conventional ploughs | H35: =_xll.DBRW($G$15,$H$21,$H$22,H$29,H$28,$H$24,$H$25,$G35,H$30) -> 0 | I35: =_xll.DBRW($G$15,$H$21,$H$22,H$29,H$28,$H$24,$H$25,$G35,I$30) -> 0 | J35: =_xll.DBRW($G$15,$H$21,$H$22,H$29,H$28,$H$24,$H$25,$G35,J$30) -> 0 | K35: =_xll.DBRW($G$15,$H$21,$H$22,K$29,H$28,$H$24,$H$25,$G35,K$30) -> 0 | L35: =_xll.DBRW($G$15,$H$21,$H$22,K$29,H$28,$H$24,$H$25,$G35,L$30) -> 0 | M35: =_xll.DBRW($G$15,$H$21,$H$22,K$29,H$28,$H$24,$H$25,$G35,M$30) -> 0 | N35: =IF(K35<>0,H35/K35,0) -> 0 | O35: =IF(M35<>0,J35/M35,0) -> 0 | P35: =_xll.DBRW($G$15,$H$21,$H$22,P$29,P$28,$H$24,$H$25,$G35,P$30) -> 0 | Q35: =_xll.DBRW($G$15,$H$21,$H$22,P$29,P$28,$H$24,$H$25,$G35,Q$30) -> 0 | R35: =_xll.DBRW($G$15,$H$21,$H$22,P$29,P$28,$H$24,$H$25,$G35,R$30) -> 0 | S35: =_xll.DBRW($G$15,$H$21,$H$22,S$29,P$28,$H$24,$H$25,$G35,S$30) -> 0 | T35: =_xll.DBRW($G$15,$H$21,$H$22,S$29,P$28,$H$24,$H$25,$G35,T$30) -> 0 | U35: =_xll.DBRW($G$15,$H$21,$H$22,S$29,P$28,$H$24,$H$25,$G35,U$30) -> 0 | V35: =IF(S35<>0,P35/S35,0) -> 0 | W35: =IF(U35<>0,R35/U35,0) -> 0 | X35: =_xll.DBRW($G$15,$H$21,$H$22,X$29,X$28,$H$24,$H$25,$G35,X$30) -> 0 | Y35: =_xll.DBRW($G$15,$H$21,$H$22,X$29,X$28,$H$24,$H$25,$G35,Y$30) -> 0 | Z35: =_xll.DBRW($G$15,$H$21,$H$22,X$29,X$28,$H$24,$H$25,$G35,Z$30) -> 0 | AA35: =_xll.DBRW($G$15,$H$21,$H$22,AA$29,X$28,$H$24,$H$25,$G35,AA$30) -> 0 | AB35: =_xll.DBRW($G$15,$H$21,$H$22,AA$29,X$28,$H$24,$H$25,$G35,AB$30) -> 0 | AC35: =_xll.DBRW($G$15,$H$21,$H$22,AA$29,X$28,$H$24,$H$25,$G35,AC$30) -> 0 | AD35: =IF(AA35<>0,X35/AA35,0) -> 0 | AE35: =IF(AC35<>0,Z35/AC35,0) -> 0 | AF35: =_xll.DBRW($G$15,$H$21,$H$22,AF$29,AF$28,$H$24,$H$25,$G35,AF$30) -> 0 | AG35: =_xll.DBRW($G$15,$H$21,$H$22,AF$29,AF$28,$H$24,$H$25,$G35,AG$30) -> 0 | AH35: =_xll.DBRW($G$15,$H$21,$H$22,AF$29,AF$28,$H$24,$H$25,$G35,AH$30) -> 0 | AI35: =_xll.DBRW($G$15,$H$21,$H$22,AI$29,AF$28,$H$24,$H$25,$G35,AI$30) -> 0 | AJ35: =_xll.DBRW($G$15,$H$21,$H$22,AI$29,AF$28,$H$24,$H$25,$G35,AJ$30) -> 0 | AK35: =_xll.DBRW($G$15,$H$21,$H$22,AI$29,AF$28,$H$24,$H$25,$G35,AK$30) -> 0 | AL35: =IF(AI35<>0,AF35/AI35,0) -> 0 | AM35: =IF(AK35<>0,AH35/AK35,0) -> 0
A36: =IF(_xll.TM1RPTELISCONSOLIDATED($G$31,$G36),IF(_xll.TM1RPTELLEV($G$31,$G36)<=3,_xll.TM1RPTELLEV($G$31,$G36),"D"),"N") -> 2 | G36: F - CROT - Rotary ploughs | H36: =_xll.DBRW($G$15,$H$21,$H$22,H$29,H$28,$H$24,$H$25,$G36,H$30) -> 0 | I36: =_xll.DBRW($G$15,$H$21,$H$22,H$29,H$28,$H$24,$H$25,$G36,I$30) -> 0 | J36: =_xll.DBRW($G$15,$H$21,$H$22,H$29,H$28,$H$24,$H$25,$G36,J$30) -> 0 | K36: =_xll.DBRW($G$15,$H$21,$H$22,K$29,H$28,$H$24,$H$25,$G36,K$30) -> 0 | L36: =_xll.DBRW($G$15,$H$21,$H$22,K$29,H$28,$H$24,$H$25,$G36,L$30) -> 0 | M36: =_xll.DBRW($G$15,$H$21,$H$22,K$29,H$28,$H$24,$H$25,$G36,M$30) -> 0 | N36: =IF(K36<>0,H36/K36,0) -> 0 | O36: =IF(M36<>0,J36/M36,0) -> 0 | P36: =_xll.DBRW($G$15,$H$21,$H$22,P$29,P$28,$H$24,$H$25,$G36,P$30) -> 0 | Q36: =_xll.DBRW($G$15,$H$21,$H$22,P$29,P$28,$H$24,$H$25,$G36,Q$30) -> 0 | R36: =_xll.DBRW($G$15,$H$21,$H$22,P$29,P$28,$H$24,$H$25,$G36,R$30) -> 0 | S36: =_xll.DBRW($G$15,$H$21,$H$22,S$29,P$28,$H$24,$H$25,$G36,S$30) -> 0 | T36: =_xll.DBRW($G$15,$H$21,$H$22,S$29,P$28,$H$24,$H$25,$G36,T$30) -> 0 | U36: =_xll.DBRW($G$15,$H$21,$H$22,S$29,P$28,$H$24,$H$25,$G36,U$30) -> 0 | V36: =IF(S36<>0,P36/S36,0) -> 0 | W36: =IF(U36<>0,R36/U36,0) -> 0 | X36: =_xll.DBRW($G$15,$H$21,$H$22,X$29,X$28,$H$24,$H$25,$G36,X$30) -> 0 | Y36: =_xll.DBRW($G$15,$H$21,$H$22,X$29,X$28,$H$24,$H$25,$G36,Y$30) -> 0 | Z36: =_xll.DBRW($G$15,$H$21,$H$22,X$29,X$28,$H$24,$H$25,$G36,Z$30) -> 0 | AA36: =_xll.DBRW($G$15,$H$21,$H$22,AA$29,X$28,$H$24,$H$25,$G36,AA$30) -> 0 | AB36: =_xll.DBRW($G$15,$H$21,$H$22,AA$29,X$28,$H$24,$H$25,$G36,AB$30) -> 0 | AC36: =_xll.DBRW($G$15,$H$21,$H$22,AA$29,X$28,$H$24,$H$25,$G36,AC$30) -> 0 | AD36: =IF(AA36<>0,X36/AA36,0) -> 0 | AE36: =IF(AC36<>0,Z36/AC36,0) -> 0 | AF36: =_xll.DBRW($G$15,$H$21,$H$22,AF$29,AF$28,$H$24,$H$25,$G36,AF$30) -> 0 | AG36: =_xll.DBRW($G$15,$H$21,$H$22,AF$29,AF$28,$H$24,$H$25,$G36,AG$30) -> 0 | AH36: =_xll.DBRW($G$15,$H$21,$H$22,AF$29,AF$28,$H$24,$H$25,$G36,AH$30) -> 0 | AI36: =_xll.DBRW($G$15,$H$21,$H$22,AI$29,AF$28,$H$24,$H$25,$G36,AI$30) -> 0 | AJ36: =_xll.DBRW($G$15,$H$21,$H$22,AI$29,AF$28,$H$24,$H$25,$G36,AJ$30) -> 0 | AK36: =_xll.DBRW($G$15,$H$21,$H$22,AI$29,AF$28,$H$24,$H$25,$G36,AK$30) -> 0 | AL36: =IF(AI36<>0,AF36/AI36,0) -> 0 | AM36: =IF(AK36<>0,AH36/AK36,0) -> 0
A37: =IF(_xll.TM1RPTELISCONSOLIDATED($G$31,$G37),IF(_xll.TM1RPTELLEV($G$31,$G37)<=3,_xll.TM1RPTELLEV($G$31,$G37),"D"),"N") -> 2 | G37: F - F-CORPS - Bodies and skim coulters | H37: =_xll.DBRW($G$15,$H$21,$H$22,H$29,H$28,$H$24,$H$25,$G37,H$30) -> 0 | I37: =_xll.DBRW($G$15,$H$21,$H$22,H$29,H$28,$H$24,$H$25,$G37,I$30) -> 0 | J37: =_xll.DBRW($G$15,$H$21,$H$22,H$29,H$28,$H$24,$H$25,$G37,J$30) -> 0 | K37: =_xll.DBRW($G$15,$H$21,$H$22,K$29,H$28,$H$24,$H$25,$G37,K$30) -> 0 | L37: =_xll.DBRW($G$15,$H$21,$H$22,K$29,H$28,$H$24,$H$25,$G37,L$30) -> 0 | M37: =_xll.DBRW($G$15,$H$21,$H$22,K$29,H$28,$H$24,$H$25,$G37,M$30) -> 0 | N37: =IF(K37<>0,H37/K37,0) -> 0 | O37: =IF(M37<>0,J37/M37,0) -> 0 | P37: =_xll.DBRW($G$15,$H$21,$H$22,P$29,P$28,$H$24,$H$25,$G37,P$30) -> 0 | Q37: =_xll.DBRW($G$15,$H$21,$H$22,P$29,P$28,$H$24,$H$25,$G37,Q$30) -> 0 | R37: =_xll.DBRW($G$15,$H$21,$H$22,P$29,P$28,$H$24,$H$25,$G37,R$30) -> 0 | S37: =_xll.DBRW($G$15,$H$21,$H$22,S$29,P$28,$H$24,$H$25,$G37,S$30) -> 0 | T37: =_xll.DBRW($G$15,$H$21,$H$22,S$29,P$28,$H$24,$H$25,$G37,T$30) -> 0 | U37: =_xll.DBRW($G$15,$H$21,$H$22,S$29,P$28,$H$24,$H$25,$G37,U$30) -> 0 | V37: =IF(S37<>0,P37/S37,0) -> 0 | W37: =IF(U37<>0,R37/U37,0) -> 0 | X37: =_xll.DBRW($G$15,$H$21,$H$22,X$29,X$28,$H$24,$H$25,$G37,X$30) -> 0 | Y37: =_xll.DBRW($G$15,$H$21,$H$22,X$29,X$28,$H$24,$H$25,$G37,Y$30) -> 0 | Z37: =_xll.DBRW($G$15,$H$21,$H$22,X$29,X$28,$H$24,$H$25,$G37,Z$30) -> 0 | AA37: =_xll.DBRW($G$15,$H$21,$H$22,AA$29,X$28,$H$24,$H$25,$G37,AA$30) -> 0 | AB37: =_xll.DBRW($G$15,$H$21,$H$22,AA$29,X$28,$H$24,$H$25,$G37,AB$30) -> 0 | AC37: =_xll.DBRW($G$15,$H$21,$H$22,AA$29,X$28,$H$24,$H$25,$G37,AC$30) -> 0 | AD37: =IF(AA37<>0,X37/AA37,0) -> 0 | AE37: =IF(AC37<>0,Z37/AC37,0) -> 0 | AF37: =_xll.DBRW($G$15,$H$21,$H$22,AF$29,AF$28,$H$24,$H$25,$G37,AF$30) -> 0 | AG37: =_xll.DBRW($G$15,$H$21,$H$22,AF$29,AF$28,$H$24,$H$25,$G37,AG$30) -> 0 | AH37: =_xll.DBRW($G$15,$H$21,$H$22,AF$29,AF$28,$H$24,$H$25,$G37,AH$30) -> 0 | AI37: =_xll.DBRW($G$15,$H$21,$H$22,AI$29,AF$28,$H$24,$H$25,$G37,AI$30) -> 0 | AJ37: =_xll.DBRW($G$15,$H$21,$H$22,AI$29,AF$28,$H$24,$H$25,$G37,AJ$30) -> 0 | AK37: =_xll.DBRW($G$15,$H$21,$H$22,AI$29,AF$28,$H$24,$H$25,$G37,AK$30) -> 0 | AL37: =IF(AI37<>0,AF37/AI37,0) -> 0 | AM37: =IF(AK37<>0,AH37/AK37,0) -> 0
A38: =IF(_xll.TM1RPTELISCONSOLIDATED($G$31,$G38),IF(_xll.TM1RPTELLEV($G$31,$G38)<=3,_xll.TM1RPTELLEV($G$31,$G38),"D"),"N") -> 2 | G38: F - PC-LAB - Ploughing | H38: =_xll.DBRW($G$15,$H$21,$H$22,H$29,H$28,$H$24,$H$25,$G38,H$30) -> 0 | I38: =_xll.DBRW($G$15,$H$21,$H$22,H$29,H$28,$H$24,$H$25,$G38,I$30) -> 0 | J38: =_xll.DBRW($G$15,$H$21,$H$22,H$29,H$28,$H$24,$H$25,$G38,J$30) -> 0 | K38: =_xll.DBRW($G$15,$H$21,$H$22,K$29,H$28,$H$24,$H$25,$G38,K$30) -> 0 | L38: =_xll.DBRW($G$15,$H$21,$H$22,K$29,H$28,$H$24,$H$25,$G38,L$30) -> 0 | M38: =_xll.DBRW($G$15,$H$21,$H$22,K$29,H$28,$H$24,$H$25,$G38,M$30) -> 0 | N38: =IF(K38<>0,H38/K38,0) -> 0 | O38: =IF(M38<>0,J38/M38,0) -> 0 | P38: =_xll.DBRW($G$15,$H$21,$H$22,P$29,P$28,$H$24,$H$25,$G38,P$30) -> 0 | Q38: =_xll.DBRW($G$15,$H$21,$H$22,P$29,P$28,$H$24,$H$25,$G38,Q$30) -> 0 | R38: =_xll.DBRW($G$15,$H$21,$H$22,P$29,P$28,$H$24,$H$25,$G38,R$30) -> 0 | S38: =_xll.DBRW($G$15,$H$21,$H$22,S$29,P$28,$H$24,$H$25,$G38,S$30) -> 0 | T38: =_xll.DBRW($G$15,$H$21,$H$22,S$29,P$28,$H$24,$H$25,$G38,T$30) -> 0 | U38: =_xll.DBRW($G$15,$H$21,$H$22,S$29,P$28,$H$24,$H$25,$G38,U$30) -> 0 | V38: =IF(S38<>0,P38/S38,0) -> 0 | W38: =IF(U38<>0,R38/U38,0) -> 0 | X38: =_xll.DBRW($G$15,$H$21,$H$22,X$29,X$28,$H$24,$H$25,$G38,X$30) -> 0 | Y38: =_xll.DBRW($G$15,$H$21,$H$22,X$29,X$28,$H$24,$H$25,$G38,Y$30) -> 0 | Z38: =_xll.DBRW($G$15,$H$21,$H$22,X$29,X$28,$H$24,$H$25,$G38,Z$30) -> 0 | AA38: =_xll.DBRW($G$15,$H$21,$H$22,AA$29,X$28,$H$24,$H$25,$G38,AA$30) -> 0 | AB38: =_xll.DBRW($G$15,$H$21,$H$22,AA$29,X$28,$H$24,$H$25,$G38,AB$30) -> 0 | AC38: =_xll.DBRW($G$15,$H$21,$H$22,AA$29,X$28,$H$24,$H$25,$G38,AC$30) -> 0 | AD38: =IF(AA38<>0,X38/AA38,0) -> 0 | AE38: =IF(AC38<>0,Z38/AC38,0) -> 0 | AF38: =_xll.DBRW($G$15,$H$21,$H$22,AF$29,AF$28,$H$24,$H$25,$G38,AF$30) -> 0 | AG38: =_xll.DBRW($G$15,$H$21,$H$22,AF$29,AF$28,$H$24,$H$25,$G38,AG$30) -> 0 | AH38: =_xll.DBRW($G$15,$H$21,$H$22,AF$29,AF$28,$H$24,$H$25,$G38,AH$30) -> 0 | AI38: =_xll.DBRW($G$15,$H$21,$H$22,AI$29,AF$28,$H$24,$H$25,$G38,AI$30) -> 0 | AJ38: =_xll.DBRW($G$15,$H$21,$H$22,AI$29,AF$28,$H$24,$H$25,$G38,AJ$30) -> 0 | AK38: =_xll.DBRW($G$15,$H$21,$H$22,AI$29,AF$28,$H$24,$H$25,$G38,AK$30) -> 0 | AL38: =IF(AI38<>0,AF38/AI38,0) -> 0 | AM38: =IF(AK38<>0,AH38/AK38,0) -> 0
